Workbook

Sheet 01_表紙・改訂履歴
A1: 認証実装確認処理 基本設計
A2: API プラットフォーム／認証外形監視（Pattern β 中央集約）
A4: 1. 文書情報
A5: 項目 | B5: 内容
A6: 文書名 | B6: 認証実装確認処理 基本設計 | C6: —
A7: 機構名 | B7: 認証実装確認処理（ADR-059 での名称は Central Auth Check Canary）
A8: 定めること | B8: アプリチームに認証を実装させたうえで、その実装漏れを中央で継続検知する仕組みの基本設計
A9: 採用方式 | B9: Pattern β（中央集約）／pull 型中央巡回 × 認証構成情報（S3）の VersionId 比較 単独
A10: 版 | B10: 0.9 | C10: —
A11: 作成日 | B11: 2026-08-14 | C11: —
A12: 作成者 | C12: —
A13: 承認者 | C13: —
A15: 記載方針 | B15: 現行仕様のみを断定形で記述する。設計に至った経緯は本文に書かず ADR-061 / ADR-059 を参照する。参照元資料のタイトル・所在は「13_出典一覧」シートにまとめる。 | C15: —
A34: 3. 改訂履歴
A35: 版 | B35: 日付 | C35: 変更内容 | D35: 担当
A36: 0.1 | B36: 2026-08-14 | C36: 初版
A37: 0.2 | B37: 2026-08-18 | C37: レビュー指摘を反映（定めることの重複解消、D-M-14-4「検査 用 VPC」への修正、D-M-14-5 の判断追記、ListAccounts の未決制約注記、真偽値表記の統一、Runtime 表の 3 Lambda 化 ほか）。詳細通信フロー（W / P / N）、用語「STS / AssumeRole」、図14 発報フロー（2 系統）を追加
A38: 0.3 | B38: 2026-08-18 | C38: 未決に M-Q-11-5（検査 識別ヘッダの WAF 許可）を追加。M-Q-18-5 を解決済みへ。運用設計（メタ監視 MM-1〜5 / エラー処理・冪等性 / スケール上限と 分割起動）、全量検査（モード2）の 分割起動 実行方式、WAF 干渉と誤判定の防止、D-M-18-8・D-M-18-9 を追加
A39: 0.4 | B39: 2026-08-19 | C39: 「14_WBS_Phase3-4」シートを追加（Phase 3 実装〜リリースの残作業 WBS・工数見積 32 タスク、集計・リスク・スコープ外）
A40: 0.5 | B40: 2026-08-19 | C40: 「14_WBS」を追加（明細 75 行・オートフィルタ・区分の入力規則）。集計はピボットで行うため小計行と集計シートは持たない
A41: 0.6 | B41: 2026-08-19 | C41: 「14_WBS」を v3 に全面改訂（明細 125 行: W1 6 / W2-A 25 / W2-B 10 / W2-C 65 / W3 9 / W4〜W7 10。設計・実装・単体テストを ID 規約 -d/-i/-t で分離）。「15_WBS集計」を追加
A42: 0.7 | B42: 2026-08-19 | C42: WBS 内容列に用語補足を追記（15 行）・区分「改修」の定義を明記（15_WBS集計 前提 5）・W1 外部調整の記述を自立説明化（タスク名を平易化、内容を【これは何か】【なぜ調整が必要か】【やること】の 3 部構成に）
A43: 0.8 | B43: 2026-08-19 | C43: WBS v4 差分を反映: 手動変更検知（deploymentId 併読）の C12-d/i/t を新設（3 行・+9 人時）、W1-6 を「無ければ実装必須」に格上げ、S0-d を権限 6 アクション化、W5-1・W4-1 に「変更は必ず git 経由」原則を明記。明細 128 行・総合計 486.5 人時
A44: 0.9 | B44: 2026-09-11 | C44: md 改訂 4 件を反映: ① S3 認証構成情報方式（ADR-061 追記 2026-08-21。CodeCommit 巡回 → 認証構成情報の VersionId 比較、deploymentId 併読は廃止）② 実行モードを 2 つに統合（18 章。heartbeat 型＝旧 M2 は廃止）③ Lambda 3 本の日本語呼称（対象検索 / 認証実装チェック / アラート検知）④ 用語改定（監視資材 → 認証構成情報 / 資材バケット → 認証構成情報連携バケット / Monitoring Registry → 認証構成情報配置バケット）。あわせて 13_出典一覧の参照コミット・blob SHA を更新、15_WBS集計を v7（487 人時 / 126 行）に、16 の RC-13 を認証構成情報連携バケットへ差し替え（合計 $11〜13）。
A45: 0.9 | B45: 2026-09-11 | C45: 処理設計セクション（シート 18〜52）を統合。基本設計シート 01〜17 に変更なし（全セル照合済み）。シート 18 以降は tools/add_process_sheets_to_apipf.py の生成物のため直接編集しない
A46: ・図は本書内に挿入位置（【図 N 挿入位置】の枠）を用意し、作図は別途行う。挿入すべき図の一覧は「02_全体概要」シート末尾を参照。

Sheet 02_全体概要
A1: 全体概要（目的 / 方式サマリ / 用語）
A3: 1. 目的
A4: 観点 | B4: 内容
A5: この設計書群で定めること | B5: アプリチームが実装する認証の実装漏れを中央で継続検知する仕組み（＝認証実装確認処理）の基本設計。 ガイドラインが「アプリチームが守るルール」を定めるのに対し、本書は共通基盤チームが運用する中央機構の設計を定める。
A6: なぜ外形監視が要るか | B6: 静的解析や Config Rules は設定・コードの検査であり、実際に稼働中の API が未認証リクエストを弾いているかは保証できない。 実トラフィックで確認する外形監視が最後の砦になる。
A7: 存在意義 | B7: 静的解析をすり抜けた認証漏れを、稼働後に 検査 → 分類 → 通知 → 是正で捕捉する。
A10: 2. スコープ
A11: 対象 | B11: 本設計書で扱う
A12: 認証実装チェック（Lambda / 検査ロジック probe lib） | B12: 扱う
A13: App Registry（S3 台帳） | B13: 扱う
A14: OpenAPI Registry（S3・台帳と同一バケット） | B14: 扱う
A15: アラート検知 Lambda（4×4 → SNS） | B15: 扱う
A16: クロスアカウント IAM / 配布 | B16: 扱う
A17: 静的解析 / Config Rules | B17: 扱わない
A20: 3. 方式サマリ（現行仕様）
A21: 項目 | B21: 現行仕様
A22: 監視方式 | B22: 検査を各アプリに配らず、共通基盤アカウントの認証実装確認処理（Lambda）が全アプリを横断監視する。
A23: 変更検知 | B23: pull 型中央巡回 × 認証構成情報（S3）の VersionId 比較 単独。各 App アカウントの認証構成情報連携バケットをデプロイパイプライン最終段が更新し、中央はそれだけを読む（認証構成情報オンリー原則）。アプリ側に登録処理・登録イベントはない。
A24: 巡回頻度 | B24: 1 時間毎（EventBridge Scheduler が対象検索 Lambda を起動）。検知遅延は最大 1 時間。
A25: 実行モード | B25: 自動差分検査（モード1）（自動・変更のあったアプリの全 endpoint）+ 全量検査（モード2）（日次定期＋随時手動・全アプリ全 endpoint）の 2 つ。heartbeat 型検査（旧 M2）は廃止（2026-08-20）。
A26: Lambda 構成 | B26: 3 本（対象検索 Lambda / 認証実装チェック Lambda / アラート検知 Lambda）。すべて VPC 外に配置（NW-2 の明示的例外。承認は M-Q-10-3）。
A27: ストア | B27: S3 ×1 バケット（認証構成情報配置バケット）。registry/ = 台帳＋巡回スナップショット、openapi/ = spec コピー。DynamoDB は不使用。
A28: 検査方式 | B28: Negative（未認証検査）+ Positive（正規検査）の Hybrid 検証。結果を 4×4 真偽値表で分類する。
A29: 検査 範囲 | B29: アプリ単位の全 endpoint（endpoint 単位に絞らない）。
A30: 検査 経路 | B30: 実ユーザーと同じ経路（インバウンド境界の CloudFront + WAF → Origin Protection → API GW / ALB）。
A31: 通知 | B31: 4×4 分類の severity / priority に従い P1 Security 即時 / P2 Platform 24h / P3 App team の SNS へ振り分ける。
A32: アラーム | B32: CloudWatch metric AuthCheckCritical > 0。
... A35: アカウント構成 | B35: 共通基盤アカウント（中央・自社管理）／インバウンド境界＝ネットワーク監査アカウント（他組織管理の可能性）／各 App アカウント／認証基盤（Broker アカウント）／アウトバウンド境界アカウント（他組織管理）。
A38: 4. 用語（英語のまま使う語の意味）
A39: 用語 | B39: 意味
A40: 認証実装確認処理 | B40: 本機構の名称。アプリの認証実装漏れを中央で継続検知する仕組み。ADR-059 での名称は Central Auth Check Canary。
A41: 対象検索 Lambda | B41: 変更検知と登録の実行体（pull）。各 App アカウントの認証構成情報連携バケットを 1 時間毎に読み取り巡回し、VersionId 比較・新規発見・台帳登録・spec 取得を行い、変更のあったアプリの検査を起動する。
A42: 認証実装チェック Lambda | B42: 検査の実行体。台帳と仕様を読み、各 endpoint に未認証／正規の 2 種リクエストを送って認証の効き具合を確かめる。
A43: 検査（probe） | B43: 原義は「探針」。本設計では「実際に HTTP リクエストを送り、応答で認証の効き具合を確かめる検査」を指す。設定を読むのではなく、実物に触って確かめるのが特徴。
A44: 未認証検査（Negative probe） | B44: 認証情報なしでリクエスト → 401/403（Cookie 系は 302）が返れば正常。2xx が返れば認証漏れ。
A45: 正規検査（Positive probe） | B45: 有効なトークン付きでリクエスト → 200 が返れば API 稼働とテスト健全性を確認。Negative との組合せで誤検知を防ぐ。
A46: 検査ロジック（probe lib） | B46: 上記の検査を実装した共通ライブラリ。認証実装チェック Lambda が実行する。
A47: Pattern β | B47: 検査を各アプリに配らず中央 1 箇所から横断実行する方式。
A48: 自動差分検査（モード1） / 全量検査（モード2） | B48: 実行モード（2 つだけ）。自動差分検査（モード1、旧称 M1） = 1 時間毎の巡回で変化アプリのみ自動検査／全量検査（モード2、旧称 M3「手動全量検査」） = 全アプリ全 endpoint を日次定期＋随時手動で検査。heartbeat 型の常時定期検査（旧 M2）は廃止（2026-08-20）。
A49: STS / AssumeRole | B49: AWS Security Token Service =「一時的な認証情報の発行所」。AssumeRole で他アカウントのロール（例: DiscoveryReadRole）を引き受け、期限付き・最小権限の一時キーを得る。恒久キーを配らずにクロスアカウント読み取りを実現する標準手段。
...

Sheet 03_構成図
A1: 構成図
A3: 図1. 全体骨格（Pattern β）
A4: 【図1 全体骨格（Pattern β） 挿入位置】
A5: 描くべき内容: 4 アカウント区分と 11 ノード（対象検索 Lambda・認証構成情報配置バケット S3・認証実装チェック Lambda・アラート検知 Lambda・SNS／CloudFront+WAF ×2／認証構成情報連携バケット S3 ×2・API GW / ALB ×2）、矢印 11 本。巡回読み取り（対象検索 Lambda → 認証構成情報連携バケット）は境界非経由、検査は境界経由で描き分ける
A7: （この枠に図を貼り込む。要素・矢印の追加および省略はしない）
A9: アカウント | B9: ノード | C9: 役割・注記
A10: 共通基盤アカウント（中央運用・自社管理） | B10: 対象検索 Lambda | C10: 1 時間毎巡回
A11: 共通基盤アカウント（中央運用・自社管理） | B11: 認証構成情報配置バケット S3 | C11: 台帳 registry/ + spec openapi/
A12: 共通基盤アカウント（中央運用・自社管理） | B12: 認証実装チェック Lambda | C12: probe lib 共通。自動差分検査（モード1） / 全量検査（モード2） フル
A13: 共通基盤アカウント（中央運用・自社管理） | B13: アラート検知 Lambda | C13: 分類結果の振り分け
A14: 共通基盤アカウント（中央運用・自社管理） | B14: SNS | C14: P1 Security / P2 Platform / P3 App
A15: ネットワーク監査アカウント（境界層 ADR-039・他組織管理の可能性） | B15: CloudFront + WAF（アプリ A 用） | C15: インターネット境界
A16: ネットワーク監査アカウント（境界層 ADR-039・他組織管理の可能性） | B16: CloudFront + WAF（アプリ B 用） | C16: インターネット境界
A17: App アカウント A | B17: 認証構成情報連携バケット S3 | C17: monitoring.yaml + openapi.yaml
A18: App アカウント A | B18: API GW / ALB | C18: 認証実装
A19: App アカウント B | B19: 認証構成情報連携バケット S3 | C19: —
A20: App アカウント B | B20: API GW / ALB | C20: 認証実装
A23: # | B23: From | C23: To | D23: ラベル | E23: 経路区分
A24: 1 | B24: 対象検索 Lambda | C24: 認証構成情報連携バケット S3（App A） | D24: 読み取り AssumeRole：認証構成情報 VersionId 比較・monitoring.yaml・spec 取得 | E24: 巡回読み取り（境界非経由）
A25: 2 | B25: 対象検索 Lambda | C25: 認証構成情報連携バケット S3（App B） | D25: 同 | E25: 巡回読み取り（境界非経由）
A26: 3 | B26: 対象検索 Lambda | C26: 認証構成情報配置バケット S3 | D26: 自動登録・スナップショット・spec Put | E26: 中央内部
A27: 4 | B27: 対象検索 Lambda | C27: 認証実装チェック Lambda | D27: 変化あり → 自動差分検査（モード1）起動 | E27: 中央内部
A28: 5 | B28: 認証実装チェック Lambda | C28: 認証構成情報配置バケット S3 | D28: 台帳 List/Get + spec Get（自動差分検査（モード1）対象 / 全量検査（モード2） 全量） | E28: 中央内部
A29: 6 | B29: 認証実装チェック Lambda | C29: CloudFront + WAF（アプリ A 用） | D29: 検査は実 UX と同じ境界経由 | E29: 検査（In 境界経由）
A30: 7 | B30: CloudFront + WAF（アプリ A 用） | C30: API GW / ALB（App A） | D30: — | E30: 検査（In 境界経由）
A31: 8 | B31: 認証実装チェック Lambda | C31: CloudFront + WAF（アプリ B 用） | D31: — | E31: 検査（In 境界経由）
A32: 9 | B32: CloudFront + WAF（アプリ B 用） | C32: API GW / ALB（App B） | D32: — | E32: 検査（In 境界経由）
A33: 10 | B33: 認証実装チェック Lambda | C33: アラート検知 Lambda | D33: CRITICAL / WARN / INFO | E33: 中央内部
A34: 11 | B34: アラート検知 Lambda | C34: SNS（P1/P2/P3） | D34: — | E34: 中央内部
A36: 注記: 境界（CloudFront + WAF）はネットワーク監査アカウントにあり、検査はそこを実ユーザーと同じ経路で通る
A37: 注記: 巡回の読み取り（対象検索 Lambda → 認証構成情報連携バケット）は境界を通らない。AWS API（S3）を読み取りロールで直接呼ぶ。変更検知は認証構成情報の VersionId 比較で、認証構成情報に現れないコンソール直変更は L2 Config Rules + 全量検査（モード2、日次定期・最大 24h）が補完
A39: 図2. 統合構成図（登録・トリガー・検査・通知）
A40: 【図2 統合構成図（登録・トリガー・検査・通知 ①〜⑥） 挿入位置】
A41: 描くべき内容: 運用者（全量検査（モード2）を随時手動起動）＋ Scheduler（日次定期起動）+ 13 ノード。①AssumeRole ②認証構成情報 List・VersionId 比較 / GetObject ③台帳・spec 登録（lastArtifactVersions 更新）④自動差分検査（モード1）起動 ⑤Neg/Pos 検査 ⑥Metrics・Alert、および無番号の EventBridge→対象検索 Lambda／全量検査（モード2）／台帳取得／CloudFront→API GW／アラート検知 Lambda→SNS／Service Catalog→API GW
A43: （この枠に図を貼り込む。要素・矢印の追加および省略はしない）
A45: アカウント | B45: ノード | C45: 役割・注記
A46: （外部） | B46: 運用者 | C46: 全量検査（モード2） 手動実行
A47: 共通基盤アカウント（中央運用・自社管理） | B47: EventBridge Scheduler | C47: 1 時間毎
A48: 共通基盤アカウント（中央運用・自社管理） | B48: 対象検索 Lambda | C48: 発見・差分検知・OpenAPI 取得
A49: 共通基盤アカウント（中央運用・自社管理） | B49: 認証構成情報配置バケット S3 | C49: registry/（台帳 + スナップショット）／openapi/（spec コピー）
...

Sheet 04_リソース一覧
A1: 構成リソース一覧（中央 / App / 境界）
A3: 1. 共通基盤アカウント（中央）側
A4: リソース | B4: AWS サービス | C4: 役割
A5: EventBridge Scheduler | B5: EventBridge | C5: 定期起動の起点（2 本）。① 1 時間毎に対象検索 Lambda を起動（巡回）② 日次に認証実装チェック Lambda を mode=full で起動（全量検査（モード2）の定期実行）
A6: 対象検索 Lambda | B6: Lambda | C6: 変更検知と登録の実行体（pull）。各 App アカウントの認証構成情報連携バケットを読み取り巡回し、認証構成情報（{appId}/monitoring.yaml）の発見・認証構成情報 VersionId 比較（lastArtifactVersions）・台帳登録・spec 取得を行い、変更のあったアプリの検査を起動する
A7: 認証構成情報配置バケット | B7: S3（Versioning）×1 バケット | C7: 台帳 + spec コピーの一体ストア（DynamoDB は不使用）。registry/{appId}/{env}.json = 監視対象の台帳＋巡回スナップショット（baseUrl / authPattern / 通知先 / 前回確認した認証構成情報の VersionId（lastArtifactVersions）。設定値は monitoring.yaml 由来、書き手は対象検索 Lambda）。openapi/… = 認証構成情報連携バケットのデプロイ版 openapi.yaml（正本はベンダー git）のさらにコピーで、endpoint 一覧と公開印（MON-1）の情報源
A8: 認証実装チェック Lambda（認証実装確認処理） | B8: Lambda | C8: 検査の実行体。台帳と仕様を読み、各 endpoint に未認証／正規の 2 種リクエストを送って認証の効き具合を確かめる
A9: CloudWatch Metrics / アラーム | B9: CloudWatch | C9: 検査結果の記録と発報。AuthCheckCritical > 0 で認証漏れアラーム
A10: アラート検知 Lambda | B10: Lambda | C10: 通知の振り分け役。検知結果を 4×4 分類に従い P1/P2/P3 の宛先へ振り分ける（「全部 Security 行き」を防ぐ）
A11: SNS（P1 / P2 / P3） | B11: SNS | C11: 通知の出口。P1 = Security 即時 / P2 = Platform 24h / P3 = アプリチーム
A12: Secrets Manager | B12: Secrets Manager | C12: 正規検査用の資格情報（canary-central-readonly）。実行ごとに短命トークンを発行
A15: 2. 各 App アカウント側
A16: リソース | B16: AWS サービス | C16: 役割
A17: Service Catalog 製品 | B17: Service Catalog | C17: 正規デプロイの型。認証必須・Origin Protection・タグ付与を全部込みで提供（アプリはパラメータを選ぶだけ。登録処理は含まない＝中央が発見する）
A18: 認証構成情報連携バケット | B18: S3（auth-monitoring-artifacts-{accountId}、StackSets 配布・Versioning） | C18: 変更検知とメタデータの源。デプロイパイプライン最終段で monitoring.yaml（監視宣言）+ openapi.yaml（デプロイ版 spec の写し）+ 任意 deploy-info.json をアップロード。認証構成情報の VersionId 変化が自動差分検査（モード1）のトリガー
A19: DiscoveryReadRole | B19: IAM ロール（StackSets 配布） | C19: 中央からの読み取り窓口。対象検索 Lambda だけが AssumeRole でき、認証構成情報連携バケットの s3 read のみ
A20: ArtifactUploadRole-{appId} | B20: IAM ロール（StackSets 配布） | C20: ベンダー CI からの認証構成情報アップロード窓口。{appId}/* 限定の s3:PutObject のみ（デプロイロールと分離）
A21: API GW / ALB | B21: — | C21: 検査の対象（アプリの認証実装そのもの）。検査が実際に叩く
A24: 3. ネットワーク監査アカウント側（境界、他組織管理の可能性）
A25: リソース | B25: AWS サービス | C25: 役割
A26: アプリごとの CloudFront + WAF | B26: CloudFront / WAF | C26: インターネット境界（Origin Protection）。検査は実ユーザーと同じくここを経由して検査する（境界を破らない）
A29: 4. 1 行まとめ
A30: アプリがデプロイ時に認証構成情報（monitoring.yaml + openapi.yaml）を認証構成情報連携バケットへアップロードすると、中央の対象検索 Lambda が 1 時間毎の巡回（認証構成情報 VersionId 比較）で見つけて台帳・仕様を自動登録し、変更のあったアプリ（自動差分検査（モード1））と日次・監査時の全量（全量検査（モード2））に認証実装チェック Lambda が実際にリクエストを投げて認証漏れを検査、問題があれば 4×4 分類で適切なチームに通知される。アプリ側に登録処理はない（モノリスも同じ）。
A33: 5. 実装状態（「検証済み」と「未実装」を混同しないための一覧）。本設計は机上でなくローカル環境で実際に走らせて検証している。
A34: 構成要素 / 実装物 | B34: 状態 | C34: 内容
A35: central-probe-lib（probe lib） | B35: 実装済み | C35: 認証実装確認処理 本体（OpenAPI 動的発見、Hybrid 検証、4×4 分類）。node --test で 27 PASS（分類 16 + 検査 統合 4 + extractEndpoints 7）
A36: alert-router-lambda | B36: 実装済み | C36: 4×4 分類 → SNS routing。LocalStack 3.8.1 で台帳から alertRouting.p1 を解決し SNS Publish まで検証済み
A37: 対象検索 Lambda（discovery） | B37: 未実装（M-Q-17-4、Phase 3/4） | C37: 巡回・差分検知・自動登録・OpenAPI pull 取得
A38: probe lib の lib/registry.js | B38: 改修待ち（M-Q-12-3） | C38: 現実装は旧 DynamoDB Scan のまま。S3 台帳化に伴い S3 List/Get へ改修が必要
A39: app-registry-lambda | B39: 旧 push 型の参考実装 | C39: App Registry CRUD。PutItem / 正規化ロジックは対象検索 Lambda に流用予定。現行構成要素ではない
A40: openapi-export-lambda | B40: 旧 push 型の参考実装 | C40: get-export → S3 Put。ロジックは対象検索 Lambda に流用予定。現行構成要素ではない
A41: full orchestration E2E（認証実装チェック Lambda E2E / 正規検査 / metrics 着地） | B41: 未実施（SAM local or 実 AWS 要） | C41: ロジックは検証済み。残るは AWS 環境依存の full-run。要 PoC 項目あり
A42: 静的解析ルール（cfn-guard 3 + Semgrep 3） | B42: フィクスチャ検証済み | C42: ローカル検証で実バグ 2 件を修正。静的解析自体は本機構のスコープ外（別領域）だが、本設計のローカル検証範囲に含む
A45: 6. Runtime / SDK
A46: 対象 | B46: バージョン | C46: 備考
A47: 認証実装チェック Lambda（現行） | B47: Node.js 22 / AWS SDK v3 | C47: probe lib を実行、synthetics 抽象は https 実装で注入
A48: 対象検索 Lambda | B48: Node.js 22 / AWS SDK v3 | C48: Organizations 列挙 + 読み取り AssumeRole + 認証構成情報 VersionId 比較
A49: アラート検知 Lambda | B49: Node.js 22 / AWS SDK v3 | C49: 4×4 分類に基づく SNS Publish

Sheet 05_処理フロー
A1: 処理フロー（巡回 ①〜⑦ / 検査シーケンス / エンドツーエンド）
A3: 図4. 巡回フロー（自動差分検査（モード1） トリガー）
A4: 【図4 巡回フロー（①〜⑦ + 新規発見・消滅検知） 挿入位置】
A5: 描くべき内容: EventBridge（1h）→ 対象検索 Lambda。①Organizations 列挙 ②AssumeRole（認証構成情報 s3 read-only）③認証構成情報 List（{appId}/ プレフィックス）④認証構成情報 VersionId 取得 ⑤lastArtifactVersions 比較 ⑥GetObject（monitoring.yaml / openapi.yaml）→ 台帳更新・spec Put ⑦自動差分検査（モード1）起動 → lastArtifactVersions 更新。新規発見・消滅検知・メタ不足／認証構成情報 staleness の分岐
A7: （この枠に図を貼り込む。要素・矢印の追加および省略はしない）
A9: ステップ | B9: 主体 | C9: 相手 | D9: 内容
A10: ① 列挙 | B10: 対象検索 Lambda | C10: AWS Organizations | D10: 対象 App アカウントを列挙（⚠ organizations:ListAccounts は管理アカウント限定のため列挙方式は M-Q-17-2 で確定）
A11: ② AssumeRole | B11: 対象検索 Lambda | C11: 各 App アカウント | D11: 各アカウントに StackSets 配布済みの読み取り専用ロール（認証構成情報連携バケットの s3 read のみ）で入る
A12: ③ 認証構成情報列挙 | B12: 対象検索 Lambda | C12: App アカウントの認証構成情報連携バケット | D12: 認証構成情報連携バケットの {appId}/ プレフィックスを List。{appId}/monitoring.yaml が置かれている = 監視対象
A13: ④ バージョン取得 | B13: 対象検索 Lambda | C13: App アカウントの認証構成情報連携バケット | D13: monitoring.yaml / openapi.yaml の VersionId（と ETag）を取得
A14: ⑤ 差分判定 | B14: 対象検索 Lambda | C14: 認証構成情報配置バケット S3 | D14: 台帳の lastArtifactVersions と比較。違えば「前回確認から認証構成情報が更新された = 新しい版がデプロイされた」
A15: ⑥ 内容取得 | B15: 対象検索 Lambda | C15: App アカウントの認証構成情報連携バケット / 認証構成情報配置バケット S3 | D15: 変化したアプリのみ GetObject で monitoring.yaml / openapi.yaml を取得し、台帳更新・OpenAPI Registry へ Put
A16: ⑦ 自動差分検査（モード1）起動 | B16: 対象検索 Lambda | C16: 認証実装チェック Lambda | D16: 変化のあったアプリを対象に認証実装チェック Lambda を invoke（{mode:'delta', appId, env}）。完了後 lastArtifactVersions を更新
A17: 新規発見 | B17: 対象検索 Lambda | C17: 認証構成情報配置バケット S3 | D17: 台帳に無い {appId}/monitoring.yaml は自動登録。「登録漏れ」という概念自体が消える
A18: 消滅検知 | B18: 対象検索 Lambda | C18: 認証構成情報配置バケット S3 | D18: 認証構成情報（monitoring.yaml）の削除は台帳を enabled=false に（棚卸しアラート）
A19: （分岐） | B19: 対象検索 Lambda | C19: メタ不足アラート | D19: monitoring.yaml 不備 / 認証構成情報 staleness の場合
A20: 注記: 変更検知の単位は認証構成情報オブジェクト。マルチパートアップロードでは ETag が MD5 と一致しないため、VersionId 主・ETag 副で比較する（認証構成情報連携バケットは Versioning 必須）。
A23: 認証構成情報とデプロイの関係
A24: 観点 | B24: 現行仕様
A25: 認証構成情報 | B25: 認証構成情報はデプロイされた版の写しであり、git のブランチ・コミットの概念は中央からは見えない（追跡が必要な場合は任意の deploy-info.json に commitId 等を書ける）
A26: probe 範囲 | B26: アプリ単位の全 endpoint（endpoint 単位に絞らない。認証 middleware 削除は差分からどの endpoint に効くか判定できないため）
A31: 図5. 検査シーケンス（1 回の実行）
A32: 【図5 検査シーケンス（1 回の実行 ①〜⑨） 挿入位置】
A33: 描くべき内容: ①台帳 scan ②spec fetch ③extractEndpoints ④未認証検査 ⑤正規検査 ⑥分類 ⑦アラート検知 Lambda 起動 ⑧putMetrics ⑨AuthCheckCritical。アプリループと endpoint ループの入れ子を明示
A35: （この枠に図を貼り込む。要素・矢印の追加および省略はしない）
A37: # | B37: 主体 | C37: 相手 | D37: 処理
A38: ① | B38: 認証実装確認処理 | C38: App Registry（S3 台帳） | D38: scanEnabledApps（enabled=true）
A39: ② | B39: 認証実装確認処理 | C39: OpenAPI Registry S3 | D39: （各アプリのループ）fetchSpec（openApiS3Key）
A40: ③ | B40: 認証実装確認処理 | C40: 認証実装確認処理 | D40: extractEndpoints（アノテーション解釈）
A41: ④ | B41: 認証実装確認処理 | C41: アプリ CloudFront | D41: （各 endpoint のループ）未認証検査（認証ヘッダなし）
A42: ⑤ | B42: 認証実装確認処理 | C42: アプリ CloudFront | D42: 正規検査（Bearer 等、対象時のみ）
A43: ⑥ | B43: 認証実装確認処理 | C43: 認証実装確認処理 | D43: 分類（4×4 真偽値表）
A44: ⑦ | B44: 認証実装確認処理 | C44: アラート検知 Lambda | D44: severity != OK のとき 起動AlertRouter
A45: ⑧ | B45: 認証実装確認処理 | C45: CloudWatch | D45: putMetrics（per-app 集計）
A46: ⑨ | B46: 認証実装確認処理 | C46: 認証実装確認処理 | D46: CRITICAL があれば AuthCheckCritical 発火
A48: 実装対応: index.js（ハンドラ）+ lib/registry.js（①）+ lib/openapi.js（②③）+ lib/probe.js（④⑤）+ lib/classify.js（⑥）+ lib/emit.js（⑦⑧）
A50: 図6. エンドツーエンド フロー（deploy → 検知 → 通知 → 是正）
A51: 【図6 エンドツーエンド フロー（①〜⑧） 挿入位置】
A52: 描くべき内容: ①デプロイ & 認証構成情報アップロード（静的解析 pass）②巡回発見（認証構成情報 VersionId 比較・最大 1h）③自動差分検査（モード1）自動 / 全量検査（モード2、日次+手動）④検査 ⑤分類（OK は Metrics のみ・それ以外は ⑥ へ）⑥アラート検知 Lambda ⑦通知 P1 / P2 / P3 ⑧是正 SLA。担当章の帯を添える
A54: （この枠に図を貼り込む。要素・矢印の追加および省略はしない）
...

Sheet 06_実行トリガー
A1: 検査の実行タイミング（トリガー）設計 — いつ・何をきっかけに検査が走るか
A2: 自動差分検査（モード1）= 1 時間毎の巡回で「変更があった」と検知されたアプリを自動検査（認証構成情報連携バケットの認証構成情報 VersionId 比較）
A3: 全量検査（モード2）= 全アプリ・全量を 日次の定期自動実行＋監査時などの随時手動実行 で検査
A4: heartbeat 型検査（旧 M2、重要 endpoint への 5-15 分 probe）は廃止（2026-08-20）。シグナルなし変化は日次全量が受け、重要 endpoint の選定が不要になった
A5: 検査が「どう動くか」は 05_処理フロー、「いつ動くか」は本シート
A7: 実行基盤は Lambda、モードは自動差分検査（モード1）+ 全量検査（モード2）の 2 つ。heartbeat 型検査（旧 M2）は廃止。
A9: 1. モード一覧
A10: 【図7 実行モードの時間軸と 検査 範囲 挿入位置】
A11: 描くべき内容: 横軸を時間として、自動差分検査（モード1） = 1 時間毎の巡回（読み取り）と変更検知時のみ検査（変更アプリの全 endpoint）／全量検査（モード2） = 日次定期＋随時手動・全アプリ全 endpoint を並べ、検知遅延 最大 1 時間（モード1）／最大 24 時間（モード2）を明示。heartbeat 型検査（旧 M2）は廃止済みのため描かない
A13: （この枠に図を貼り込む。要素・矢印の追加および省略はしない）
A15: モード | B15: トリガ | C15: 範囲 | D15: 頻度 | E15: 状態
A16: 自動差分検査（モード1） | B16: 中央巡回（対象検索 Lambda が 1 時間毎に各 App アカウントの認証構成情報連携バケットを読み取り、認証構成情報 VersionId の変化を確認） | C16: 変更のあったアプリの全 endpoint | D16: 1 時間毎（検知遅延 最大 1h） | E16: Phase 1
A17: 全量検査（モード2） | B17: 日次定期（EventBridge Scheduler）+ 運用者の手動（随時） | C17: 全アプリ全 endpoint | D17: 日次 + オンデマンド | E17: Phase 1
A20: 2. 自動差分検査（モード1）の巡回と heartbeat 型検査（旧 M2）の違い（heartbeat 型を廃止した理由）
A21: ・自動差分検査（モード1）の巡回は「認証構成情報連携バケットの読み取り」（VersionId 比較）であり、検査（HTTP 検査）は変更のあったアプリだけに飛ぶ。heartbeat 型検査（旧 M2）は「endpoint への検査を常時定期実行」する別物で、重要 endpoint の定義がないと全量検査の重さに戻る。
A22: ・その重要 endpoint の定義・維持はアプリチームとの業務会話に依存し（全 GET か / 認証必須のみか / 業務上の重要度か）、コストが検知価値に見合わない。全量なら選定自体が不要になる。
A23: ・自動差分検査（モード1）で「認証構成情報の更新 = 新しい版がデプロイされた事実」を最大 1 時間遅れで捕捉でき、全量検査（モード2、日次定期＋手動）で「網羅確認」ができるため、常時検査がなくても認証漏れの主要な入り口は塞げる。
A24: ・したがって heartbeat 型検査（旧 M2）は廃止（2026-08-20、D-M-18-3）。シグナルなしの変化は全量検査（モード2）の日次定期実行が最大 24 時間で受け、設定レベルの即時性は Config Rules（L2）が受け持つ。
A27: 3. 自動差分検査（モード1）の差分粒度は「アプリ単位」
A28: 粒度 | B28: 見逃すケース | C28: 採否
A29: endpoint 単位（OpenAPI diff） | B29: コードで認証 middleware を外したが OpenAPI は不変 → 差分に出ず見逃す | C29: 不採用
A30: アプリ単位（変更アプリの全 endpoint） | B30: — | C30: 採用
A32: 認証漏れの典型（AuthorizationType=NONE / middleware 削除）は OpenAPI に現れないことが多い。だから「変更されたアプリは全 endpoint を 検査」する。全アプリ全量よりは軽く（変更アプリのみ）、endpoint 差分より安全
A35: 4. 自動差分検査（モード1）の実行基盤（発見 → 検査の 2 段）
A36: 項目 | B36: 内容
A37: トリガ | B37: 対象検索 Lambda の 1 時間毎巡回（認証構成情報連携バケットの認証構成情報 VersionId = lastArtifactVersions 比較）が変更を検知し、変更のあったアプリだけ自動差分検査（モード1）を起動する。アプリ側イベントには依存しない。
A38: 対象検索 Lambda | B38: EventBridge Scheduler（1h）起動。Organizations 列挙 + 読み取り AssumeRole + 差分判定
A39: 認証実装チェック Lambda | B39: 対象検索 Lambda から 起動（変化アプリのみ）。payload { mode:'delta', appId, env }
A40: 検査 ロジック | B40: lib/probe.js / classify.js / emit.js を共通流用。synthetics 抽象を素の https 実装で注入
A43: 5. 全量検査（モード2）（手動）
A44: 項目 | B44: 内容
A45: トリガ | B45: 日次定期（EventBridge Scheduler）+ 手動（運用者が CLI / コンソールから invoke）
A46: 範囲 | B46: 全アプリ全 endpoint（台帳 registry/ を List）
A47: 用途 | B47: 初回の全量確認 / 大きな変更後 / 監査前 / 定期棚卸し（人が判断）
A48: 実行基盤 | B48: 自動差分検査（モード1）と同じ認証実装チェック Lambda（mode=full）。実装 1 つを payload で切替
A49: 起動例 | B49: aws lambda invoke --function-name central-auth-probe --payload '{"mode":"full"}' /dev/null ／ 特定アプリだけ全量: {"mode":"full","appId":"expense-api","env":"prod"}
A50: 実行方式 | B50: mode=full は台帳を List した後、アプリ単位に自分自身を mode=delta 相当で 分割起動する（1 Lambda 実行 = 1 アプリ）。全量を 1 実行で回さないため、アプリ数が増えても Lambda 15 分制限に当たらない
A51: コスト | B51: 日次定期実行分のコストのみ。随時の手動実行は必要な時だけ人が回す
A54: 6. 受容した穴 2 つと補完レイヤー
A55: 【図8 受容した穴 2 つと補完レイヤーの関係 挿入位置】
...

Sheet 07_データ定義
A1: データ定義
A2: 本シートは台帳スキーマ・monitoring.yaml 規約・OpenAPI アノテーション・CloudWatch Metrics・4×4 真偽値表・Alert イベント形式のデータ定義を示す。
A3: 0. このシートに載せるデータ定義の一覧
A4: # | B4: データ定義 | C4: 中身 | D4: 何のために使うか | E4: 本シートの節
A5: 1 | B5: App Registry（S3 台帳）スキーマ | C5: 1 アプリ × 1 環境ぶんの管理項目 14 個（appId / env / baseUrl / authPattern / openApiS3Key / testTokenSecret / alertRouting / enabled / registeredAt / artifactBucket / artifactPrefix / lastArtifactVersions / deployInfo / lastSeenAt）+ JSON 例 | D5: 中央が「どのアプリをどう検査するか」を読む唯一の管理簿 | E5: 1.
A6: 2 | B6: 認証構成情報配置バケット S3 構造 | C6: バケットとキー体系（registry/{appId}/{env}.json、openapi/{accountId}/{appId}/openapi.yaml）・Versioning | D6: 台帳と API 仕様書コピーの置き場所の取り決め | E6: 2.
A7: 3 | B7: authPattern enum（6 値） | C7: 認証方式の識別子と、方式ごとの未認証時の期待応答・正規検査の手段 | D7: 検査の期待値（401 / 403 / 302 など）を切り替える | E7: 3.
A8: 4 | B8: 認証構成情報の規約 | C8: 各 App アカウントの認証構成情報連携バケットに置く認証構成情報（バケット・キー体系・monitoring.yaml / openapi.yaml / 任意 deploy-info.json）＋項目規約と不備時の挙動、アップロード権限 | D8: 台帳への供給源。このファイルの有無が監視対象の宣言そのもの | E8: 4.
A9: 5 | B9: OpenAPI アノテーションと MON-1 | C9: 検査制御の印 7 種（公開明示 x-synthetics-skip-auth-check ほか）と default-deny の原則 | D9: どの endpoint をどう検査するかの指定 | E9: 5.
A10: 6 | B10: CloudWatch Metrics | C10: namespace・Dimensions・メトリクス 5 種・アラーム条件 | D10: 検査結果の記録と発報 | E10: 6.
A11: 7 | B11: 4×4 真偽値表 | C11: 未認証検査 × 正規検査の応答組合せ 8 行 → 重大度・優先度・通知先 | D11: 検知結果の判定ロジック（検査と アラート検知 Lambda が共有） | E11: 7.
A12: 8 | B12: Alert イベント形式 | C12: 検査 → アラート検知 Lambda へ渡す JSON の 10 項目 | D12: 通知の入力データ | E12: 8.
A13: 9 | B13: 環境別の検査動作 | C13: 本番 / 検証それぞれの未認証検査・正規検査・POST の実施範囲 | D13: 本番での副作用回避の規則 | E13: 9.
A14: 10 | B14: WAF 干渉と誤判定の防止 | C14: WAF 由来 403 の識別条件と対策 2 段（識別ヘッダ許可・分類側の防御） | D14: 4×4 判定の前提条件（403 の意味の切り分け） | E14: 10.
A15: 11 | B15: 検査起動 payload | C15: 対象検索 Lambda → 検査 Lambda の受け渡し形式（mode / appId / env）と起動例 | D15: 自動差分検査（モード1）の自動起動・全量検査（モード2）の全量指定 | E15: 11.
A16: 12 | B16: 検査識別ヘッダ X-Auth-Probe | C16: ヘッダ名・値の保管場所・付与元・WAF 許可ルールとの対応 | D16: 検査が WAF にブロックされ誤判定になるのを防ぐ | E16: 12.
A20: 1. App Registry（S3 台帳）スキーマ
A21: 置き場: 認証構成情報配置バケットの registry/{appId}/{env}.json（1 アプリ×環境 = 1 JSON オブジェクト。DynamoDB は不使用）。対象検索 Lambda が巡回（各 App アカウントの認証構成情報連携バケットの monitoring.yaml）から自動登録・同期し、認証実装確認処理が registry/ を List → Get する。
A23: 項目 | B23: 型 | C23: 説明 | D23: 例 | E23: 由来 / 管理
A24: appId | B24: S | C24: 台帳の識別子（キーと同値） | D24: expense-api | E24: キーと同値 | F24: データ契約 §2.1, 12 §12.1
A25: env | B25: S | C25: 台帳の識別子（キーと同値） | D25: prod / stg / dev | E25: キーと同値 | F25: データ契約 §2.1, 12 §12.1
A26: baseUrl | B26: S | C26: 検査先 CloudFront URL（Origin Protection 経由） | D26: https://expense.example.com | E26: monitoring.yaml | F26: データ契約 §2.1, 12 §12.1
A27: authPattern | B27: S | C27: 認証方式 enum | D27: api-gw-jwt | E27: monitoring.yaml | F27: データ契約 §2.1, 12 §12.1
A28: openApiS3Key | B28: S | C28: spec コピーのキー | D28: openapi/111122223333/expense-api/openapi.yaml | E28: 巡回が導出 | F28: データ契約 §2.1, 12 §12.1
A29: testTokenSecret | B29: S | C29: Positive 用 token の Secret 名 | D29: canary-central-readonly | E29: monitoring.yaml | F29: データ契約 §2.1, 12 §12.1
A30: alertRouting | B30: M | C30: 通知先 {p1,p2,p3} の SNS ARN（未設定は全社デフォルト） | D30: { p1: 'arn:aws:sns:...:security' } | E30: 台帳のみ・中央管理 | F30: データ契約 §2.1, 12 §12.1
A31: enabled | B31: BOOL | C31: 監視有効フラグ（monitoring.yaml には置かない） | D31: TRUE | E31: 台帳のみ・中央管理 | F31: データ契約 §2.1, 12 §12.1
A32: registeredAt | B32: S | C32: ISO8601 登録日時 | D32: 2026-07-06T00:00:00Z | E32: 巡回 | F32: データ契約 §2.1, 12 §12.1
A33: artifactBucket | B33: S | C33: 発見元の認証構成情報連携バケット | D33: auth-monitoring-artifacts-111122223333 | E33: 巡回が記録 | F33: データ契約 §2.1, 12 §12.1
A34: artifactPrefix | B34: S | C34: 発見元の {appId}/ プレフィックス | D34: expense-api/ | E34: 巡回が記録 | F34: データ契約 §2.1, 12 §12.1
A35: lastArtifactVersions | B35: M | C35: 前回確認した認証構成情報（monitoring.yaml / openapi.yaml）の S3 VersionId。差分判定の基準 | D35: { 'monitoring.yaml': '3z9K…', 'openapi.yaml': '8aQ2…' } | E35: 巡回状態 | F35: データ契約 §2.1, 12 §12.1
A36: deployInfo | B36: M | C36: ベンダー CI が申告した commitId / deployedAt 等の追跡用参考値（検知には使わない。staleness 検知の補助） | D36: { commitId: 'a1b2c3d…', deployedAt: '2026-08-20T12:00:00Z' } | E36: deploy-info.json（任意） | F36: データ契約 §2.1, 12 §12.1
A37: lastSeenAt | B37: S | C37: 最後に観測した日時（消滅検知用） | D37: 2026-08-21T00:00:00Z | E37: 巡回状態 | F37: データ契約 §2.1, 12 §12.1
A42: baseUrl / authPattern / testTokenSecret は monitoring.yaml 由来（巡回同期）、artifactBucket / artifactPrefix / lastArtifactVersions / lastSeenAt は巡回状態、alertRouting / enabled は台帳のみで中央管理。認証実装確認処理は enabled=true のみ検査する。自動差分検査（モード1）は該当 1 オブジェクトのみ Get、全量検査（モード2）は全 List。旧スキーマ（repositoryName / branch / pathPrefix / lastCheckedCommitId / apiGatewayId / stage / deploymentId）は 2026-08-21 廃止。
A45: 台帳 JSON 例（キー例: registry/expense-api/prod.json）
A46: {
A47: "appId": "expense-api",
A48: "env": "prod",
A49: "baseUrl": "https://expense.example.com",
A50: "authPattern": "api-gw-jwt",
...

Sheet 08_セキュリティ・IAM
A1: セキュリティ・IAM
A3: 1. アカウント分離
A4: アカウント | B4: 置くもの | C4: 管理主体
A5: 共通基盤アカウント | B5: 認証実装確認処理のリソース群（App Registry / OpenAPI Registry / 認証実装チェック Lambda / アラート検知 Lambda / Secrets）+ 対象検索 Lambda + SNS + CloudWatch | C5: 自社管理
A6: ネットワーク監査アカウント（インバウンド境界） | B6: インターネット境界（アプリごとの CloudFront + WAF、Origin Protection、ADR-039） | C6: 他組織管理の可能性あり（ROSA 側 P-18）
A7: アウトバウンド境界アカウント | B7: Transit Gateway + Network Firewall（ドメインフィルタ） | C7: 他組織管理
A8: 各 App アカウント | B8: Service Catalog 製品 / 認証構成情報連携バケット S3 / API GW・ALB / DiscoveryReadRole / ArtifactUploadRole-{appId} | C8: 各アプリチーム
A9: 認証基盤（Broker アカウント） | B9: Keycloak /token（client_credentials） | C9: 認証基盤
A11: 検査は境界越しに実ユーザーと同じ経路で検査する。認証実装確認処理は共通基盤アカウント（自社管理）に置くため、境界が他組織管理になっても再設計は不要。影響は 検査 先経路の調整のみ（BD-Q-01）
A12: 巡回の読み取り経路（中央 → App）も境界を通らないため、境界の管理主体変更の影響を受けない
A15: 2. クロスアカウント要件の全体像
A16: # | B16: 経路 | C16: 方向 | D16: 手段 | E16: 権限
A17: 1 | B17: 巡回発見（認証構成情報の読み取り） | C17: 中央 → App アカウント（読み取り） | D17: 対象検索 Lambda が DiscoveryReadRole に AssumeRole → 認証構成情報連携バケットを読む | E17: s3 read-only（下記 3.）
A18: — | B18: 検査 → アプリ | C18: 中央 → App アカウント | D18: Public CloudFront URL | E18: 権限不要
A19: — | B19: 検査 → OAuth /token | C19: 中央 → 認証基盤 | D19: Public URL | E19: 権限不要
A21: 検査 自体はクロスアカウント権限を要さない（実ユーザーと同じ Public 経路）。権限が要るのは巡回の読み取りだけ。台帳への書き込みは中央アカウント内のみ
A24: 3. DiscoveryReadRole の設計
A25: 【図12 クロスアカウント IAM の関係 挿入位置】
A26: 描くべき内容: DiscoveryLambdaRole → 各 App の DiscoveryReadRole（認証構成情報連携バケットの s3 read-only・信頼先 1 本・ExternalId）への AssumeRole 1 種のみ。ベンダー CI → ArtifactUploadRole-{appId}（{appId}/* 限定 PutObject）の書き込み経路。StackSets の全アカウント同一名配布、CentralProbeRole / alert-router-lambda-role の権限範囲、台帳書き込みが中央アカウント内のみであること
A28: （この枠に図を貼り込む。要素・矢印の追加および省略はしない）
A30: 各 App アカウントに読み取り専用ロールを 1 つ配布し、中央の対象検索 Lambda だけが引き受けられるようにする
A32: // 権限（App アカウント側、read-only 最小。認証構成情報連携バケット限定）
A33: {
A34: "Version": "2012-10-17",
A35: "Statement": [
A36: {
A37: "Effect": "Allow",
... A73: 4. 必要な IAM 一覧
A74: 区分 | B74: ロール | C74: 使い手 | D74: 権限
A75: 共通基盤アカウント | B75: DiscoveryLambdaRole | C75: 対象検索 Lambda | D75: organizations:ListAccounts / sts:AssumeRole（各 App の DiscoveryReadRole）/ s3:PutObject・GetObject・ListBucket（認証構成情報配置バケット の registry/* + openapi/*）/ lambda:InvokeFunction（認証実装チェック Lambda）。※ 列挙方式は未決 M-Q-17-2（organizations:ListAccounts は Organizations 管理アカウント（または delegated admin）限定で、共通基盤アカウントからの直接呼び出しは不可。案 a なら管理アカウントの列挙用ロールへの sts:AssumeRole、案 b なら ssm:GetParameter に置換する）
A76: 共通基盤アカウント | B76: CentralProbeRole | C76: 認証実装チェック Lambda | D76: s3:GetObject・ListBucket（認証構成情報配置バケット：台帳 + spec）/ secretsmanager:GetSecretValue / cloudwatch:PutMetricData / lambda:InvokeFunction（アラート検知 Lambda）
A77: 共通基盤アカウント | B77: alert-router-lambda-role | C77: アラート検知 Lambda | D77: s3:GetObject（registry/*、alertRouting 解決）/ sns:Publish
A78: 各 App アカウント（StackSets 配布） | B78: DiscoveryReadRole | C78: 中央の対象検索 Lambda（AssumeRole） | D78: 認証構成情報連携バケットの s3:ListBucket / ListBucketVersions / GetObject / GetObjectVersion（read-only）
A79: 各 App アカウント（StackSets 配布） | B79: ArtifactUploadRole-{appId} | C79: 各アプリのベンダー CI（アプリごとの接続方式で Assume） | D79: 認証構成情報連携バケットの {appId}/* への s3:PutObject のみ
A80: 各 App アカウント（StackSets 配布） | B80: 認証構成情報連携バケット | C80: —（S3。Versioning 有効 + バケットポリシーで prefix 外 Put を Deny） | D80: —
A82: App アカウント側に置くのは認証構成情報連携バケット + 読み取りロール 1 本 + アプリ単位のアップロードロール。旧 push 型で必要だった中央への Invoke / 書き込み AssumeRole / Custom Resource 実行権限は不要のまま（中央への書き込み開放はしない）。
A84: 5. 配布（StackSets）
A85: 配布物 | B85: 手段 | C85: 内容
A86: DiscoveryReadRole | B86: CloudFormation StackSets（Organizations 連携・自動デプロイ） | C86: 新規アカウント作成時も自動で配布 → 巡回が即座に読める
A87: Service Catalog 製品 | B87: Portfolio 共有（Organizations / RAM） | C87: 認証必須 / Origin Protection / タグの「守られた API の型」
...

Sheet 09_アプリチーム向け手順
A1: アプリチーム向け手順
A2: アプリチーム（ベンダー）の作業は 3 点のみ。監視への登録作業はない（中央の機構が認証構成情報から自動で発見する）。
A4: 1. やること 3 点
A5: 手順 | B5: やること | C5: かんたんな説明
A6: 1 | B6: Service Catalog で製品を launch する | C6: AppId / Env / CostCenter / Owner を入力して払い出す。この製品には「認証が必ず有効な API」「Origin Protection」「必須タグ」があらかじめ組み込まれている。
A7: 2 | B7: デプロイパイプラインの最終段で認証構成情報をアップロードする | C7: 自アカウントの認証構成情報連携バケット（auth-monitoring-artifacts-{accountId}）の {appId}/ 配下に monitoring.yaml と openapi.yaml を置く。専用のアップロードロール（ArtifactUploadRole-{appId}）を Assume して Put する。CI から AWS へ接続する方式は、アプリごとの既存方式でよい。
A8: 3 | B8: OpenAPI に公開印を付ける | C8: 認証が不要（誰でも呼べる）な endpoint にのみ x-synthetics-skip-auth-check: true を記述する。詳細は下記 5.（MON-1）。
A10: 原則: アップロードは必ずデプロイ成功後に行うこと。これにより「認証構成情報がある = その版がデプロイ済み」が成り立ち、中央の検査が実態と一致する。変更は必ず CI/CD 経由で行い、コンソールでの直接変更はしない（認証構成情報に現れず検知が遅れる）。
A12: 責任分界（顧客・ベンダー合意事項）: 認証構成情報のアップロード漏れ・内容の誤りは、原則アプリ（ベンダー）側の責任とする。中央は検知網（認証構成情報の最終更新が古いアプリの棚卸しアラート・月次棚卸し・日次の全量検査）で補助するが、「認証構成情報が正しく上がっていること」の保証責任は負わない。この分界は顧客・ベンダーとの合意が必要（M-Q-17-7）。
A14: 2. やらなくてよいこと
A15: 項目 | B15: 理由
A16: 監視対象への登録作業・登録用のコード | B16: 中央の対象検索 Lambda が 1 時間毎に認証構成情報連携バケットを巡回して自動で見つけ、台帳に登録する。
A17: OpenAPI の中央へのアップロード | B17: 認証構成情報連携バケットに置いた openapi.yaml を中央が取得してコピーする。
A18: 通知先（SNS ARN）の設定 | B18: 認証構成情報には書かない。共通基盤チームが台帳側で管理する（未設定なら全社デフォルト）。
A19: 監視の一時停止（enabled） | B19: 認証構成情報には書かない。台帳側の中央管理。
A20: endpoint を追加したときの監視設定 | B20: openapi.yaml を更新して認証構成情報をアップロードすれば、次回巡回（最大 1 時間）で新しい endpoint も自動で検査対象になる。検査側の改修は不要。
A22: 3. 認証構成情報の置き方
A23: s3://auth-monitoring-artifacts-{accountId}/ ← 各アカウントに配布済み（Versioning 有効）
A24: {appId}/
A25: monitoring.yaml # 監視宣言（下記 4.）
A26: openapi.yaml # デプロイした版の API 仕様
A27: deploy-info.json # 任意: { "commitId": "…", "deployedAt": "…", "pipelineRunId": "…" }
A29: アップロードは ArtifactUploadRole-{appId} を Assume して行う。このロールは自アプリの {appId}/ 配下への Put だけができ、削除・読み取りはできない（他アプリの認証構成情報にも触れない）。
A31: 4. monitoring.yaml の書き方
A32: # {appId}/monitoring.yaml
A33: appId: expense-api # プレフィックスと一致必須
A34: environments:
A35: prod:
... A41: testTokenSecret: canary-central-readonly # 省略時は共通
A43: 項目 | B43: 書き方 | C43: 書き忘れ・間違いのとき
A44: {appId}/monitoring.yaml | B44: 必須。これが監視対象の宣言になる。 | C44: API 提供契約やタグがあるのに認証構成情報が無い場合は、中央の棚卸しで検出される。
A45: appId | B45: プレフィックス（フォルダ名）と一致させる。 | C45: 不一致は取り込み拒否 + メタ不足アラート。
A46: authPattern | B46: 認証方式を enum（6 種）から選ぶ。 | C46: 既定値 api-gw-jwt が使われ、未認証検査のみ実施 + メタ不足アラート。
A47: baseUrl | B47: CloudFront の URL を書く（API Gateway の直 URL ではない）。 | C47: 検査できないため、メタ不足アラート。
A48: openapi.yaml | B48: 同じ {appId}/ 配下に併置する。 | C48: 無い場合は endpoint リストを monitoring.yaml に列挙する（ALB 直モノリス等）。
A49: deploy-info.json | B49: 任意。commitId / deployedAt 等の追跡用。 | C49: 中央は検知に使わないため、無くても問題ない。
A51: 5. OpenAPI の公開印（MON-1）
A52: ルール: 本機構は「記述のない endpoint はすべて認証必須」と判定する（default-deny）。したがって、認証なしで公開する endpoint には x-synthetics-skip-auth-check: true を必ず記述する。記述漏れの場合、正しく公開している endpoint でも「認証漏れ」として P1（Security 即時）のアラートが発報される。
A54: ・「記述がない = 認証必須」とする理由: 「うっかり公開した endpoint」を必ず検知できる側に倒しているため。
A55: ・公開印は、アプリチームが必ず記述する必要がある唯一の監視用アノテーション（他は任意）。
...

Sheet 10_設計判断一覧
A1: 設計判断一覧（決定事項）
A2: 本シートは決定事項（D-M-*）のみを収める。未決事項（M-Q-* / BD-Q-*）は「11_未決事項」シートに分離。判断に至った経緯は ADR 参照列の ADR を参照する。なお参照した md 内に D-G-* の ID は存在しない。
A4: ID | B4: 判断 | C4: 根拠 | D4: ADR 参照
A5: D-M-10-1 | B5: Pattern β（中央集約）を採用 | C5: Deploy 漏れが構造的にゼロ、「中央でチェック」要件と一致 | D5: ADR-059
A6: D-M-10-2 | B6: データ定義はデータ契約を正とし、設計書は意図を説明する | C6: 実装と設計の二重管理を避ける | D6: —
A7: D-M-10-3 | B7: 設計は Phase 4 で実行検証してから確定 | C7: 「検証済み事実」を積み上げる方針（BD 品質方針） | D7: —
A8: D-M-10-4 | B8: Lambda 3 本は VPC 外配置（VPC / EP / TGW / NAT 不要）。検査の外向き HTTPS は NW-2（NWFW 経由）の明示的例外として受容し、宛先 allowlist のコード強制 + 中央管理コード + 監査で代償 | C8: 宛先が固定 3 種のみで任意外部 SaaS を呼ばない監視系に NWFW 経路を組むのは複雑さに見合わない。例外承認は M-Q-10-3、Phase 2 Private 対応時に 検査のみ VPC 化。In 境界（CloudFront + WAF）は従来どおり実 UX と同じ向きで通過 | D8: —
A9: D-M-11-1 | B9: Negative + Positive の Hybrid 検証を必須化 | C9: Negative 単独では構成ミスと認証漏れを区別不能 | D9: —
A10: D-M-11-2 | B10: 分類は 4×4 真偽値表、分類を 検査 / alert-router で共通化 | C10: 二重実装の分類ずれを防ぐ | D10: —
A11: D-M-11-3 | B11: 検査は Lambda + 共通 probe lib（OpenAPI 動的発見）。Synthetics / Multi Checks は将来オプション | C11: 動的発見が Pattern β に必須、定期実行は不要 | D11: —
A12: D-M-11-4 | B12: Cookie モノリスは 302 を認証拒否とみなし監視対象化 | C12: API GW 非依存アプリも担保 | D12: —
A13: D-M-11-5 | B13: CRITICAL で AuthCheckCritical メトリクス → アラーム発火 | C13: 「認証漏れ」を運用に即時可視化 | D13: —
A14: D-M-12-1 | B14: 台帳ストアは S3。DynamoDB は不使用 | C14: 消せない情報は 3 つ・書き手 1 本・MB 未満で DB が過剰。ストアを S3 1 つに集約 | D14: ADR-061 追記 2026-08-13
A15: D-M-12-2 | B15: 検査 先は CloudFront URL（API GW 直でない） | C15: Origin Protection を破らず実 UX 同一条件で検証 | D15: —
... A55: D-M-18-9 | B55: at-least-once + 冪等（lastArtifactVersions は自動差分検査（モード1）起動成功後のみ更新、発見 → 検査は非同期起動 + DLQ、アカウント単位の部分失敗分離）。全量検査（モード2）と大規模巡回はアプリ / アカウント単位の分割起動 | C55: Lambda 15 分制限に構造で当たらない。検査は読み取り検査で重複無害 | D55: —

Sheet 11_未決事項
A1: 未決事項（M-Q-* / BD-Q-*）
A2: 本シートは未決事項のみを収める。決定事項（D-M-*）は「10_設計判断一覧」シート。未決は未決のまま記載し、確定した設計としては書かない。担当・期限は未定のため空欄（記入用）。
A4: ID | B4: 内容 | C4: 解説・選択肢（回答記入用） | D4: 担当 | E4: 期限
A5: BD-Q-01 | B5: ROSA 側 P-18（監査アカウント他組織管理）確定時の責任分界 / 検査 先経路の改訂 | C5: 【解説】インターネット境界（CloudFront+WAF）が他組織管理になるかの確定待ち。確定しても中央リソースは自社の共通基盤アカウントにあるため再設計は不要で、検査が境界を通る経路の運用調整のみ発生する。【回答】当方では決められない（ROSA 側 P-18 の確定待ち）。→ 確定日と結果を記入: ＿＿
A6: M-Q-10-1 | B6: Central 障害時の Multilocation（DR region replica）採否 | C6: 【解説】中央（共通基盤アカウント）が障害になると監視が全停止する。別リージョンに監視系の複製を併走させるか。障害中も「検査が止まるだけ」で本番アプリには影響しない。【選択肢】a) Phase 1 は無し。復旧後に 全量検査（モード2）で追い付く（★）/ b) Phase 2 検討として残す / c) Phase 1 から複製を持つ 【→ 回答: ＿＿】
A7: M-Q-10-2 | B7: full-run（SAM local / 実 AWS）の実施タイミング | C7: 【解説】ローカルで検証済みのロジックを、実 AWS（or SAM）で通しで動かす時期の話。決定事項ではなく実施タイミングのみ。【回答例】「対象検索 Lambda 実装（M-Q-17-4）完了後に実施」で足りる。【→ 回答: ＿＿】
A8: M-Q-10-3 | B8: NW-2 例外（VPC 外 Lambda の Egress が NWFW 非経由）の明示的承認をセキュリティ / 境界管理の他組織から取得 | C8: 【解説】監視 Lambda を VPC 外に置いたため、外向き通信が組織のアウトバウンド統制（Network Firewall のドメインフィルタ）を通らない。これは社内ルール NW-2 の例外にあたるため、セキュリティ部門と境界管理の他組織から明示的な承認を得る必要がある。宛先が固定 3 種のみ・コードは中央管理という例外理由と代償統制の説明資料は「08_セキュリティ・IAM」シートの「VPC 外配置の判断」表がそのまま使える。【回答】承認取得タスク。承認者と取得日を記入: ＿＿
A9: M-Q-11-2 | B9: SigV4 Positive（api-gw-iam）の実装（@aws-sdk/signature-v4 手動署名、Phase 2） | C9: 【解説】AWS IAM 認証（SigV4 署名）の API に対する「正しい署名を付けたら通る」側の検査は未実装（Phase 2 計画）。未認証を弾く検査（Negative）は今でも可能。【回答】決定不要（Phase 2 実装タスク）。
A10: M-Q-11-3 | B10: Cookie モノリス Positive（Puppeteer ログイン）の実装 | C10: 【解説】Cookie ログイン型アプリ（モノリス/BFF）の「正規ログインしたら見える」側の検査は、ブラウザ自動操作（Puppeteer）の実装が必要で未実装。未ログインを弾く検査（302 確認）は今でも可能。【回答】決定不要（Phase 2 実装タスク）。
A11: M-Q-11-4 | B11: Positive トークン スコープ B（canary 専用テナント / 合成データ）の設計（認証基盤 Keycloak へ引き渡し）。Phase 1 は A、機微データ API から B へ移行 | C11: 【解説】検査用の正規トークンが漏れても実データに一切届かないようにする強化策。認証基盤（Keycloak）側に「検査専用テナント/合成データしか読めないスコープ」を作ってもらう必要がある（現在はスコープ A=全 API 読み取り専用で開始）。【回答】認証基盤チームへの引き渡し事項。依頼日と回答を記入: ＿＿
A12: M-Q-11-5 | B12: 検査 識別ヘッダの WAF 許可ルールを境界管理側（ネットワーク監査アカウント）へ依頼・合意。M-Q-10-3（NW-2 例外承認）と同じ相手のため同梱で調整可 | C12: 【解説】検査はインバウンド境界の WAF を通過するため、WAF（Bot Control / ジオ制限等）が 検査 自体を 403 でブロックすると、認証レイヤーに到達していないのに「401/403 = 認証は正常」と誤判定する（偽陰性）、または「認証逆転 CRITICAL」と誤報する。対策として 検査に固定の識別ヘッダ（例 X-Auth-Probe）を付け、各アプリの WAF でレート／Bot Control ルールの対象外とする許可ルールを境界管理側に入れてもらう必要がある。M-Q-10-3（NW-2 例外承認）と依頼先が同じため同梱で調整できる。【回答】依頼・合意タスク。依頼日と合意内容を記入: ＿＿
A13: M-Q-12-1 | B13: alertRouting を全アプリ個別指定か、env 既定 + 上書きか | C13: 【解説】alertRouting とは「このアプリのアラートをどのチーム（SNS トピック）に届けるか」の宛先設定（台帳の 1 項目）。設定が無いアプリは全社デフォルトのトピックに届く 2 段構え。全アプリに個別設定を必須にするか、デフォルト運用で始めるかの選択。【選択肢】a) 全社デフォルトで開始し、必要なアプリだけ個別設定（★・運用が軽い）/ b) 全アプリ個別設定を必須にする（宛先は正確だが登録運用が重い）【→ 回答: ＿＿】
A14: M-Q-12-2 | B14: バケットのバックアップ方針（Versioning は有効。加えてレプリケーション要否） | C14: 【解説】台帳と spec を置く S3 バケットの保全レベル。Versioning（誤更新を履歴から戻せる）は有効済み。加えて別リージョンへの複製（レプリケーション）まで要るか。データは巡回で再生成可能なため失っても再構築できる。【選択肢】a) Versioning のみ（★）/ b) クロスリージョンレプリケーションも追加 【→ 回答: ＿＿】
A15: M-Q-12-3 | B15: probe lib lib/registry.js の S3 対応改修（DynamoDB Scan → S3 List/Get。M-Q-17-4 対象検索 Lambda 実装と同時に）+ 手動更新との競合対策（ETag 条件付き PUT） | C15: 【解説】実装済みコード registry.js が旧 DynamoDB 読み取りのままで、S3 台帳への切替改修が必要。【回答】決定不要（実装タスク。対象検索 Lambda 実装 M-Q-17-4 と同時に対応）。
A16: M-Q-13-2 | B16: S3 Object Lock（改ざん防止）の要否 | C16: 【解説】S3 Object Lock = 一定期間削除・上書きを不可能にする改ざん防止機能。監査証跡レベルの保全が必要かどうか。台帳・spec は運用データであり Versioning で通常は十分。【選択肢】a) 不要（Versioning で足りる ★）/ b) 必要（監査要件がある場合）【→ 回答: ＿＿】
... A43: OP-Q-4 | B43: 拡大時（10 アプリ超）の体制見直しトリガー（件数 or 工数の閾値） | C43: 【解説】拡大時（10 アプリ超）の体制見直しトリガー（件数 or 工数の閾値）。30 アプリ時は月 55h（0.34 FTE）の想定で、どの水準で増員・専任化を検討するかを決めておく（出典: 17_運用工数 シート）。【→ 回答: ＿＿】
A47: 解決済み（参照用）
A48: ID | B48: 内容 | C48: 結論
A49: M-Q-18-2 | B49: 自動差分検査（モード1） トリガの確定 | C49: 解決: 中央巡回（pull、1h）に統一（ADR-061）
A50: M-Q-18-4 | B50: モノリスの変更を 全量検査（モード2）で補う | C50: 解消: git 巡回でモノリスも自動発見・自動検知。全量検査（モード2）の役割は「git に現れない変更（コンソール直変更等）の網羅確認」に純化
A51: M-Q-11-1 | B51: 検査 頻度（5min / 15min）とコストのバランス | C51: 解決: 自動差分検査（モード1）=巡回差分（1h）/ 全量検査（モード2）=手動の 2 モードに再設計済みで、定期 検査 自体が存在しない（ADR-061）
A52: M-Q-13-1 | B52: OpenAPI を持たないレガシー API の扱い | C52: 解消: monitoring.yaml に endpoint リストを直接列挙して代替可
A53: M-Q-18-5 | B53: 前提規模の確定（対象アカウント数等） | C53: 解決: Phase 1 の対象は約 3 アカウント。対象検索 Lambda は単一実行で Lambda 15 分制限に十分な余裕があり、分割起動 分割への移行は不要（規模拡大時に再評価）
A54: 注記: 文書情報の作成者・承認者、改訂履歴の担当、および本シートの担当・期限は未定のため空欄とする（記入用）。

Sheet 12_関連文書
A1: 関連文書
A2: 参照元資料のタイトル・所在・パスは「13_出典一覧」シートにまとめる。
A4: 1. ADR（設計判断の経緯。本文では番号参照のみとし、内容は転記しない）
A5: ADR | B5: タイトル | C5: 本書での扱い
A6: ADR-061 | B6: デプロイ検知の pull 型統一 | C6: 参照のみ（番号参照）
A7: ADR-059 | B7: Central Auth Check Canary Architecture（Pattern β） | C7: 参照のみ（番号参照）
A8: ADR-039 | B8: Centralized Network Account Edge Layer（インターネット境界 CloudFront + WAF） | C8: 本文中で境界層の根拠として言及
A11: 2. 設計要素と実装物の対応
A12: 設計要素 | B12: 実装物 | C12: 状態
A13: 認証実装チェック（検査 / 分類 / 発行） | B13: central-probe-lib | C13: 実装済み
A14: アラート検知 Lambda | B14: alert-router-lambda | C14: 実装済み
A15: 巡回発見（対象検索 Lambda） | B15: 未実装（M-Q-17-4） | C15: 未実装
A16: App Registry（台帳 CRUD） | B16: app-registry-lambda（旧 push 型の参考実装。ロジックを対象検索 Lambda に流用予定） | C16: 現行構成要素ではない
A17: OpenAPI Registry（spec 取得） | B17: openapi-export-lambda（旧 push 型の参考実装。ロジックを対象検索 Lambda に流用予定） | C17: 現行構成要素ではない
A18: 実行モード 自動差分検査（モード1） / 全量検査（モード2） | B18: 検査 Lambda（central-probe-lib を Lambda ハンドラに転用） | C18: 実装済み（対象検索 Lambda 連携は未実装）
A19: 台帳アクセス（検査 側） | B19: central-probe-lib の lib/registry.js | C19: S3 改修待ち（M-Q-12-3）
A21: 3. 処理設計セクション（本ブック内）
A22: 文書 | B22: 所在 | C22: 内容
A23: 処理設計（本ブック内） | B23: 本ブック シート 18〜52 | C23: 処理単位の I/O・シーケンス・例外・権限。SSOT は research/process-design-template.md、生成は tools/add_process_sheets_to_apipf.py + tools/process_catalog.py（再生成すると 18 以降の記入は消える）

Sheet 13_出典一覧
A1: 出典一覧（本書の出典表記 ↔ 参照元ファイルの場所とパス）
A2: 本書（Excel）は認証実装確認処理の基本設計そのものであり、本文に出典表記は持たない。内容の元となった資料のタイトル・概要・所在は本シートにまとめ、必要時にたどれるようにする。
A4: 1. 参照元の所在
A5: 項目 | B5: 値
A6: リポジトリ | B6: github.com/suepie/aws-atuh-poc
A7: 最新確認コミット | B7: d68d10f60ce1c35c084ef50b05d329a36d1cd0ca
A8: 確認日時 | B8: 2026-09-11T00:37:21+09:00
A9: 基本設計書ディレクトリ | B9: doc/api-platform/basic-design/
A10: ADR ディレクトリ | B10: doc/adr/
A11: md 改訂の取り込み状況 | B11: 2026-09-11 版で第 10 / 11 / 12 / 13 / 16 / 17 / 18 章および code-samples/README・WBS の最新版を取り込み済み（S3 認証構成情報方式・実行モード 2 つ統合・Lambda 3 本の日本語呼称・用語改定）。下表の blob SHA は取り込んだ版を指す。
A13: 2. 参照元資料（基本設計書）
A14: タイトル | B14: 目的・スコープ、全体骨格、統合構成、AWS リソース構成と通信経路 A〜D、詳細通信フロー（W1〜W9 / P1〜P6 / N1〜N6）、リソース一覧、用語表。→ 02 / 03 / 04 / 05 / 08 シート | C14: ファイル名 | D14: パス | E14: blob SHA（本書に反映済みの版）
A15: 第 10 章 外形監視 概要 | B15: 目的・スコープ、全体骨格、統合構成、AWS リソース構成と通信経路 A〜D、リソース一覧、用語表。→ 02 / 03 / 04 / 05 / 08 シート | C15: 10-external-monitoring-overview.md | D15: doc/api-platform/basic-design/10-external-monitoring-overview.md | E15: 5de0e377f89cfbd6c59d3eab17fc159d7ee9a2d3
A16: 第 11 章 認証実装確認処理 アーキテクチャ | B16: 検査シーケンス、Negative / Positive の Hybrid 検証と 4×4 分類、WAF 干渉と誤判定の防止、authPattern 別の検査方式、Positive トークン管理、環境別動作、ユースケース。→ 05 / 07 / 08 シート | C16: 11-central-probe-architecture.md | D16: doc/api-platform/basic-design/11-central-probe-architecture.md | E16: 4f2382ff266d7a6a0dcadd9bc093f4289a388135
A17: 第 12 章 App Registry 設計 | B17: S3 台帳のキー体系・項目定義・JSON 例、検査 先を CloudFront とする理由、台帳への書き込み権限。→ 07 / 08 シート | C17: 12-app-registry-design.md | D17: doc/api-platform/basic-design/12-app-registry-design.md | E17: d4cdeb813f4b35dd03b74bb2b1cdf530e07b72cc
A18: 第 13 章 OpenAPI Registry 設計 | B18: spec の正本と S3 コピー、公開明示 MON-1（default-deny）、検査 制御アノテーション一覧、新規 endpoint の自動追随。→ 07 / 09 シート | C18: 13-openapi-registry-design.md | D18: doc/api-platform/basic-design/13-openapi-registry-design.md | E18: 2f6d3fc1df077a46a98a1c3a2f059d9c916e62de
A19: 第 14 章 認証実装チェック 実装ガイド | B19: probe lib のモジュール構成、モノリス / BFF / Private API 対応、要 PoC 項目、テスト状況。→ 04 シート | C19: 14-probe-implementation-guide.md | D19: doc/api-platform/basic-design/14-probe-implementation-guide.md | E19: a34b394ffffdbf2976a477784fa0ed108074845e
A20: 第 15 章 Alert Routing 設計 | B20: 4×4 分類から P1 / P2 / P3 への振り分け、通知先 ARN の 2 段解決、通知メッセージ、エラー処理。→ 08 シート | C20: 15-alert-routing-design.md | D20: doc/api-platform/basic-design/15-alert-routing-design.md | E20: b55e3e82c59a28b429ba8d4ffcdbc2930d782ce0
A21: 第 16 章 クロスアカウント IAM 設計 | B21: アカウント分離、DiscoveryReadRole の権限・信頼ポリシー、中央側 3 ロール、StackSets 配布。→ 08 シート | C21: 16-cross-account-iam-design.md | D21: doc/api-platform/basic-design/16-cross-account-iam-design.md | E21: d7a7cf8754f32652558de3f4cff22941344152bd
A22: 第 17 章 デプロイ連携・登録 | B22: 巡回フロー、受容した穴 2 つと補完レイヤー、monitoring.yaml 規約、モノリス対応、SCP。→ 05 / 06 / 07 / 09 シート | C22: 17-deployment-integration-and-registration.md | D22: doc/api-platform/basic-design/17-deployment-integration-and-registration.md | E22: 2cec6db57782a896be8ddeec9022507a9f70ff95
A23: 第 18 章 スキャンモードとスケジューリング | B23: 自動差分検査（モード1） / 全量検査（モード2）（分割起動）/ heartbeat 型検査（旧 M2、廃止） 将来の定義、差分粒度、実行基盤、運用設計（メタ監視・エラー処理・スケール上限）、アラーム。実行モデルはこの章を正とする。→ 06 シート | C23: 18-scan-modes-and-scheduling.md | D23: doc/api-platform/basic-design/18-scan-modes-and-scheduling.md | E23: 7cfdd021c181a3d2066c3f9f485ee0f40f999c64
A24: データ契約 | B24: 台帳スキーマ、authPattern enum（6 値）、OpenAPI アノテーション、CloudWatch Metrics、4×4 真偽値表、Alert イベント形式。データ定義はこの資料を正とする。→ 04 / 07 シート | C24: code-samples/README.md | D24: doc/api-platform/basic-design/code-samples/README.md | E24: 87720e510764b446d5201e9e686a2aec24d46f62
A25: 残作業 WBS・工数見積 v7 | B25: Phase 3 実装〜リリースの残作業。AWS リソース毎に設計書行、Lambda は処理毎に設計・実装・単体テストの 3 行。合計 487 人時 / 126 行（v6 で S3 認証構成情報方式、v7 で呼称改定）。→ 14 / 15 シート | C25: wbs-phase3-4-estimate.md | D25: doc/api-platform/basic-design/research/wbs-phase3-4-estimate.md | E25: d97c61201ad988ab09a0df1270b164859273e44f
A27: 静的解析ガイドライン（04-static-analysis-guidelines.md）・セキュリティ（05-security.md）・課金按分（03-billing-cost-allocation-rules.md）は本書から参照のみで、転記対象外。所在は同ディレクトリ。
A30: 3. ADR（経緯。本書本文では番号参照のみ）
A31: ADR | B31: タイトル | C31: ファイル名 | D31: パス
A32: ADR-061 | B32: デプロイ検知の pull 型統一 | C32: 061-deploy-detection-pull-model.md | D32: doc/adr/061-deploy-detection-pull-model.md
A33: ADR-059 | B33: Central Auth Check Canary Architecture（Pattern β） | C33: 059-central-auth-check-canary-architecture.md | D33: doc/adr/059-central-auth-check-canary-architecture.md
A34: ADR-039 | B34: Centralized Network Account Edge Layer（インターネット境界） | C34: 039-centralized-network-account-edge-layer.md | D34: doc/adr/039-centralized-network-account-edge-layer.md
A37: 4. 目録（参照のみ）
A38: 内容 | B38: ファイル名 | C38: パス
A39: 基本設計書群の目録 | B39: 00-index.md | C39: doc/api-platform/basic-design/00-index.md
A40: ADR の目録 | B40: 00-index.md | C40: doc/adr/00-index.md
A43: 5. 本書の対象外（所在のみ記録）
A44: 対象外 | B44: パス | C44: 理由
A45: 要件定義 | B45: doc/api-platform/proposal/ | C45: 要件定義であり基本設計の写しの対象外
A46: 検証の歴史記録 | B46: doc/api-platform/basic-design/research/ | C46: 検証の経過記録であり現行仕様ではない
A47: 実装コード本体 | B47: doc/api-platform/basic-design/code-samples/（README.md を除く） | C47: 実装物。データ契約のみ転記対象

Sheet 14_WBS
A1: WBS番号 | B1: 区分 | C1: タスク | D1: 内容 | E1: 依存 | F1: 外部待ち | G1: 人時 | H1: 人日 | I1: 担当 | J1: 開始予定 | K1: 終了予定 | L1: 状態 | M1: 備考
A2: W1-1 | B2: 外部調整 | C2: 監視通信のセキュリティ規則例外の承認取得 | D2: 【これは何か】社内セキュリティ規則（NW-2）は「AWS から外部への通信は必ずファイアウォール（許可ドメイン制）を通す」と定めている。今回の監視 Lambda は構成を簡素にするため VPC 外に置いており、検査の外向き通信がこのファイアウォールを通らない＝規則の例外にあたる。【なぜ調整が必要か】規則の所管（セキュリティ部門）とファイアウォールを管理する他組織の了承なしに例外運用はできない。無許可のままでは監査指摘・リリース差し止めのリスク。【やること】例外が許容できる理由（通信先が自組織の 3 種に固定・任意の外部サイトを呼ぶコードが存在しない・コードは中央管理）と代償統制（宛先固定・操作記録）をまとめた説明資料で承認を取り、記録を残す（管理番号: M-Q-10-3） | E2: — | F2: ◎ | G2: 12 | H2: 1.5
A3: W1-2 | B3: 外部調整 | C3: 検査リクエストを WAF にブロックさせないための許可設定依頼 | D3: 【これは何か】WAF＝不正アクセスやボットを自動ブロックする防御壁。監視の検査リクエストは機械的なアクセスのため、ボットと誤認されてブロックされる恐れがあり、そうなると「認証の 403」と「WAF の 403」の区別がつかず誤判定（漏れの見逃し・誤警報）につながる。【なぜ調整が必要か】WAF は境界を管理する他組織の所管で、当方だけでは設定できない。【やること】検査リクエストに付ける合言葉ヘッダ（X-Auth-Probe）の名前と秘密値の受け渡し方法を決め、「このヘッダ付きはブロック対象外」とするルール追加を依頼・合意する。承認相手が W1-1 と同じため同梱で調整（管理番号: M-Q-11-5） | E3: — | F3: ◎ | G3: 8 | H3: 1
A4: W1-3 | B4: 外部調整 | C4: 巡回対象アカウント一覧の自動取得の許可設定依頼 | D4: 【これは何か】巡回は「どの AWS アカウントを見て回るか」の一覧を AWS Organizations から自動取得したい。しかしこの一覧取得 API は組織の親（管理）アカウントしか呼べない。委任ポリシー＝親アカウントが「この操作はこのアカウントにも許す」と一度設定すれば、共通基盤アカウントから直接呼べるようになる仕組み。【なぜ調整が必要か】親アカウントの管理者に設定してもらわないと、アカウント一覧を手作業のリスト管理にせざるを得ず、アカウント追加時の登録漏れ＝監視漏れのリスクが残る。【やること】委任ポリシーの文面を作成 → 親アカウントでの適用を依頼 → 共通基盤から一覧取得できることを確認（管理番号: M-Q-17-2） | E4: — | F4: ◎ | G4: 4 | H4: 0.5
A5: W1-4 | B5: 外部調整 | C5: 検査用の認証クライアント発行依頼（認証基盤チーム） | D5: 【これは何か】検査には「未認証は弾かれるか」だけでなく「正しいトークンなら通るか」を確かめる正規検査がある。その検査用トークンを発行してもらうためのシステム用アカウント（クライアント。読み取り専用の最小権限）が認証基盤（Keycloak）側に必要。【なぜ調整が必要か】認証基盤は別チームの所管で、クライアントの発行・権限設定は当方ではできない。【やること】検査専用クライアント（api-canary-probe）の発行を依頼し、発行後に実際にトークンが取得できることを受入確認する | E5: — | F5: ◎ | G5: 8 | H5: 1
A6: W1-5 | B6: 外部調整 | C6: アラートの届け先と再送ルールの決定（受信チームへのヒアリング） | D6: 【これは何か】検知したアラートは重大度別に 3 系統（P1=重大・即時 / P2=構成系 / P3=アプリ通知）のメールで届く。その宛先メーリングリストと、同じ問題が直るまで 1 時間ごとに同じアラートが再送されることを抑制するか（重複抑制）という運用ルール。【なぜ調整が必要か】受け取る側（セキュリティ・Platform・アプリ各チーム）の体制や好みで正解が変わるため、当方単独で決められない。【やること】宛先 DL の確定と、再送抑制の要否ヒアリング・決定の記録（管理番号: M-Q-15-1 / M-Q-15-3） | E6: — | G6: 4 | H6: 0.5
A7: W1-6 | B7: 外部調整 | C7: 「コンソール直変更」を検知する別の仕組みの実在確認と整備 | D7: 【これは何か】本監視は S3 に上がった認証構成情報だけを見る方式（認証構成情報オンリー原則、2026-08-21）のため、コンソールで直接 AWS の認証設定を外した変更は認証構成情報に現れず検知できない（挙動レベルでは日次の全量検査（モード2）が最大 24h で捕捉）。この死角を設定レベルで常時チェックするのが AWS Config Rules。旧方式の deploymentId 併読の廃止により、本監視側の即時検知手段が無くなったため Config Rules の重要度が上がった。【なぜ調整が必要か】その Config Rules が組織に本当に整備されているかを確認していない。無ければ死角が塞がらないまま運用に入ってしまう。【やること】該当ルール（API GW の認証必須チェック）の有無を確認し、無ければ追加実装（+8 人時）を必須タスクとして起票する（管理番号: 17 §17.2.2 ②） | E7: — | G7: 4 | H7: 0.5
A8: W1-7 | B8: 外部調整 | C8: ベンダーへの認証構成情報アップロードの告知・CI 改修依頼 | D8: 【これは何か】コードリポジトリが開発ベンダーごとに外部にあるため、監視は「デプロイパイプラインの最終段で認証構成情報（monitoring.yaml / openapi.yaml）を App アカウントの認証構成情報連携バケットへアップロードしてもらう」方式に確定した（ADR-061 追記 2026-08-21）。【なぜ調整が必要か】アップロードの組み込みは各ベンダーの CI 改修であり、当方では実施できない。またアップロード漏れ・認証構成情報の誤りは原則アプリ責任とする責任分界（M-Q-17-7）は顧客との合意事項。【やること】告知資料（バケット・キー規約 / アップロードロールの Assume 手順 / パイプライン例 / 責任分界）を作成・配布し、各ベンダーの CI 改修とアップロード実績を受入確認する。責任分界は顧客と合意し記録する | E8: S2 | F8: ◎ | G8: 8 | H8: =G8/8 | M8: 外部律速
A9: 小計 W1 | G9: =SUM(G2:G8) | H9: =SUM(H2:H8)
A10: A1-d | B10: 基盤IaC | C10: S3 バケット 設計 | D10: 認証構成情報配置バケット のパラメータシート: バケット名 / Versioning / SSE 方式 / パブリックブロック / prefix 構成（registry/・openapi/） | E10: — | G10: 1 | H10: 0.125
A11: A1-i | B11: 基盤IaC | C11: S3 バケット 実装 | D11: A1-d の IaC 化・適用・設定実査 | E11: A1-d | G11: 2 | H11: 0.25
A12: A2-d | B12: 基盤IaC | C12: S3 バケットポリシー 設計 | D12: prefix 単位のアクセス制御表（誰が registry/*・openapi/* に何を許可されるか。3 ロール準拠） | E12: A1-d | G12: 1 | H12: 0.125
A13: A2-i | B13: 基盤IaC | C13: S3 バケットポリシー 実装 | D13: ポリシー IaC 化・適用・拒否確認（無関係ロールで AccessDenied） | E13: A2-d | G13: 2 | H13: 0.25
A14: A3-d | B14: 基盤IaC | C14: S3 Lifecycle 設計 | D14: noncurrent 版の失効日数（例 90 日）と対象 prefix の決定 | E14: A1-d | G14: 0.5 | H14: 0.0625
A15: A3-i | B15: 基盤IaC | C15: S3 Lifecycle 実装 | D15: Lifecycle ルール適用・確認 | E15: A3-d | G15: 1 | H15: 0.125
A16: A4-d | B16: 基盤IaC | C16: SNS 設計 | D16: P1/P2/P3 のトピック名・サブスクリプション（W1-5 の DL）・アクセスポリシー | E16: W1-5 | G16: 0.5 | H16: 0.0625
A17: A4-i | B17: 基盤IaC | C17: SNS 実装 | D17: 3 トピック + メールサブスクリプション作成・確認メール承認 | E17: A4-d | G17: 2 | H17: 0.25
A18: A5-d | B18: 基盤IaC | C18: SQS DLQ 設計 | D18: 検査 Lambda 用 / アラート検知 Lambda 用の 2 本。保持期間・再処理手順の方針。【補足】DLQ（デッドレターキュー）＝処理に失敗したメッセージの退避先。失敗を握り潰さず、後から中身を見て再処理・原因調査するための受け皿 | E18: — | G18: 0.5 | H18: 0.0625
A19: A5-i | B19: 基盤IaC | C19: SQS DLQ 実装 | D19: 2 キュー作成・Lambda 非同期設定への紐付け | E19: A5-d | G19: 2 | H19: 0.25
A20: A6-d | B20: 基盤IaC | C20: Scheduler 設計 | D20: rate(1 hour)・リトライポリシー（回数 / 間隔）・Scheduler 側 DLQ・実行ロール | E20: — | G20: 1 | H20: 0.125
A21: A6-i | B21: 基盤IaC | C21: Scheduler 実装 | D21: EventBridge Scheduler 作成・対象検索 Lambda への紐付け・空振り起動確認 | E21: A6-d | G21: 2 | H21: 0.25
... A34: A14-i | B34: 基盤IaC | C34: Lambda ログ保持設定 | D34: 3 Lambda のロググループ保持期間の明示設定（OBS-4。組織標準値、未定なら 90 日仮置き） | E34: — | G34: 1 | H34: 0.125
A35: A15-i | B35: 基盤IaC | C35: 全量検査の日次 Scheduler 実装 | D35: EventBridge Scheduler（日次、時刻帯は M-Q-18-3）→ 認証実装チェック Lambda mode=full 起動の IaC + 起動確認。【補足】heartbeat 型検査（旧 M2）廃止の代替として、シグナルなし変化（ALB 直の手動変更・設定駆動の認証切替等）を最大 24h で機械的に捕捉する（D-M-18-4、18 §18.1.1） | E35: A5-i | G35: 2 | H35: =G35/8
A36: 小計 W2-A | G36: =SUM(G10:G35) | H36: =SUM(H10:H35)
A37: B0-d | B37: 監視(定型) | C37: 監視設計書 | D37: アラーム一覧表（8 本: 名称 / メトリクス / 閾値 / 評価期間 / 通知先 / 対応 Runbook）+ メトリクス定義（DiscoveryLastSuccess / AccountErrors の単位・Dimensions） | E37: — | G37: 2 | H37: 0.25
A38: B1-i | B38: 監視(定型) | C38: メトリクス 発行 実装 | D38: 対象検索 Lambda に DiscoveryLastSuccess（巡回成功時）/ DiscoveryAccountErrors（失敗アカウント数）の PutMetricData を実装 | E38: C11-i | G38: 2 | H38: 0.25
A39: B2-i | B39: 監視(定型) | C39: アラーム: AuthCheckCritical > 0 | D39: 保険系。1 データポイントで発報 → SNS P1 | E39: B0-d | G39: 1 | H39: 0.125
A40: B3-i | B40: 監視(定型) | C40: アラーム: MM-1 巡回鮮度 | D40: DiscoveryLastSuccess が 2 時間欠損（missing data 扱い = breaching）→ P2 | E40: B0-d | G40: 1 | H40: 0.125
A41: B4-i | B41: 監視(定型) | C41: アラーム: MM-2 対象検索 Lambda Errors | D41: Lambda Errors ≥ 1（Scheduler 起動失敗も Errors で捕捉）→ P2 | E41: B0-d | G41: 1 | H41: 0.125
A42: B5-i | B42: 監視(定型) | C42: アラーム: MM-3 AccountErrors | D42: DiscoveryAccountErrors ≥ 1 → P2 | E42: B0-d | G42: 1 | H42: 0.125
A43: B6-i | B43: 監視(定型) | C43: アラーム: MM-4 検査 Lambda | D43: Errors ≥ 1 + DLQ（検査用）滞留 ≥ 1 → P2 | E43: B0-d | G43: 1 | H43: 0.125
A44: B7-i | B44: 監視(定型) | C44: アラーム: MM-5 アラート検知 Lambda | D44: DLQ（Router 用）滞留 ≥ 1 → P2 | E44: B0-d | G44: 1 | H44: 0.125
A45: B8-i | B45: 監視(定型) | C45: アラーム: 対象検索 Lambda Duration | D45: 15 分制限の前倒し検知（初期閾値は仮置き → W3-5 で本決め）→ P2 | E45: B0-d | G45: 1 | H45: 0.125
A46: B9-t | B46: 監視(定型) | C46: 全アラームのテスト発報 | D46: 8 本すべて閾値を跨がせ、SNS → メール到達まで実確認（訓練 W4-2 とは別の技術確認） | E46: B2〜B8 | G46: 2 | H46: 0.25
A47: 小計 W2-B | G47: =SUM(G37:G46) | H47: =SUM(H37:H46)
A48: C0-d | B48: 機能実装 | C48: 対象検索 Lambda 全体設計 | D48: 処理設計書: 全体シーケンス図（W1〜W9 展開）/ 入出力定義（Scheduler イベント・台帳 JSON・自動差分検査（モード1） payload）/ 環境変数一覧 / エラー・リトライ方針の実装割付 / ログ設計（相関 ID・マスク） | E48: — | G48: 6 | H48: 0.75
A49: C1-d | B49: 機能実装 | C49: アカウント列挙 設計 | D49: 委任ポリシー経由 ListAccounts の呼出仕様・対象 OU フィルタ・ページング。【補足】アカウント列挙＝巡回の対象となる App アカウントの一覧を AWS Organizations から毎回取得する処理。手作業のリスト管理をなくし、アカウント追加に自動追随する | E49: C0-d | G49: 1 | H49: 0.125
A50: C1-i | B50: 機能実装 | C50: アカウント列挙 実装 | D50: 上記の実装 | E50: C1-d, W1-3 | G50: 2 | H50: 0.25
A51: C1-t | B51: テスト | C51: アカウント列挙 単体テスト | D51: OU フィルタ・ページング・権限エラー時の挙動 | E51: C1-i | G51: 1 | H51: 0.125
A52: C2-d | B52: 機能実装 | C52: AssumeRole/S3 認証構成情報クライアント 設計 | D52: ExternalId・一時クレデンシャルのライフサイクル・SDK リトライ（指数バックオフ）設定。【補足】AssumeRole＝他アカウントに置かれた読み取り専用ロールの権限を、期限付きで一時的に借る AWS の標準的な仕組み。これで恆久的な鍵を配らずに App アカウントの認証構成情報連携バケットを読める | E52: C0-d | G52: 1 | H52: 0.125
...

Sheet 15_WBS集計
A1: 残作業 WBS・工数見積 v7 — 前提・集計・別表・リスク
A2: 明細は「14_WBS」シート（126 行）。本シートの人時・人日は 14_WBS を参照する数式。
A4: 1. 前提条件
A5: # | B5: 前提
A6: 1 | B6: 1 人日 = 8 人時。人日は換算値
A7: 2 | B7: 規模: 対象約 3 アカウント（M-Q-18-5）、パイロットアプリ 1 本から
A8: 3 | B8: 要員: AWS + Node.js 経験者 1 名主担当。各行にレビュー時間込み
A9: 4 | B9: 外部依頼の待ち時間（リードタイム）は工数外（◎印、カレンダー日で別管理）
A10: 5 | B10: 流用資産: probe lib（27 PASS）/ alert-router（19 PASS）/ 旧 push 型 2 Lambda のロジック。区分「改修」の意味: 設計は最初から現行仕様（S3 台帳）で確定しており設計の手戻りではない。設計確定に先立って検証目的で作成した参考実装コードの一部（台帳読み取り部）が旧前提（DynamoDB）のまま残っているため、確定設計に合わせて手直しして流用するタスクを指す。新規書き起こしも可能だが検証済みロジックとテスト資産を捨てることになるため流用を採用
A11: 6 | B11: 成果物の体系: AWS リソース毎に「インフラ設計書（パラメータシート）」、Lambda は「処理設計書（シーケンス・IF・エラー方針）」を実装前に作成し、処理毎に単体テストを残す
A12: 7 | B12: ID 規約: -d = 設計 / -i = 実装 / -t = 単体テスト。設計不要の作業系は -i のみ
A14: 区分（Excel フィルタ用・11 種）: 外部調整 / 基盤IaC / 監視(定型) / 機能実装 / 改修 / 配布物 / テスト / 運用 / ガイド / ドキュメント / 管理
A15: -d 行の区分は対象と同じ区分（例: A1-d は 基盤IaC）。設計だけ抽出したい場合はタスク名の「設計」でフィルタする。
A17: 2. スコープ外
A18: SigV4 Positive / Cookie Positive・cleanup / heartbeat 型検査（旧 M2、廃止） / Private API VPC 化 / スコープ B（依頼のみ）/ SCP 強制（Phase 2 判断）/ Multilocation / ガイドライン章（01〜06）側の残未決
A20: 3. 集計（人時・人日は 14_WBS の該当範囲を参照）
A21: 分類 | B21: 人時 | C21: 人日（標準） | D21: min–max（人日）
A22: W1 外部調整・依頼（7 行） | B22: ='14_WBS'!G9 | C22: ='14_WBS'!H9 | D22: 4–10
A23: W2-A 基盤 IaC（26 行） | B23: ='14_WBS'!G36 | C23: ='14_WBS'!H36 | D23: 3–6
A24: W2-B 監視(定型)（10 行） | B24: ='14_WBS'!G47 | C24: ='14_WBS'!H47 | D24: 1.5–2.5
A25: W2-C 対象検索 Lambda（31 行） | B25: ='14_WBS'!G79 | C25: ='14_WBS'!H79
A26: W2-C 検査 Lambda（13 行） | B26: ='14_WBS'!G93 | C26: ='14_WBS'!H93
A27: W2-C 改修・周辺（20 行） | B27: ='14_WBS'!G114 | C27: ='14_WBS'!H114
A28: W3 テスト（9 行） | B28: ='14_WBS'!G124 | C28: ='14_WBS'!H124 | D28: 8–17.5
A29: W4〜W7 運用・ガイド・ドキュメント・管理（10 行） | B29: ='14_WBS'!G135 | C29: ='14_WBS'!H135 | D29: 13–26.5
A30: 合計（126 行） | B30: ='14_WBS'!G136 | C30: ='14_WBS'!H136 | D30: 45–93
A32: 注記: 人時・人日は 14_WBS の小計・総合計セルを参照する数式。md（research/wbs-phase3-4-estimate.md §9）の集計表は W2-C を 1 行にまとめ数値を丸めて合計 487 人時としているが、明細を SUM した本表は 487.5 人時になる（差 0.5 は W2-C の丸め）。明細の SUM を正とする。min–max は md §9 の値。W2-C は md 側が 15–31 人日で一括のため個別欄は空、W4〜W7 は md の W4〜W6（9–18）と W7（4–8.5）の合算。
A34: 4. 別表: 定型監視の工数（区分 = 監視(定型) の横断集計）
A35: ID | B35: 内容 | C35: 人時
A36: B0-d | B36: 監視設計書（アラーム一覧・閾値・通知先マトリクス） | C36: 2
A37: B1-i | B37: メトリクス 発行 実装 | C37: 2
A38: B2-i〜B8-i | B38: アラーム実装 7 本 | C38: 7
A39: B9-t | B39: 全アラームのテスト発報 | C39: 2
A40: W3-5 | B40: 性能実測・閾値本決め | C40: 4
A41: W4-3 | B41: 運用ダッシュボード | C41: 8
A42: 定型監視 計 | C42: 25
A44: 注記: 14_WBS で 区分=監視(定型) をフィルタしても同じ集合が得られる（人時計 25 = 3.1 人日）。
A46: 5. 漏れチェック結果
A47: v2 で追加した 10 件（L2 Config Rules 確認 / S3 Lifecycle / Scheduler リトライ / Secrets 格納 / X-Auth-Probe secret / タグ + Budgets / ログ保持 / アラームテスト発報 / メタ不足・棚卸し通知経路 / JSON Schema 配布）は全行に反映済み。
A48: v3 では成果物としての設計書群を明示化した: インフラ設計書（A 系 -d）/ 監視設計書（B0-d）/ Lambda 処理設計書（C0-d・K0-d）/ ロール・製品設計書（S0-d・P0-d）。
...

Sheet 16_ランニング費用
A1: 認証実装確認処理 ランニング費用（AWS 利用料）
A2: 対象範囲: 認証実装確認処理（外形監視）の機構のみ。アプリ本体・CloudFront / WAF（ネットワーク監査アカウント）・ベンダー側 CI / git ホスティング費用・ガイドライン章（01-06）の費用は含まない。
A4: 1. 前提パラメータ
A5: # | B5: パラメータ | C5: Phase 1 | D5: 将来（拡大時） | E5: 根拠
A6: P-1 | B6: App アカウント数 = アプリ数 | C6: 3 | D6: 30 | E6: WBS（Phase 1 ≈ 3 アカウント）
A7: P-2 | B7: 環境数 / アプリ | C7: 2（prod + stg） | D7: 2 | E7: monitoring.yaml 規約
A8: P-3 | B8: endpoint 数 / アプリ | C8: 30 | D8: 30 | E8: 想定値（要ヒアリング）
A9: P-4 | B9: 巡回頻度 | C9: 1 時間毎 = 約 730 回/月 | D9: 同左 | E9: 実行モード 自動差分検査（モード1）
A10: P-5 | B10: デプロイ（自動差分検査（モード1）起動） | C10: 1 回/営業日/アプリ ≈ 60 回/月 | D10: 600 回/月 | E10: 想定値
A11: P-6 | B11: 全量検査（モード2） | C11: 月 1 回 | D11: 月 1 回 | E11: 運用工数 OP-3（推奨頻度、未決 RC-Q-2）
A12: P-7 | B12: Lambda メモリ / 実行時間 | C12: 対象検索 512MB×60s / 認証実装チェック 512MB×120s / アラート検知 256MB×5s | D12: 対象検索は巡回対象比例で 300s | E12: 想定値（W3-5 実測で本決め）
A13: P-8 | B13: 為替目安 | C13: $1 = ¥150 | D13: 同左 | E13: 概算表示用
A15: 単価は 2026-08-19 に AWS 公式（価格ページ + Price List API、ap-northeast-1）で検証済み。Scheduler 東京 $1.25/M・Logs 取り込み東京 $0.76/GB に補正
A17: 2. 費用内訳（月額 USD、東京）
A18: ID | B18: 項目 | C18: リソース | D18: 算定（Phase 1） | E18: 月額 USD（Phase 1） | F18: 月額 USD（将来 30） | G18: 負担アカウント | H18: 備考
A19: RC-1 | B19: 対象検索 Lambda | C19: Lambda | D19: 730 回 × 60s × 0.5GB = 21,900 GB-s × $0.0000166667 | E19: $0.4 | F19: $1.8 | G19: 共通基盤 | H19: 将来は巡回 300s/回で試算
A20: RC-2 | B20: 認証実装チェック Lambda | C20: Lambda | D20: 63 回 × 120s × 0.5GB ≈ 3,800 GB-s | E20: $0.1 | F20: $0.6 | G20: 共通基盤 | H20: 自動差分検査（モード1） 60 + 全量検査（モード2） 3
A21: RC-3 | B21: アラート検知 Lambda | C21: Lambda | D21: 発報数十回 × 5s × 0.25GB | E21: $0.0 | F21: $0.0 | G21: 共通基盤 | H21: 無料枠内
A22: RC-4 | B22: スケジューラ | C22: EventBridge Scheduler | D22: 730 起動 × $1.25/M | E22: $0.0 | F22: $0.0 | G22: 共通基盤 | H22: 無料枠 1,400 万起動/月
A23: RC-5 | B23: 認証構成情報配置バケット | C23: S3 Standard | D23: <1GB + GET 約 1 万/月 + PUT 少量 | E23: $0.1 | F23: $0.5 | G23: 共通基盤 | H23: Versioning 込みでも KB オーダー
A24: RC-6 | B24: シークレット | C24: Secrets Manager | D24: 3 個 × $0.40（検査 トークン共通 + X-Auth-Probe + 予備） | E24: $1.2 | F24: $1.2〜12 | G24: 共通基盤 | H24: 将来 M-Q-11-4 スコープ B（アプリ別クライアント）採用なら 30 個 ≈ $12
A25: RC-7 | B25: カスタムメトリクス | C25: CloudWatch | D25: 約 20 個（MM-1〜5 + AccountErrors + アプリ別次元 3×3 ほか）× $0.30 | E25: $6.0 | F25: $30.0 | G25: 共通基盤 | H25: 最大費目。メトリクスはディメンション組合せごとに 1 個課金 → アプリ数比例
A26: RC-8 | B26: アラーム | C26: CloudWatch | D26: 10 本（B2〜B8 + 保険系）× $0.10 | E26: $1.0 | F26: $1.5 | G26: 共通基盤
A27: RC-9 | B27: ダッシュボード | C27: CloudWatch | D27: 1 個（W4-3） | E27: $0.0 | F27: $0.0 | G27: 共通基盤 | H27: 無料枠 3 個内
A28: RC-10 | B28: ログ | C28: CloudWatch Logs | D28: 取り込み 2GB × $0.76 + 保存 | E28: $2.0 | F28: $9.0 | G28: 共通基盤 | H28: 東京は $0.76/GB。保持期間の設定が保存費を左右（A 系で設定済み前提）
A29: RC-11 | B29: 通知メール | C29: SNS | D29: 数百通/月 | E29: $0.0 | F29: $0.0 | G29: 共通基盤 | H29: 無料枠 1,000 通/月内。$2.00/10 万通
A30: RC-12 | B30: Config Rules（②） | C30: AWS Config | D30: ルール評価 ~100 回 × $0.001 + 変更 CI ~100 × $0.003 | E30: $0.5 | F30: $3.0 | G30: App 各アカウント | H30: Config recorder は組織で有効済み前提（W1-6）。増分のみ計上
A31: RC-13 | B31: 認証構成情報連携バケット | C31: S3 Standard（App 各アカウント） | D31: 認証構成情報 3 ファイル（KB オーダー）+ Versioning 旧版 + 巡回 List/Get | E31: $0.0 | F31: $0.1 | G31: App 各アカウント | H31: 2026-08-21 更新: 旧 RC-13（CodeCommit アクティブユーザー $0〜3/月）は S3 認証構成情報化（ADR-061 追記）で消滅。認証構成情報連携バケットの費用は誤差
A32: RC-14 | B32: KMS | C32: KMS | D32: SSE-S3 なら不要。CMK 1 本なら $1 + リクエスト | E32: $0〜1 | F32: $0〜1 | G32: 共通基盤 | H32: 暗号化方式は A 系 IaC の決定に従う（RC-Q-3）
A33: 合計 | E33: ≈ $11〜13/月（≈ ¥1,700〜2,000） | F33: ≈ $48〜61/月（≈ ¥7,000〜9,200） | H33: 為替目安 $1 = ¥150
A35: 3. 読み方（要点）
A36: 機構のランニングは月 2,000 円前後で、支配項は CloudWatch（メトリクス + ログ = 費用の 2/3）。Lambda・S3・Scheduler は事実上ゼロ
A37: アプリ数比例で増えるのは RC-7（メトリクス）・RC-10（ログ）・RC-12/13（App アカウント側）。30 アプリでも月 1 万円台
A38: App アカウント側に発生する費用が 2 件ある（RC-12/13）。課金按分の説明にこの 2 件を「監視のための共通負担」として明記が必要 → RC-Q-1
A39: 検査の通信は CloudFront 経由の HTTPS 数千リクエスト/月でデータ転送費は誤差（<$0.1）。巡回のクロスアカウント読み取りは S3 の List/GetObject のみで、認証構成情報は KB オーダーのため無視できる。
A41: 4. 未決（費用）
A42: ID | B42: 内容
A43: RC-Q-1 | B43: App アカウント側費用（RC-12/13）の按分整理 — 課金ガイドへの記載方法
A44: RC-Q-2 | B44: 全量検査（モード2）の定期実行頻度（月次推奨 / 四半期 / 監査時のみ）— OP-3 と連動
A45: RC-Q-3 | B45: 認証構成情報配置バケット の暗号化方式（SSE-S3 / SSE-KMS）— RC-14 の要否
...

Sheet 17_運用工数
A1: 認証実装確認処理 運用開始後の作業（運用工数）
A2: 体制想定 = 共通基盤チーム内の兼務 1 名。頻度は Phase 1（3 アプリ）想定で、導入期 3 か月の実績で v2 改訂（OP-Q-1）
A3: 時間は 1 件あたりの実働。「件数 × 時間」の変動項はアプリ数比例で、30 アプリ時は下部の集計表を参照。根拠: Runbook 5 本（W4-1 ①〜⑤）、メタ監視 MM-1〜5、4×4 分類。
A5: 1. 作業一覧（分類別）
A6: ID | B6: 分類 | C6: 作業 | D6: 内容 | E6: 周期 or 件数/月 | F6: 1 回 h | G6: 月換算 h | H6: 備考
A7: OP-1 | B7: 定期 | C7: 日次ヘルスチェック | D7: ダッシュボード確認（巡回成功・未処理アラート・AccountErrors） | E7: 営業日 | F7: 0.2 | G7: 4
A8: OP-2 | B8: 定期 | C8: 月次棚卸し | D8: 消滅レコード削除・公開印 skip 濫用レビュー・enabled 一覧確認（Runbook ⑤） | E8: 月 | F8: 2 | G8: 2
A9: OP-3 | B9: 定期 | C9: 全量検査（モード2）実行 | D9: 全アプリ全量検査 + 結果確認（Runbook ②） | E9: 月（RC-Q-2） | F9: 1 | G9: 1
A10: OP-4 | B10: 定期 | C10: アラームテスト発報 | D10: B-2 相当の擬似ケースで通知経路を通す訓練 | E10: 四半期 | F10: 2 | G10: 0.7
A11: OP-5 | B11: 定期 | C11: シークレットローテ確認 | D11: 検査 トークンクライアント・X-Auth-Probe secret（T2 自動なら結果確認のみ） | E11: 四半期 | F11: 2 | G11: 0.7
A12: OP-6 | B12: 定期 | C12: 権限棚卸し | D12: DiscoveryReadRole 信頼先・ExternalId・AssumeRole CloudTrail 監査 | E12: 半期 | F12: 3 | G12: 0.5
A13: OP-7 | B13: 定期 | C13: ランタイム・SDK 更新 | D13: Lambda ランタイム EOL 追随・依存更新 + 回帰（W3 の UT 資産流用） | E13: 年 | F13: 16 | G13: 1.3
A14: OP-8 | B14: 定期 | C14: ガイド・Schema 年次見直し | D14: 利用ガイド / JSON Schema / FAQ の改訂 | E14: 年 | F14: 8 | G14: 0.7
B15: 定期 小計 | G15: 10.9
A16: OP-9 | B16: 発生ベース | C16: P1 対応 | D16: 認証漏れ疑いの一次切り分け（真の漏れ / 設定ずれ / 誤検知）→ アプリ連絡 → 暫定遮断判断（Runbook ①） | E16: 0.5 | F16: 4 | G16: 2
A17: OP-10 | B17: 発生ベース | C17: P2 対応 | D17: メタ不足・消滅検知・Config 設定ずれの確認とアプリ督促 | E17: 3 | F17: 1 | G17: 3
A18: OP-11 | B18: 発生ベース | C18: P3・問い合わせ対応 | D18: アプリ通知系のフォロー・FAQ 対応 | E18: 4 | F18: 0.5 | G18: 2
A19: OP-12 | B19: 発生ベース | C19: 誤検知調査 | D19: WAF 干渉（X-Auth-Probe 不通など）・WARN 分類の原因調査 | E19: 1 | F19: 2 | G19: 2
A20: OP-13 | B20: 発生ベース | C20: メタ監視（MM）発報対応 | D20: DiscoveryLastSuccess 欠損等の初動（Runbook ③） | E20: 1 | F20: 1 | G20: 1
A21: OP-14 | B21: 発生ベース | C21: 新規アプリ導入支援 | D21: monitoring.yaml レビュー・アップロードロール払い出し（CI 信頼先設定）・初回アップロード〜検知の受入確認 | E21: 1 | F21: 3 | G21: 3
A22: OP-15 | B22: 発生ベース | C22: 外部調整の維持 | D22: WAF ルール変更追随・Keycloak クライアント更新・NW-2 例外の年次更新 | E22: 0.5 | F22: 1 | G22: 0.5
B23: 発生ベース 小計 | G23: 13.5
A24: OP-16 | B24: 改善・維持 | C24: 設計書・Excel・Runbook の同期 | D24: 実装差分・未決消し込みの反映 | G24: 1
A25: OP-17 | B25: 改善・維持 | C25: 閾値チューニング | D25: アラーム・WARN 分類の見直し（実績ベース） | G25: 0.5
B26: 改善・維持 小計 | G26: 1.5
A28: 2. 集計
A29: 期間 | B29: 月間工数 | C29: 人日/月 | D29: FTE 換算
A30: 導入期（リリース後 3 か月） | B30: 約 39h（定常 26h × 1.5。チューニング・導入支援・誤検知が集中） | C30: 4.9 | D30: 0.24
A31: 定常期（Phase 1、3 アプリ） | B31: 約 26h | C31: 3.3 | D31: 0.16
