Workbook

Sheet コスト見積もり
A1: AWS＋ROSA コスト見積もり（東京リージョン ap-northeast-1）
A2: 構成の根拠: doc/basic-design/06-infra-network-design.md（D-U6-01〜14）ほか設計書。ROSAサービス料は AWS 公式料金ページから取得（2026-08時点）。AWSインフラの単価は公式ページが動的読み込みのため取得できず、青字の入力欄としている
A3: ★青字セル＝入力欄（未取得）。AWS Pricing Calculator または各サービスの公式料金ページから値を入れると、以降の集計は自動計算される。数量は設計値（上限台数・構成）に基づくが、規模別の按分は推定
A5: ■ 前提（入力）
A6: 項目 | B6: 値 | C6: 単位 | D6: 備考
A7: 対象リージョン | B7: 東京 ap-northeast-1 | C7: — | D7: 前提P-15。予備地域は平時ゼロのため本表に含めない
A8: 月間稼働時間 | B8: 730 | C8: 時間 | D8: 24時間×365日÷12
A9: 為替レート | B9: 150 | C9: 円/USD | D9: 円換算用の入力値。実勢に合わせて変更
A10: 想定利用者数 シナリオ1 | B10: 1000000 | C10: 人 | D10: 小規模。最小構成想定
A11: 想定利用者数 シナリオ2 | B11: 5000000 | C11: 人 | D11: 更新メモ「100〜500万ユーザー」の上限
A12: 想定利用者数 シナリオ3 | B12: 10000000 | C12: 人 | D12: 前提P-02の凍結値（設計上の上限）
A14: ■ ROSA サービス料（AWS公式料金ページから取得）
A15: 区分 | B15: 項目 | C15: 単価 | D15: 単位 | E15: 出典 | F15: 状態
A16: ROSA | B16: 制御部分の料金（hosted control planes） | C16: 0.25 | D16: クラスタ・時 | E16: https://aws.amazon.com/rosa/pricing/ | F16: 取得済
A17: ROSA | B17: ワーカーノードのサービス料（従量） | C17: 0.171 | D17: 4vCPU・時 | E17: https://aws.amazon.com/rosa/pricing/ | F17: 取得済
A18: ROSA | B18: 同・年額換算（従量） | C18: 1500 | D18: 4vCPU・年 | E18: https://aws.amazon.com/rosa/pricing/ | F18: 取得済
A19: ROSA | B19: 同・1年契約 | C19: 1000 | D19: 4vCPU・年 | E19: https://aws.amazon.com/rosa/pricing/ | F19: 取得済
A20: ROSA | B20: 同・3年契約 | C20: 667 | D20: 4vCPU・年 | E20: https://aws.amazon.com/rosa/pricing/ | F20: 取得済
A21: ※ ROSAのサービス料は全対応リージョンで同一。契約による割引は従量比で1年33%・3年55%。製品サポートは基盤に内包され追加費用は発生しない（前提P-01）
A23: ■ AWSインフラ費 明細（数量＝月間の課金単位数。単価は青字の入力欄）
A24: 区分 | B24: リソース／サービス | C24: 用途（設計上の根拠） | D24: 数量の考え方 | E24: 数量 100万人 | F24: 数量 500万人 | G24: 数量 1000万人 | H24: 単位 | I24: 単価(USD) | J24: 月額 100万人 | K24: 月額 500万人 | L24: 月額 1000万人 | M24: 単価の出典URL | N24: 備考
A25: 計算 | B25: ROSA 計算ノード（認証製品専用・仲介側） | C25: 認証処理の実行。D-U6-04で2系統に分離、上限9台 | D25: 台数×730時間。100万=3台／500万=6台／1000万=9台（上限） | E25: 2190 | F25: 4380 | G25: 6570 | H25: インスタンス時間 | I25: 0.1819 | J25: =E25*$I25 -> 398.361 | K25: =F25*$I25 -> 796.722 | L25: =G25*$I25 -> 1195.083 | M25: https://aws.amazon.com/jp/ec2/pricing/on-demand/ | N25: c7g.xlarge（D-U6-04）
A26: 計算 | B26: ROSA 計算ノード（認証製品専用・自社受け皿側） | C26: パスワード検証が支配的。D-U6-04で上限18台 | D26: 台数×730時間。100万=3台／500万=9台／1000万=18台（上限） | E26: 2190 | F26: 6570 | G26: 13140 | H26: インスタンス時間 | I26: 0.1819 | J26: =E26*$I26 -> 398.361 | K26: =F26*$I26 -> 1195.083 | L26: =G26*$I26 -> 2390.166 | M26: https://aws.amazon.com/jp/ec2/pricing/on-demand/ | N26: c7g.xlarge（D-U6-04）
A27: 計算 | B27: ROSA 計算ノード（管理系）×2クラスタ | C27: 入口・監視・イメージ配布・受け口。規模と監視量で準静的 | D27: 3台×2クラスタ×730時間で固定 | E27: 4380 | F27: 4380 | G27: 4380 | H27: インスタンス時間 | I27: 0.091 | J27: =E27*$I27 -> 398.58 | K27: =F27*$I27 -> 398.58 | L27: =G27*$I27 -> 398.58 | M27: https://aws.amazon.com/jp/ec2/pricing/on-demand/ | N27: c7g.large（default/infra Pool）
A28: 計算 | B28: ROSA サービス料（制御部分） | C28: D-U6-03で2クラスタ構成 | D28: 0.25ドル×2クラスタ×730時間 | E28: 1460 | F28: 1460 | G28: 1460 | H28: クラスタ時間 | I28: 0.25 | J28: =E28*$I28 -> 365 | K28: =F28*$I28 -> 365 | L28: =G28*$I28 -> 365 | M28: https://aws.amazon.com/jp/rosa/pricing/ | N28: 取得済（変更なし）
A29: 計算 | B29: ROSA サービス料（ワーカーノード） | C29: 4vCPUあたりの従量。ノードのvCPU総数に比例 | D29: ノード合計vCPU÷4×730時間。1台4vCPU想定 | E29: 1642 | F29: 3103 | G29: 5658 | H29: 4vCPU時間 | I29: 0.171 | J29: =E29*$I29 -> 280.782 | K29: =F29*$I29 -> 530.613 | L29: =G29*$I29 -> 967.518 | M29: https://aws.amazon.com/jp/rosa/pricing/ | N29: 取得済（変更なし）
A30: 計算 | B30: EBS（ノード用ブロックストレージ） | C30: 各ノードのOS・作業領域 | D30: 認証製品用ノード120GB＋管理系ノード100GB（D-U6-16）。100万=KC6台+管理6台／500万=KC15台+管理6台／1000万=KC27台+管理6台 | E30: 1320 | F30: 2400 | G30: 3840 | H30: GB・月 | I30: 0.096 | J30: =E30*$I30 -> 126.72 | K30: =F30*$I30 -> 230.4 | L30: =G30*$I30 -> 368.64 | M30: https://aws.amazon.com/jp/ebs/pricing/ | N30: D-U6-16でgp3・KC Pool 120GB（ログバッファ30GB明示）・infra Pool 100GBに確定。旧値は一律100GB前提
A31: DB | B31: Aurora インスタンス（認証用・書込1＋読取2） | C31: D-U6-07。db.r7g.xlarge想定の3拠点構成 | D31: 3台×730時間 | E31: 2190 | F31: 2190 | G31: 2190 | H31: インスタンス時間 | I31: 0.665 | J31: =E31*$I31 -> 1456.35 | K31: =F31*$I31 -> 1456.35 | L31: =G31*$I31 -> 1456.35 | M31: https://aws.amazon.com/jp/rds/aurora/pricing/ | N31: db.r7g.xlarge 標準ストレージ構成
A32: DB | B32: Aurora インスタンス（権限系・書込1＋読取2） | C32: D-U6-07。認証用と別系統・別鍵で分離 | D32: 3台×730時間 | E32: 2190 | F32: 2190 | G32: 2190 | H32: インスタンス時間 | I32: 0.665 | J32: =E32*$I32 -> 1456.35 | K32: =F32*$I32 -> 1456.35 | L32: =G32*$I32 -> 1456.35 | M32: https://aws.amazon.com/jp/rds/aurora/pricing/ | N32: db.r7g.xlarge 標準ストレージ構成
A33: DB | B33: Aurora ストレージ | C33: 利用者・セッション・権限・ID対応表・射影 | D33: 利用者数に比例。1人あたり約2KB＋索引 | E33: 200 | F33: 1000 | G33: 2000 | H33: GB・月 | I33: 0.12 | J33: =E33*$I33 -> 24 | K33: =F33*$I33 -> 120 | L33: =G33*$I33 -> 240 | M33: https://aws.amazon.com/jp/rds/aurora/pricing/ | N33: 1人あたり約2KB＋索引
A34: DB | B34: Aurora I/O | C34: 認証時の読み書き。100req/sあたり書込1,400 IOPSが公式算定式 | D34: ログイン回数に比例（月間認証回数×IO係数） | E34: 50000000 | F34: 250000000 | G34: 500000000 | H34: I/O 件 | I34: 2.4e-07 | J34: =E34*$I34 -> 12 | K34: =F34*$I34 -> 60 | L34: =G34*$I34 -> 120 | M34: https://aws.amazon.com/jp/rds/aurora/pricing/ | N34: ※単位を「100万リクエスト」から「I/O 件」へ是正。件数×単価で計算する
A35: DB | B35: Aurora バックアップストレージ | C35: 時点復元1〜35日＋定期取得の控え | D35: データ量と同程度＋世代分 | E35: 400 | F35: 2000 | G35: 4000 | H35: GB・月 | I35: 0.023 | J35: =E35*$I35 -> 9.2 | K35: =F35*$I35 -> 46 | L35: =G35*$I35 -> 92 | M35: https://aws.amazon.com/jp/rds/aurora/pricing/
A36: DB | B36: Aurora グローバル複製（予備地域へのデータ保全） | C36: D-U8-14のL1。計算資源は平時ゼロだがデータ層は維持 | D36: 複製データ量。転送＋предスト保管 | E36: 200 | F36: 1000 | G36: 2000 | H36: GB・月 | I36: 0.12 | J36: =E36*$I36 -> 24 | K36: =F36*$I36 -> 120 | L36: =G36*$I36 -> 240 | M36: https://aws.amazon.com/jp/rds/aurora/pricing/ | N36: ※DR案②③でのみ発生。案①では0
A37: NW | B37: 内部接続点（内部NLB）×2 | C37: D-U6-05。管理APIへの到達。インターネット非露出 | D37: 2台×730時間＋処理容量単位 | E37: 1460 | F37: 1460 | G37: 1460 | H37: NLB時間 | I37: 0.0243 | J37: =E37*$I37 -> 35.478 | K37: =F37*$I37 -> 35.478 | L37: =G37*$I37 -> 35.478 | M37: https://aws.amazon.com/jp/elasticloadbalancing/pricing/ | N37: 別途 LCU 0.006/時
A38: NW | B38: 負荷分散装置（ALB） | C38: D-U6-11の生命線。管理画面の固定拒否ルールを評価 | D38: 1台×730時間＋処理容量単位 | E38: 730 | F38: 730 | G38: 730 | H38: ALB時間 | I38: 0.0243 | J38: =E38*$I38 -> 17.739 | K38: =F38*$I38 -> 17.739 | L38: =G38*$I38 -> 17.739 | M38: https://aws.amazon.com/jp/elasticloadbalancing/pricing/ | N38: 別途 LCU
A39: NW | B39: 配信網（CloudFront） | C39: D-U6-04の入口3系統。画面配信とAPI入口 | D39: データ転送量とリクエスト数 | E39: 500 | F39: 2500 | G39: 5000 | H39: GB | I39: 0.114 | J39: =E39*$I39 -> 57 | K39: =F39*$I39 -> 285 | L39: =G39*$I39 -> 570 | M39: https://aws.amazon.com/jp/cloudfront/pricing/ | N39: 日本向け転送。別途リクエスト 0.0000012/件
A40: NW | B40: 不正アクセス遮断（WAF） | C40: D-U7-17。ただし入口側は他組織管理 | D40: ルール数＋リクエスト数。自管理分のみ | E40: 10 | F40: 50 | G40: 100 | H40: 100万リクエスト | I40: 0.6 | J40: =E40*$I40 -> 6 | K40: =F40*$I40 -> 30 | L40: =G40*$I40 -> 60 | M40: https://aws.amazon.com/jp/waf/pricing/ | N40: 0.0000006/件×100万。別途 Rule 1.0/月
A41: NW | B41: 私設接続（PrivateLink） | C41: D-U6-06。2つの受け皿の間を単方向で接続 | D41: エンドポイント×730時間＋転送量 | E41: 1460 | F41: 1460 | G41: 1460 | H41: エンドポイント時間 | I41: 0.014 | J41: =E41*$I41 -> 20.44 | K41: =F41*$I41 -> 20.44 | L41: =G41*$I41 -> 20.44 | M41: https://aws.amazon.com/jp/privatelink/pricing/
A42: NW | B42: 接続点群（VPCエンドポイント） | C42: D-U6-07の外部通信を持たない構成。各サービスへの私設経路 | D42: 20種×3拠点×730時間 | E42: 7300 | F42: 7300 | G42: 7300 | H42: エンドポイント時間 | I42: 0.014 | J42: =E42*$I42 -> 102.2 | K42: =F42*$I42 -> 102.2 | L42: =G42*$I42 -> 102.2 | M42: https://aws.amazon.com/jp/privatelink/pricing/
A43: NW | B43: 名前解決（Route 53 私設ゾーン） | C43: DU-U6-13。内外で解決結果を分ける構成 | D43: ゾーン数＋問い合わせ数 | E43: 10000000 | F43: 50000000 | G43: 100000000 | H43: クエリ | I43: 4e-07 | J43: =E43*$I43 -> 4 | K43: =F43*$I43 -> 20 | L43: =G43*$I43 -> 40 | M43: https://aws.amazon.com/jp/route53/pricing/ | N43: ※単位を「100万クエリ」から「クエリ」へ是正。別途ゾーン 0.50/月
...

Sheet 設計決定一覧
A1: 設計決定一覧（基本設計 02〜10 の正式決定）
A2: 出典: github.com/suepie/aws-atuh-poc doc/basic-design/ commit 9511a58 ／ Gitからの派生ビュー（読み取り専用）。2026-08-12 網羅性再監査で16件追加
A4: 決定名（何を決めたか） | B4: 設計単元 | C4: 決定内容 | D4: 内部ID（Git内の採番） | E4: 出典
A5: Realm構成 | B5: U2 Keycloak論理 | C5: Broker KC=単一Realm『broker』+Organizations、IdP-KC=単一Realm『idp』+Organizations。masterはKeycloak自体の管理専用で業務ユーザ・Clientを置かない。Realm名はissuer URLに埋まり変更不可のため普遍的短名 | D5: U2 §2.1.1 | E5: basic-design/02-keycloak-logical-design.md
A6: Organizationsの使い方 | B6: U2 Keycloak論理 | C6: Brokerは全顧客（IdPあり・なし問わず）を1顧客=1Orgで登録。顧客IdPは必ず当該顧客Orgに紐付け（グローバルIdP禁止）。IdP-KCはIdPなし顧客のみ登録。Org attributeは表示名とhrd_modeのみ、課金・契約メタは持たない | D6: U2 §2.1.2 | E6: basic-design/02-keycloak-logical-design.md
A7: Org命名規則・alias規則 | B7: U2 Keycloak論理 | C7: Org alias=小文字英数字2〜20文字・先頭英字・ハイフン禁止・作成後変更不可。tenant_idクレーム値とログインIDのtenantプレフィックスと完全一致。master/admin/broker/idp/api/scim/test等は予約語で使用禁止 | D7: U2 §2.1.3 | E7: basic-design/02-keycloak-logical-design.md
A8: IdP alias規則 | B8: U2 Keycloak論理 | C8: 顧客IdP alias=<orgAlias>-<proto><NN>（例 acme-oidc01）。IdP製品名はdisplayNameのみに記載しaliasには含めない（製品乗換時にalias変更＝顧客側再設定を避ける） | D8: U2 §2.1.4 | E8: basic-design/02-keycloak-logical-design.md
A9: 2-tier間フェデの位置付け | B9: U2 Keycloak論理 | C9: Brokerから見たIdP-KCは「OIDC IdPの1つ」として登録。IdP-KC側ではBrokerをOIDC confidential clientとして登録 | D9: U2 §2.2.1 | E9: basic-design/02-keycloak-logical-design.md
A10: Broker側IdP登録（IdP-KC向け） | B10: U2 Keycloak論理 | C10: IdPなし顧客共通の単一OIDC IdPエントリ『idpkc-oidc01』を作り、IdPなし顧客の全Orgに紐付け。loginHint=true / hideOnLoginPage=true / trustEmail=false / syncMode=IMPORT / storeToken=false | D10: U2 §2.2.2 | E10: basic-design/02-keycloak-logical-design.md
A11: IdP-KC側Client登録（Broker向け） | B11: U2 Keycloak論理 | C11: client_id=broker-rp。Confidential・Standard Flowのみ（Implicit/Direct Access/Service Account無効）。redirect URIは完全一致1本のみ（ワイルドカード禁止）。Phase 1=client_secret_post、Phase 2でprivate_key_jwtへ昇格。Web Origins/CORSなし | D11: U2 §2.2.3 | E11: basic-design/02-keycloak-logical-design.md
A12: 2-tier間のクレーム受け渡し | B12: U2 Keycloak論理 | C12: IdP-KC側に専用Client Scope『broker-federation』を作りMapperを集約（tenant_id / preferred_username / amr / email の4種）。JIT突合キーはtenant_id+persistent sub、emailは補助。Phase 1ではIdP-KCのrolesをBrokerへ伝播しない | D12: U2 §2.2.4 | E12: basic-design/02-keycloak-logical-design.md
A13: ログアウト連鎖 | B13: U2 Keycloak論理 | C13: idpkc-oidc01にbackchannelSupported=trueを設定し、Brokerのログアウト時にIdP-KCセッションも常時破棄（自社基盤のため越境問題なし）。storeToken=false下でのid_token_hint取り回しは実機確認が必要 | D13: U2 §2.2.5 #1 | E13: basic-design/02-keycloak-logical-design.md
A14: IdP-KC側Realmセッション TTL | B14: U2 Keycloak論理 | C14: Realm『idp』のSSO Session Idle/MaxをBroker Realmと同値（Idle 1h / Max 24h）に固定。IaCで両Realm共通変数化し独立変更を構造的に防ぐ | D14: U2 §2.2.5 #2 | E14: basic-design/02-keycloak-logical-design.md
A15: ステップアップ（AAL3）の転送 | B15: U2 Keycloak論理 | C15: 認証元がidpkc-oidc01の場合、IdP-KCへacr_values="3"+prompt=loginを付けて再リダイレクト。IdP-KC側にもACR-to-LoAマッピング（1/2/3）を定義し、amrで返してmfa_indicator Mapper（FORCE）がBroker側acr判定に反映 | D15: U2 §2.2.5 #3 | E15: basic-design/02-keycloak-logical-design.md
... A189: 忘れられる権利と7年間の改ざん不能監査の境界を明文化 | B189: U10 連携・移行 | C189: 利用者からの消去要求と、改ざん不能で7年保管する監査証跡は正面から衝突するため、「消去する対象」と「不変の監査側で墓標化・仮名化して残す対象」の境界を文書で定める（都度判断は不可）。既定は、個人データ本体は停止処理のうえ次段階の物理削除へ／監査ログ内の主体識別子は仮名化して保持（法令上の保持根拠がある）。認可判定ログ内の識別子の仮名化も同じ扱いで整合させる。境界の最終確定は顧客確認 B-RTBF-1 | D189: D-U10-13b | E189: basic-design/10-integration-migration-design.md §10.5

Sheet ADR一覧
A1: ADR（アーキテクチャ決定記録）一覧 — 全67本
A2: 出典: doc/adr/00-index.md ＋ 各ADRファイル（commit 9511a58 時点）。Gitからの派生ビュー（読み取り専用）
A3: ★ADR-061は2026-08-18にGit側の索引（00-index.md）へ登録済み（APIプラットフォーム側のスコープ）。本表では実ファイルから収録している
A5: ADR番号 | B5: 表題 | C5: ステータス | D5: 日付 | E5: 備考・更新履歴 | G5: ステータス別
A6: ADR-001 | B6: PoC第1パターンとしてCognitoハイブリッド構成を採用 | C6: Accepted | D6: 2026-03-17 | G6: ステータス | H6: 件数
A7: ADR-002 | B7: 認可方式としてLambda Authorizerを採用 | C7: Accepted | D7: 2026-03-17 | G7: Proposed | H7: =COUNTIF($C$6:$C$72,$G7) -> 48
A8: ADR-003 | B8: 認証ライブラリとしてoidc-client-tsを採用 | C8: Accepted | D8: 2026-03-17 | G8: Accepted | H8: =COUNTIF($C$6:$C$72,$G8) -> 12
A9: ADR-004 | B9: 1アカウント2 User Poolでマルチアカウント構成を擬似再現 | C9: Accepted | D9: 2026-03-17 | G9: Accepted (Phase 1) | H9: =COUNTIF($C$6:$C$72,$G9) -> 1
A10: ADR-005 | B10: 共通認証基盤にUser Poolを使用（Identity Poolではない） | C10: Accepted | D10: 2026-03-17 | G10: Accepted（条件付き） | H10: =COUNTIF($C$6:$C$72,$G10) -> 1
A11: ADR-006 | B11: Cognito vs Keycloak コスト損益分岐点の分析 | C11: Proposed | D11: 2026-03-17 | G11: Scope Reduced | H11: =COUNTIF($C$6:$C$72,$G11) -> 2
A12: ADR-007 | B12: 大阪リージョンでAuth0 OIDC IdP接続不可の記録 | C12: Accepted | D12: 2026-03-18 | G12: Out of Scope | H12: =COUNTIF($C$6:$C$72,$G12) -> 1
A13: ADR-008 | B13: PoCでKeycloak start-devモードを使用 | C13: Accepted | D13: 2026-03-25 | G13: 合計 | H13: =SUM(H7:H12) -> 65 | I13: =IF(H13=COUNTA($A$6:$A$72),"✓ 明細行数と一致","⚠ 不一致") -> ⚠ 不一致
A14: ADR-009 | B14: MFA責任はパスワード管理側に帰属させる | C14: Accepted | D14: 2026-03-28
A15: ADR-010 | B15: Keycloak環境をPrivate Subnet + VPC Endpoint構成へ移行 | C15: Accepted | D15: 2026-04-21
A16: ADR-011 | B16: 認証基盤前段ネットワーク設計の統合判断 | C16: Proposed | D16: 2026-04-21 | E16: HTTPS／カスタムドメイン／WAF／CloudFront
A17: ADR-012 | B17: VPC Lambda Authorizer + Internal ALBによる鍵情報のプライベート化 | C17: Accepted | D17: 2026-04-23
A18: ADR-013 | B18: CloudFront + WAFによるIP制限の置き換え戦略 | C18: Proposed | D18: 2026-04-24
A19: ADR-014 | B19: 共有認証基盤が対応する認証パターンの範囲 | C19: Proposed | D19: 2026-04-24
A20: ADR-015 | B20: PoCではRHBK検証を実施せず本番設計フェーズへ先送り | C20: Proposed | D20: 2026-04-24
A21: ADR-016 | B21: Cognito機能ティアの機能マトリクスと選定基準 | C21: Proposed | D21: 2026-05-13 | E21: Lite / Essentials / Plus
A22: ADR-017 | B22: マルチテナントL2（単一領域＋複数IdP）の採用根拠 | C22: Proposed | D22: 2026-06-11 / 2026-07-23 | E22: 2026-07-23更新: 1000+ IdP条件付き成立・必須対策7点・PoC P-1〜P-7を追記
A23: ADR-018 | B23: 利用者識別子3階層戦略（メール非保有＋顧客独自ID対応） | C23: Proposed | D23: 2026-06-12
A24: ADR-019 | B24: 既存システムからの移行戦略（並走＋キャッシュ移行） | C24: Proposed | D24: 2026-06-12
A25: ADR-020 | B25: 所属判定のヒントキー戦略＋フェデ/ローカル混在の識別子先行 | C25: Proposed | D25: 2026-06-12
A26: ADR-021 | B26: ログイン後の着地UX（サービス選択画面＋権限不足画面） | C26: Proposed | D26: 2026-06-12
A27: ADR-022 | B27: エッジでの権限不足画面の制御パターン | C27: Proposed | D27: 2026-06-12
A28: ADR-023 | B28: 業務システム（ServiceNow）連携設計 | C28: Proposed | D28: 2026-06-15 | E28: SSO＋プロビジョニング方向の選択
A29: ADR-024 | B29: ログイン画面アーキテクチャとブランディング4パターン | C29: Proposed | D29: 2026-06-15
A30: ADR-025 | B30: 利用者自動同期の位置づけと受信スタンス | C30: Proposed | D30: 2026-06-15 | E30: 2026-07-08 §H追記: 顧客IdPがLDAPの場合の扱い、論点6件、ヒアリングB-LDAP-1〜7を起票
A31: ADR-026 | B31: 強度の不整合の具体例とステップアップ設計 | C31: Proposed | D31: 2026-06-15
A32: ADR-027 | B32: 同一顧客内の利用者重複の扱い（7シナリオ＋連携戦略） | C32: Proposed | D32: 2026-06-15
A33: ADR-028 | B33: IdPなし顧客のローカル利用者管理 — 4選択肢の比較 | C33: Superseded | D33: 2026-06-15 | E33: 2026-08-18: 前提P-07の転換により置き換え（Superseded）。削除せず記録として保持
A34: ADR-029 | B34: ローカル利用者の定義 — 利用者カテゴリと範囲シナリオ | C34: Superseded | D34: 2026-06-15 | E34: 2026-08-18: ADR-033の2層分離（2-tier）で置き換え（Superseded）。削除せず記録として保持
A35: ADR-030 | B35: 最小の通行証項目設計と接続元アプリの表現 | C35: Proposed | D35: 2026-06-15
A36: ADR-031 | B36: 追加確認の実施情報の統合方針 | C36: Proposed | D36: 2026-06-15
A37: ADR-032 | B37: 1000万規模におけるプラットフォーム選定とコスト比較 | C37: Proposed | D37: 2026-06-12
A38: ADR-033 | B38: 2層アーキテクチャ（仲介＋自社受け皿） | C38: Proposed | D38: 2026-06-15 / 2026-07-23 | E38: 2026-07-23更新: 別アカウント配置＋2クラスタ凍結＋シャーディング拡張パス
A39: ADR-034 | B39: 状況に応じた認証（リスクベース）の設計 | C39: Proposed | D39: 2026-06-18
A40: ADR-035 | B40: 不正検知と対応（ITDR）の設計 | C40: Proposed | D40: 2026-06-18
A41: ADR-036 | B41: 顧客監査対応 | C41: Scope Reduced | D41: 2026-06-18 | E41: 2026-06-24縮小: 監査ログ保管＋都度メール対応のみ。情報開示ポータルはスコープ外
...

Sheet 機能グループ一覧
A1: 機能グループ | B1: 系統 | C1: 概要 | D1: 行数 | E1: 人日
A2: ログインの振り分け | B2: 認証 | C2: 入力された ID から、その人をどの顧客IdPへ送るかを決める入口。顧客IdPの一覧を見せずに済ませる | D2: 4 | E2: 4
A3: 顧客IdP 連携ログイン | B3: 認証 | C3: 顧客が持つ認証システムに認証を委ね、その結果を受けてログインさせる。Keycloak-Broker の中核で、ユーザの大半がこの経路を通る | D3: 17 | E3: 28
A4: パスワードによるログイン | B4: 認証 | C4: 顧客側に認証システムが無い顧客のユーザと、基盤の運用者が、Keycloak-Broker に直接 ID とパスワードでログインする | D4: 4 | E4: 5.5
A5: 多要素認証 | B5: 認証 | C5: パスワードに加えて 2 つ目の要素（数字コード・生体・セキュリティキー）を求める。登録と利用の両方を含む | D5: 2 | E5: 1
A6: パスワードと復旧 | B6: 認証 | C6: 端末の紛失やパスワード忘れから、ユーザ自身または管理者が復旧する | D6: 0 | E6: 0
A7: ログイン口の保護 | B7: 認証 | C7: 総当たり・ユーザ名の推測・流出パスワードなど、ログイン口への攻撃を防ぐ | D7: 1 | E7: 1
A8: セッションとログアウト | B8: 認証 | C8: ログイン状態をどこまで保つか、いつ切るか。アプリ側へのログアウト連携を含む | D8: 5 | E8: 9
A9: ログイン画面 | B9: 認証 | C9: ユーザが実際に目にする画面。ログイン画面の見せ方と、失敗したときの案内 | D9: 3 | E9: 2.5
A10: ユーザ管理 | B10: ユーザ管理 | C10: 顧客の人事システムや IdP から SCIM でユーザの登録・更新・削除を受け取る。ログインを待たずに反映できる | D10: 6 | E10: 6.75
A11: ユーザ属性の統一 | B11: ユーザ管理 | C11: 顧客ごとにバラバラな項目名や登録経路を、基盤内の統一した形に揃える | D11: 3 | E11: 3.75
A12: ユーザの停止・再開・消去 | B12: ユーザ管理 | C12: 退職などでユーザを止めた事実を確実に反映し、復職時に安全に再開する。消さずに無効化し、期限後に消す | D12: 4 | E12: 4
A13: 顧客・組織管理 | B13: ユーザ管理 | C13: 顧客と組織の作成・設定・解約 | D13: 2 | E13: 2
... A30: 非機能: 提供ドキュメント | B30: 非機能 | C30: 顧客とアプリ開発者へ渡す資料のうち、特定の機能に紐づかない共通部分 | D30: 3 | E30: 4

Sheet 提供API一覧
A1: 対象 | B1: 機能ID | C1: 機能グループ | D1: 機能名 | E1: 提供する API（機能の粒度） | F1: エンドポイント | G1: 呼ぶ主体 | H1: 区分 | I1: コスト | J1: 備考 | L1: コスト | M1: 件数
A2: Broker | B2: F-AUTH-05 | C2: 顧客IdP 連携ログイン | D2: 顧客IdPへのログイン委譲（OIDC） | E2: 接続情報の公開 | F2: GET /realms/{r}/.well-known/openid-configuration | G2: アプリ（M2M） | H2: ✅ 標準 | I2: 標準内 | J2: アプリはこの 1 本から他の入口を自動取得できる。手で URL を配らない | L2: 標準内 | M2: =COUNTIF($I$2:$I$109,$L2) -> 84
A3: Broker | B3: F-AUTH-05 | C3: 顧客IdP 連携ログイン | D3: 顧客IdPへのログイン委譲（OIDC） | E3: ログイン開始（認可） | F3: GET /realms/{r}/protocol/openid-connect/auth | G3: ブラウザ（画面遷移） | H3: ✅ 標準 | I3: 標準内 | J3: 認可コード + PKCE。顧客IdP への振り分けはこの先で Keycloak が行う | L3: 🔺 標準外（追加コスト） | M3: =COUNTIF($I$2:$I$109,$L3) -> 16
A4: Broker | B4: F-AUTH-05 | C4: 顧客IdP 連携ログイン | D4: 顧客IdPへのログイン委譲（OIDC） | E4: JWT の取得・更新 | F4: POST /realms/{r}/protocol/openid-connect/token | G4: アプリ（M2M） | H4: ✅ 標準 | I4: 標準内 | J4: 認可コード交換 / リフレッシュ / システム間の 3 用途が同じ入口 | L4: 🔻 削減候補 | M4: =COUNTIF($I$2:$I$109,$L4) -> 6
A5: Broker | B5: F-AUTH-05 | C5: 顧客IdP 連携ログイン | D5: 顧客IdPへのログイン委譲（OIDC） | E5: ユーザ情報の取得 | F5: GET /realms/{r}/protocol/openid-connect/userinfo | G5: エンドユーザ本人 | H5: ✅ 標準 | I5: 標準内 | J5: JWT に載せない属性をここで補う。JWT を軽くしたいときの受け皿 | L5: — 提供しない | M5: =COUNTIF($I$2:$I$109,$L5) -> 2
A6: Broker | B6: F-AUTH-05 | C6: 顧客IdP 連携ログイン | D6: 顧客IdPへのログイン委譲（OIDC） | E6: 署名鍵の公開 | F6: GET /realms/{r}/protocol/openid-connect/certs | G6: アプリ（M2M） | H6: ✅ 標準 | I6: 標準内 | J6: アプリ側の JWT 検証に必須。鍵の入れ替えに自動追随する前提 | L6: 合計 | M6: =SUM(M2:M5) -> 108
A7: Broker | B7: F-AUTH-06 | C7: 顧客IdP 連携ログイン | D7: 顧客IdPへのログイン委譲（SAML） | E7: SAML の接続情報 | F7: GET /realms/{r}/protocol/saml/descriptor | G7: アプリ（M2M） | H7: ✅ 標準 | I7: 標準内 | J7: 顧客IdP・業務システムとの交換用
A8: Broker | B8: F-AUTH-06 | C8: 顧客IdP 連携ログイン | D8: 顧客IdPへのログイン委譲（SAML） | E8: SAML の送受信 | F8: POST/GET /realms/{r}/protocol/saml | G8: ブラウザ（画面遷移） | H8: ✅ 標準 | I8: 標準内 | J8: 受け入れ（SP）と提供（IdP）の両方が同じ入口 | L8: 🔺 標準外（追加コスト）の API
A9: Broker | B9: F-AZ-07 | C9: JWT の発行 | D9: システム間 JWT の発行 | E9: システム間 JWT の発行 | F9: POST /realms/{r}/protocol/openid-connect/token（client_credentials） | G9: アプリ（M2M） | H9: ✅ 標準 | I9: 標準内 | J9: アプリ・バッチが API を呼ぶための資格。スコープで範囲を絞る | L9: 対象 | M9: 提供する API | N9: 機能名
A10: Broker | B10: F-AZ-08 | C10: JWT の発行 | D10: 別アプリ向け JWT への交換（Token Exchange） | E10: JWT の交換 | F10: POST /realms/{r}/protocol/openid-connect/token（token-exchange） | G10: アプリ（M2M） | H10: ✅ 標準 | I10: 標準内 | J10: Phase 1 対象外（FR-AUTH-005）。必要になったら設定で有効化 | L10: {=IFERROR(_xlfn._xlws.FILTER($A$2:$A$109,$I$2:$I$109=$L$3),"")} -> Broker | M10: {=IFERROR(_xlfn._xlws.FILTER($E$2:$E$109,$I$2:$I$109=$L$3),"")} -> 接続情報の自動追随 | N10: {=IFERROR(_xlfn._xlws.FILTER($D$2:$D$109,$I$2:$I$109=$L$3),"")} -> 顧客IdP の接続情報の自動追随
A11: Broker | B11: F-AZ-10 | C11: JWT の発行 | D11: アプリへの JWT 発行 | E11: JWT に載せる項目 | F11: （API なし）Protocol Mapper / Client Scope の設定 | G11: アプリ（M2M） | H11: ⚙ 設定のみ | I11: 標準内 | J11: 載せる項目はアプリごとにスコープで出し分ける。設計は必要だがアプリが呼ぶ API は無い | L11: Broker | M11: 証明書期限の監視 | N11: 顧客IdP・本基盤の証明書の期限監視
A12: Broker | B12: F-AUTH-23 | C12: セッションとログアウト | D12: ログイン状態の保持とタイムアウト | E12: ログイン状態の保持 | F12: POST /realms/{r}/protocol/openid-connect/token（refresh_token） | G12: アプリ（M2M） | H12: ✅ 標準 | I12: 標準内 | J12: 有効期間は Realm 設定。上限 12 時間（2026-09-07 決定） | L12: Broker | M12: ログインの振り分け（HRD） | N12: 顧客IdPの自動振り分け
A13: Broker | B13: F-AUTH-24 | C13: セッションとログアウト | D13: アプリへのログアウト連携 | E13: ログアウト | F13: GET/POST /realms/{r}/protocol/openid-connect/logout | G13: ブラウザ（画面遷移） | H13: ✅ 標準 | I13: 標準内 | J13: 本人のログイン状態を破棄。顧客IdP 側への連鎖は IdP ごとの設定 | L13: Broker | M13: アプリへの変更通知（Webhook） | N13: アプリへの変更通知（Webhook）
A14: Broker | B14: F-AUTH-24 | C14: セッションとログアウト | D14: アプリへのログアウト連携 | E14: 他アプリへのログアウト通知 | F14: （Keycloak → アプリ）Back-Channel Logout | G14: アプリ（M2M） | H14: ✅ 標準 | I14: 標準内 | J14: **アプリ側が受信の入口を作る**。Keycloak が呼びに行く向きなので、提供 API ではなくアプリへの実装要求 | L14: Broker | M14: 長期未使用者の自動停止 | N14: 長期未使用者の自動停止
A15: Broker | B15: F-AZ-10 | C15: JWT の発行 | D15: アプリへの JWT 発行 | E15: JWT の失効 | F15: POST /realms/{r}/protocol/openid-connect/revoke | G15: アプリ（M2M） | H15: ⚠ 標準（制約） | I15: 標準内 | J15: リフレッシュトークンは即時に効く。アクセストークンは署名だけで検証するアプリには最大 30 分残る（FR-SSO-009） | L15: Broker | M15: 保存期限切れの消去 | N15: 保存期限切れデータの消去
A16: Broker | B16: F-AZ-10 | C16: JWT の発行 | D16: アプリへの JWT 発行 | E16: JWT の有効性照会 | F16: POST /realms/{r}/protocol/openid-connect/token/introspect | G16: アプリ（M2M） | H16: ✅ 標準 | I16: 標準内 | J16: 失効を即座に反映したい重要な操作で使う。毎回呼ぶと Keycloak の負荷になる | L16: Broker | M16: 実在推測の防止 | N16: ユーザの存在推測の防止
A17: Broker | B17: F-ADM-16 | C17: 顧客IdP 管理 | D17: 顧客IdPの接続登録 | E17: 顧客IdP の登録 | F17: POST /admin/realms/{r}/identity-provider/instances | G17: 管理画面 | H17: ⚠ 標準（制約） | I17: 標準内 | J17: 標準にある。ただし Admin API は Realm 全体に効くため、そのままアプリへは渡せない（後述の権限の絞り込みが前提） | L17: IdP | M17: パスワードの照合 | N17: Keycloak-IdP 収容ユーザのログイン
A18: Broker | B18: F-ADM-17 | C18: 顧客IdP 管理 | D18: 接続設定の変更・証明書更新 | E18: 顧客IdP の変更・証明書更新 | F18: PUT /admin/realms/{r}/identity-provider/instances/{alias} | G18: 管理画面 | H18: ⚠ 標準（制約） | I18: 標準内 | J18: 同上 | L18: IdP | M18: 流出パスワードの使用拒否 | N18: 流出パスワードの使用拒否
A19: Broker | B19: F-ADM-16 | C19: 顧客IdP 管理 | D19: 顧客IdPの接続登録 | E19: 顧客IdP の接続情報の取り込み | F19: POST /admin/realms/{r}/identity-provider/import-config | G19: 管理画面 | H19: ✅ 標準 | I19: 標準内 | J19: 相手の接続情報（メタデータ URL）から設定値を起こす | L19: IdP | M19: メールを持たない人の復旧 | N19: メールを持たない人の復旧
A20: Broker | B20: F-INT-11 | C20: 顧客IdP 管理 | D20: 顧客IdP の接続情報の自動追随 | E20: 接続情報の自動追随 | F20: （標準に無い） | G20: バッチ・システム | H20: 🔧 カスタム必要 | I20: 🔺 標準外（追加コスト） | J20: 定期的に取り込み直す仕組みは標準に無い。Admin API を叩くバッチを作る | L20: Broker | M20: 振り分け失敗時の切替 | N20: 振り分け失敗時のパスワード入力への切替
A21: Broker | B21: F-ADM-14 | C21: 顧客・組織管理 | D21: 顧客の作成 | E21: 顧客の作成 | F21: POST /admin/realms/{r}/organizations | G21: 管理画面 | H21: ⚠ 標準（制約） | I21: 標準内 | J21: Keycloak 26 の Organizations を顧客の単位に使う | L21: Broker | M21: 管理 API の内部公開 | N21: アプリ向け管理 API の公開
A22: Broker | B22: F-ADM-15 | C22: 顧客・組織管理 | D22: 顧客設定の編集 | E22: 顧客設定の編集 | F22: PUT /admin/realms/{r}/organizations/{id} | G22: 管理画面 | H22: ⚠ 標準（制約） | I22: 標準内 | J22: ドメイン・表示名など | L22: Broker | M22: 不正兆候の検知 | N22: 不正なログインの兆候の検知
... A25: Broker | B25: F-ADM-01 | C25: ユーザ管理 | D25: ユーザの参照 | E25: ユーザの検索・一覧 | F25: GET /admin/realms/{r}/users | G25: 管理画面 | H25: ⚠ 標準（制約） | I25: 標準内 | J25: 標準にある。件数の区切りと検索条件も標準 | L25: IdP | M25: パスワードの変更日・期限の取得 | N25: パスワード変更・初回強制変更
A26: Broker | B26: F-ADM-01 | C26: ユーザ管理 | D26: ユーザの参照 | E26: ユーザの詳細参照 | F26: GET /admin/realms/{r}/users/{id} | G26: 管理画面 | H26: ⚠ 標準（制約） | I26: 標準内
A27: Broker | B27: F-ADM-03 | C27: ユーザ管理 | D27: ユーザの登録と変更 | E27: ユーザの登録 | F27: POST /admin/realms/{r}/users | G27: 管理画面 | H27: ⚠ 標準（制約） | I27: 標準内
A28: Broker | B28: F-ADM-03 | C28: ユーザ管理 | D28: ユーザの登録と変更 | E28: ユーザの変更 | F28: PUT /admin/realms/{r}/users/{id} | G28: 管理画面 | H28: ⚠ 標準（制約） | I28: 標準内 | J28: 属性の追加は User Profile で宣言した項目のみ | L28: 🔻 削減候補の API
A29: Broker | B29: F-ADM-05 | C29: ユーザ管理 | D29: ユーザの利用可否の切替・削除 | E29: ユーザの利用可否の切替 | F29: PUT /admin/realms/{r}/users/{id}（enabled） | G29: 管理画面 | H29: ⚠ 標準（制約） | I29: 標準内 | J29: 停止・再開はこの 1 本 | L29: 対象 | M29: 提供する API | N29: 機能名
A30: Broker | B30: F-PROV-10 | C30: ユーザの停止・再開・消去 | D30: ユーザの停止（消さずに無効化） | E30: ユーザの停止 | F30: PUT /admin/realms/{r}/users/{id}（enabled=false） | G30: バッチ・システム | H30: ⚠ 標準（制約） | I30: 標準内 | J30: 停止日時の記録は属性で持つ（標準の項目に無いため User Profile で宣言） | L30: {=IFERROR(_xlfn._xlws.FILTER($A$2:$A$109,$I$2:$I$109=$L$4),"")} -> Broker | M30: {=IFERROR(_xlfn._xlws.FILTER($E$2:$E$109,$I$2:$I$109=$L$4),"")} -> ユーザ登録の受信（SCIM） | N30: {=IFERROR(_xlfn._xlws.FILTER($D$2:$D$109,$I$2:$I$109=$L$4),"")} -> 顧客IdP からのユーザ情報の同期
A31: Broker | B31: F-PROV-11 | C31: ユーザの停止・再開・消去 | D31: 停止済みユーザの再開 | E31: 停止済みユーザの再開 | F31: PUT /admin/realms/{r}/users/{id}（enabled=true） | G31: バッチ・システム | H31: ⚠ 標準（制約） | I31: 標準内 | J31: 誤って戻さない条件の判定は呼ぶ側の責任 | L31: Broker | M31: ユーザ更新の受信（SCIM） | N31: 顧客IdP からのユーザ情報の同期
A32: Broker | B32: F-ADM-05 | C32: ユーザ管理 | D32: ユーザの利用可否の切替・削除 | E32: ユーザの削除 | F32: DELETE /admin/realms/{r}/users/{id} | G32: 管理画面 | H32: ⚠ 標準（制約） | I32: 標準内 | J32: Phase 1 は消さずに止める方針のため通常は使わない | L32: Broker | M32: 削除通知の受信（SCIM） | N32: 顧客IdP からのユーザ情報の同期
A33: Broker | B33: F-ADM-10 | C33: セッションとログアウト | D33: 強制ログアウト（管理者） | E33: 強制ログアウト（1 人） | F33: POST /admin/realms/{r}/users/{id}/logout | G33: 管理画面 | H33: ⚠ 標準（制約） | I33: 標準内 | L33: Broker | M33: ユーザ検索の受信（SCIM） | N33: 顧客IdP からのユーザ情報の同期
A34: Broker | B34: F-ADM-10 | C34: セッションとログアウト | D34: 強制ログアウト（管理者） | E34: 強制ログアウト（全員） | F34: POST /admin/realms/{r}/logout-all | G34: 管理画面 | H34: ⚠ 標準（制約） | I34: 標準内 | J34: 事故対応用。顧客単位の一括は標準に無く、対象を絞って繰り返す | L34: IdP | M34: パスワードの自己再設定 | N34: パスワードの自己再設定
A35: Broker | B35: F-ADM-01 | C35: ユーザ管理 | D35: ユーザの参照 | E35: ログイン状態の一覧 | F35: GET /admin/realms/{r}/users/{id}/sessions | G35: 管理画面 | H35: ⚠ 標準（制約） | I35: 標準内 | L35: Broker | M35: 一括の有効化・無効化 | N35: ユーザの利用可否の切替・削除
A36: Broker | B36: F-AUTH-20 | C36: ログイン口の保護 | D36: 連続失敗時の一時締め出し | E36: 締め出しの解除 | F36: DELETE /admin/realms/{r}/attack-detection/brute-force/users/{id} | G36: 管理画面 | H36: ✅ 標準 | I36: 標準内 | J36: 連続失敗で止まったユーザを戻す。締め出しそのものは Realm 設定
A37: Broker | B37: F-INT-13 | C37: アプリ連携 | D37: アプリの接続登録（クライアント登録） | E37: アプリの接続登録 | F37: POST /admin/realms/{r}/clients | G37: 管理画面 | H37: ⚠ 標準（制約） | I37: 標準内 | J37: ひな形を用意して登録する
A38: Broker | B38: F-INT-13 | C38: アプリ連携 | D38: アプリの接続登録（クライアント登録） | E38: アプリの接続登録（申請式） | F38: POST /realms/{r}/clients-registrations/{provider} | G38: アプリ（M2M） | H38: ✅ 標準 | I38: 標準内 | J38: 管理者が発行した引換券（initial access token）でアプリ側が自分で登録できる。Admin API を渡さずに済む
A39: Broker | B39: F-INT-13 | C39: アプリ連携 | D39: アプリの接続登録（クライアント登録） | E39: 引換券の発行 | F39: POST /admin/realms/{r}/clients-initial-access | G39: 管理画面 | H39: ⚠ 標準（制約） | I39: 標準内 | J39: 上の申請式で使う券
A40: Broker | B40: F-BAT-05 | C40: 鍵・証明書管理 | D40: アプリの接続用パスワードの定期入れ替え | E40: 接続用パスワードの再発行 | F40: POST /admin/realms/{r}/clients/{id}/client-secret | G40: 管理画面 | H40: ⚠ 標準（制約） | I40: 標準内 | J40: 入れ替えの周期と通知は運用側で作る
A41: Broker | B41: F-BAT-04 | C41: 鍵・証明書管理 | D41: JWT 署名鍵の定期入れ替え | E41: 署名鍵の状態確認 | F41: GET /admin/realms/{r}/keys | G41: 管理画面 | H41: ⚠ 標準（制約） | I41: 標準内 | J41: 鍵の追加・無効化は components API。並走期間の管理は運用手順
A42: Broker | B42: F-BAT-07 | C42: 鍵・証明書管理 | D42: 顧客IdP・本基盤の証明書の期限監視 | E42: 証明書期限の監視 | F42: （標準に無い） | G42: バッチ・システム | H42: 🔧 カスタム必要 | I42: 🔺 標準外（追加コスト） | J42: 期限が近いものを知らせる仕組みは標準に無い。API を読むバッチを作る
...

Sheet 要件マッピング
A1: 要件ID | B1: 種別 | C1: 優先度 | D1: 要件実現対象 | E1: 構築場所 | F1: 担当 | G1: 担当の理由 | H1: 項目 | I1: 概要 | J1: ① 基本設計 | K1: ② 詳細設計 | L1: ③ 製造 | M1: ④ テスト | N1: 状況 | O1: Keycloak-IdP 側
A2: FR-AUTH-001-a | B2: 機能要件 | C2: Must | D2: 対象 | E2: Keycloak-Broker | F2: インフラ（本基盤） | G2: Keycloak-Broker にローカルで残るのは運用者だけ。認証は WebAuthn 必須（NFR-SEC-021） | H2: ID/PW 認証（ローカルユーザー）（本基盤運用者） | I2: ID とパスワードで直接ログインできること。顧客IdP を持たない顧客のユーザは Keycloak-IdP（アプリ責務）、本基盤の運用者は Keycloak-Broker（NFR-SEC-021）で満たす | J2: HB-F-AUTH-01 HG-09 | K2: DDB-19 | L2: MKB-31 | M2: SEC-10 | N2: 全工程あり | O2: アプリ（主体）
A3: FR-AUTH-001-b | B3: 機能要件 | C3: Must | D3: 対象 | E3: Keycloak-IdP | F3: アプリ（Keycloak-IdP） | G3: Keycloak-IdP に収容するユーザの話。本基盤は ROSA の引き渡しまで（NFR-OPS-012） | H3: ID/PW 認証（ローカルユーザー）（顧客IdP を持たない顧客のユーザ） | I3: ID とパスワードで直接ログインできること。顧客IdP を持たない顧客のユーザは Keycloak-IdP（アプリ責務）、本基盤の運用者は Keycloak-Broker（NFR-SEC-021）で満たす | N3: アプリ側で実施（Keycloak-IdP 側。本基盤は ROSA の引き渡しまで＝NFR-OPS-012） | O3: アプリ（主体）
A4: FR-AUTH-002 | B4: 機能要件 | C4: Must | D4: 対象 | E4: Keycloak-Broker | F4: インフラ（本基盤） | G4: — | H4: Authorization Code + PKCE（SPA / モバイル） | I4: 画面を持つアプリが、標準の手順（認可コード＋PKCE）でログインを開始し JWT を受け取れること | J4: GD-09 GD-10 GD-14 GD-15 HB-F-AUTH-05 HE-14 HJ-02a HJ-09 HJ-10a | K4: DDB-01 DDB-14 DDE-01 DDI-02 | L4: MKB-02 MKB-03 MKB-22 MKI-02 MKI-13 | M4: IT-07 ST-04 | N4: 全工程あり | O4: —
A5: FR-AUTH-003 | B5: 機能要件 | C5: Must | D5: 対象 | E5: Keycloak-Broker | F5: インフラ（本基盤） | G5: — | H5: Authorization Code + client_secret（SSR） | I5: サーバ側で処理するアプリが、接続用パスワードを使う標準の手順でログインできること | J5: GD-09 GD-10 GD-14 GD-15 HB-F-AUTH-05 HE-14 HJ-02a HJ-09 HJ-10a | K5: DDB-01 DDB-14 DDE-01 DDI-02 | L5: MKB-02 MKB-03 MKB-22 MKI-02 MKI-13 | M5: IT-01 IT-07 RI-01 RI-02 ST-04 | N5: 全工程あり | O5: —
A6: FR-AUTH-004 | B6: 機能要件 | C6: Must | D6: 対象 | E6: Keycloak-Broker | F6: インフラ（本基盤） | G6: — | H6: Client Credentials（M2M） | I6: 人ではなくシステムが API を呼ぶための資格を発行できること | J6: HB-F-AZ-07 | K6: DDB-13 | L6: MKB-21 MKI-12 | M6: IT-06 | N6: 全工程あり | O6: —
A7: FR-AUTH-005 | B7: 機能要件 | C7: TBD | D7: 対象外 | E7: — | F7: — | G7: Phase 1 では作らない。必要になれば Keycloak の標準機能で足せる | H7: Token Exchange（RFC 8693） | I7: あるアプリ向けの JWT を、別のアプリ向けに交換できること | N7: Phase 1 では作らない | O7: —
A8: FR-AUTH-006 | B8: 機能要件 | C8: 不要 | D8: 対象外 | E8: — | F8: — | G8: 2026-08-16 の判断で Phase 1 対象外 | H8: Device Code Flow（画面のない機器・CLI 向けログイン） | I8: 画面のない機器や CLI からログインできること | N8: Phase 1 では作らない | O8: —
A9: FR-AUTH-007 | B9: 機能要件 | C9: 不要 | D9: 対象外 | E9: — | F9: — | G9: 2026-08-16 の判断で対象外。金融水準の顧客が現れたときに再評価 | H9: mTLS Client Authentication（RFC 8705、証明書によるアプリ認証） | I9: 証明書でアプリを認証できること | N9: Phase 1 では作らない | O9: —
A10: FR-AUTH-008 | B10: 機能要件 | C10: Won't | D10: 対象外 | E10: — | F10: — | G10: 採用しない（安全でないため） | H10: ROPC（Password Grant） | I10: アプリがユーザのパスワードを直接受け取ってログインさせる方式 | N10: Phase 1 では作らない | O10: —
A11: FR-AUTH-009 | B11: 機能要件 | C11: Must | D11: 対象 | E11: Keycloak-IdP | F11: アプリ（Keycloak-IdP） | G11: ローカルに収容するユーザだけの話。フェデレーションのユーザは顧客IdP 側の規則に従う | H11: パスワードポリシー（最小長・複雑性） | I11: パスワードの最小の長さと文字種の組み合わせを決められること | N11: アプリ側で実施（Keycloak-IdP 側。本基盤は ROSA の引き渡しまで＝NFR-OPS-012） | O11: アプリ（主体）
A12: FR-AUTH-010 | B12: 機能要件 | C12: Should | D12: 対象 | E12: Keycloak-IdP | F12: アプリ（Keycloak-IdP） | G12: 同上 | H12: パスワード履歴（N 個と一致禁止） | I12: 過去に使ったパスワードを一定個数まで再利用させないこと | N12: アプリ側で実施（Keycloak-IdP 側。本基盤は ROSA の引き渡しまで＝NFR-OPS-012） | O12: アプリ（主体）
A13: FR-AUTH-011 | B13: 機能要件 | C13: Must | D13: 対象 | E13: Keycloak-IdP | F13: アプリ（Keycloak-IdP） | G13: パスワードのロックは Keycloak-IdP 側（アプリ）。Keycloak-Broker はパスワードを持たないため、本基盤側の対策は NFR-SEC-010（実在推測の防止・試行回数の制限）で扱う | H13: アカウントロック（連続失敗） | I13: パスワードを連続で間違えたら一時的にログインを受け付けないこと | N13: アプリ側で実施（Keycloak-IdP 側） | O13: アプリ（主体）
A14: FR-AUTH-012 | B14: 機能要件 | C14: Should | D14: 対象 | E14: Keycloak-IdP | F14: アプリ（Keycloak-IdP） | G14: 同上 | H14: パスワード有効期限 | I14: パスワードに有効期限を設けられること | N14: アプリ側で実施（Keycloak-IdP 側。本基盤は ROSA の引き渡しまで＝NFR-OPS-012） | O14: アプリ（主体）
A15: FR-AUTH-013 | B15: 機能要件 | C15: Must | D15: 対象 | E15: Keycloak-IdP | F15: アプリ（Keycloak-IdP） | G15: 同上 | H15: セルフサービスパスワードリセット | I15: ユーザが自分でパスワードを再設定できること | N15: アプリ側で実施 | O15: アプリ（主体）
A16: FR-AUTH-014 | B16: 機能要件 | C16: Should | D16: 対象 | E16: Keycloak-IdP | F16: アプリ（Keycloak-IdP） | G16: 同上 | H16: 初期パスワード強制変更 | I16: 初回ログイン時にパスワードの変更を強制できること | N16: アプリ側で実施 | O16: アプリ（主体）
A17: FR-AUTH-015 | B17: 機能要件 | C17: TBD | D17: 対象外 | E17: — | F17: — | G17: 提案書で新規想定として挙げた項目。Phase 1 では作らない | H17: DPoP（RFC 9449、送信者に縛った JWT） | I17: JWT を受け取った本人以外が使い回せないよう、送信者を JWT に縛りつけること（DPoP） | N17: Phase 1 では作らない | O17: —
A18: FR-AUTH-016 | B18: 機能要件 | C18: TBD | D18: 対象 | E18: Keycloak-Broker | F18: インフラ（本基盤） | G18: 要否未確定。顧客回答待ち（D-22 で判断のみ計上） | H18: 利用規約への同意取得と記録 | I18: 利用規約などへの同意を取り、いつ誰がどの版に同意したかを記録できること | J18: D-22 | N18: 要件確認（判断のみ計上） | O18: —
A19: FR-FED-001 | B19: 機能要件 | C19: 推奨値あり | D19: 対象 | E19: Keycloak-Broker | F19: インフラ（本基盤） | G19: Auth0 も Phase 1 の対象（2026-09-07 決定）。PoC で使った接続を実機突合（RI-02）に流用する | H19: Auth0 OIDC IdP 連携 | I19: Auth0 を顧客IdP として接続できること | J19: GD-09 GD-10 GD-14 GD-15 HB-F-ADM-16 HB-F-AUTH-05 HE-14 HJ-02a HJ-10a | K19: DDB-01 DDE-01 DDI-02 | L19: MKB-02 MKB-03 MKB-16 MKI-02 | M19: IT-01 RI-02 | N19: 全工程あり | O19: —
A20: FR-FED-002 | B20: 機能要件 | C20: Must | D20: 対象 | E20: Keycloak-Broker | F20: インフラ（本基盤） | G20: — | H20: Entra ID（Azure AD）OIDC 連携 | I20: Entra ID（Azure AD）を顧客IdP として接続できること | J20: GD-09 GD-10 GD-14 GD-15 HB-F-ADM-16 HB-F-AUTH-05 HE-14 HJ-02a HJ-10a | K20: DDB-01 DDE-01 DDI-02 | L20: MKB-02 MKB-03 MKB-16 MKI-02 | M20: RI-01 | N20: 全工程あり | O20: —
A21: FR-FED-003 | B21: 機能要件 | C21: Should | D21: 対象 | E21: Keycloak-Broker | F21: インフラ（本基盤） | G21: — | H21: Okta OIDC 連携 | I21: Okta を顧客IdP として接続できること | J21: GD-09 GD-10 GD-14 GD-15 HB-F-ADM-16 HB-F-AUTH-05 HE-14 HJ-02a HJ-10a | K21: DDB-01 DDE-01 DDI-02 | L21: MKB-02 MKB-03 MKB-16 MKI-02 | M21: IT-01 OP-01 RI-01 RI-02 ST-04 | N21: 全工程あり | O21: —
A22: FR-FED-004 | B22: 機能要件 | C22: Could | D22: 対象 | E22: Keycloak-Broker | F22: インフラ（本基盤） | G22: — | H22: Google Workspace OIDC 連携 | I22: Google Workspace を顧客IdP として接続できること | J22: GD-09 GD-10 GD-14 GD-15 HB-F-ADM-16 HB-F-AUTH-05 HE-14 HJ-02a HJ-10a | K22: DDB-01 DDE-01 DDI-02 | L22: MKB-02 MKB-03 MKB-16 MKI-02 | M22: IT-01 OP-01 RI-01 RI-02 ST-04 | N22: 全工程あり | O22: —
A23: FR-FED-005 | B23: 機能要件 | C23: Should | D23: 対象 | E23: Keycloak-Broker | F23: インフラ（本基盤） | G23: — | H23: SAML 2.0 IdP として受け入れ（SP モード） | I23: 旧方式（SAML）の顧客IdP からログインを受け入れられること | J23: HB-F-ADM-16 HB-F-AUTH-06 HE-15 | K23: DDB-02 DDE-02 DDI-03 | L23: MKB-04 MKB-16 MKI-03 | M23: IT-02 RI-03 ST-05 | N23: 全工程あり | O23: —
A24: FR-FED-006 | B24: 機能要件 | C24: TBD | D24: 対象 | E24: Keycloak-Broker | F24: インフラ（本基盤） | G24: ServiceNow 連携で必要 | H24: SAML 2.0 IdP として発行（IdP モード） | I24: Keycloak-Broker が旧方式（SAML）の提供元として、業務システムへログインを提供できること | J24: GD-13 HB-F-INT-01 HE-16 | K24: DDB-15 DDI-08 | L24: MKB-23 MKI-14 | M24: IT-08 RI-05 ST-25 ST-26 | N24: 全工程あり | O24: —
A25: FR-FED-007 | B25: 機能要件 | C25: TBD | D25: 対象外 | E25: — | F25: — | G25: Phase 1 では作らない | H25: LDAP / AD 直接連携 | I25: 社内ディレクトリ（LDAP / AD）に直接つなげること | N25: Phase 1 では作らない | O25: —
A26: FR-FED-008 | B26: 機能要件 | C26: Must | D26: 対象 | E26: Keycloak-Broker | F26: インフラ（本基盤） | G26: — | H26: JIT プロビジョニング | I26: 顧客IdP 経由で初めて来た人を、その場でユーザとして自動作成できること | J26: HB-F-AUTH-07 | K26: DDB-03 DDI-04 | L26: MKB-05 MKI-04 | M26: ST-04 ST-06 ST-12 | N26: 全工程あり | O26: アプリ（Keycloak-IdP 側の同じ設定は接続仕様 HE-23 に従う）
A27: FR-FED-009 | B27: 機能要件 | C27: Must | D27: 対象 | E27: Keycloak-Broker | F27: インフラ（本基盤） | G27: — | H27: 属性マッピング / クレーム変換 | I27: 顧客ごとにバラバラな属性名を、基盤の統一名に変換して取り込めること | J27: HB-F-PROV-02 HD-05 HD-18 | K27: DDB-04 DDD-01 | L27: MKB-06 MKB-10 | M27: IT-04 ST-07 ST-16 | N27: 全工程あり | O27: アプリ（Keycloak-IdP 側の同じ設定は接続仕様 HE-23 に従う）
A28: FR-FED-010 | B28: 機能要件 | C28: Must | D28: 対象 | E28: Keycloak-Broker | F28: インフラ（本基盤） | G28: — | H28: 複数 IdP 並行運用（マルチテナント） | I28: 複数の顧客IdP を同時に運用でき、顧客ごとに分離できること | J28: HB-F-AZ-05a HJ-01a | K28: DDB-12 DDB-17 | L28: MKB-20 MKB-27 MKI-11 | M28: IT-12 ST-24 | N28: 全工程あり | O28: —
A29: FR-FED-011-a | B29: 機能要件 | C29: Must | D29: 対象 | E29: Keycloak-Broker | F29: インフラ（本基盤） | G29: 登録の手順と疎通確認は本基盤 | H29: 顧客追加時のオンボーディングフロー（本基盤側の登録） | I29: 新しい顧客を迎え入れるときの、登録から利用開始までの流れが用意されていること | J29: HB-F-ADM-14 HB-F-ADM-16 | K29: DDB-09 | L29: MKB-14 MKB-16 | M29: OP-02 ST-21 UAT-02 | N29: 全工程あり | O29: —
A30: FR-FED-011-b | B30: 機能要件 | C30: Must | D30: 対象 | E30: その他 | F30: 顧客（顧客IdP） | G30: 自社 IdP 側の設定（接続先の登録・返す項目・証明書）は顧客が接続ガイドどおりに行う | H30: 顧客追加時のオンボーディングフロー（顧客側の設定） | I30: 新しい顧客を迎え入れるときの、登録から利用開始までの流れが用意されていること | M30: UAT-02 | N30: 顧客側で実施 | O30: —
A31: FR-FED-012-a | B31: 機能要件 | C31: Must | D31: 対象 | E31: Keycloak-Broker | F31: インフラ（本基盤） | G31: 追加認証済みの印（amr）を取り込み、二重に求めない設定は Keycloak-Broker 側 | H31: フェデレーション時の MFA 重複回避（取り込み側） | I31: 顧客IdP 側で追加認証を済ませた人に、Keycloak-Broker で二重に追加認証を求めないこと | J31: HB-F-AUTH-05 HB-F-AUTH-09 HE-14 HE-23 | K31: DDB-01 DDB-18 | L31: MKB-02 MKB-30 | M31: RI-01 ST-04 ST-28 | N31: 全工程あり | O31: —
A32: FR-FED-012-b | B32: 機能要件 | C32: Must | D32: 対象 | E32: その他 | F32: 顧客（顧客IdP） | G32: 追加認証そのものは顧客IdP（Keycloak-IdP 収容ユーザは Keycloak-IdP）が行い、結果を amr で返す。接続ガイドで求める | H32: フェデレーション時の MFA 重複回避（実施側） | I32: 顧客IdP 側で追加認証を済ませた人に、Keycloak-Broker で二重に追加認証を求めないこと | M32: RI-01 | N32: 顧客側で実施 | O32: —
A33: FR-FED-013 | B33: 機能要件 | C33: Should | D33: 対象 | E33: Keycloak-Broker | F33: インフラ（本基盤） | G33: — | H33: ログイン画面での顧客IdP への振り分け（HRD） | I33: ログイン画面で入力した識別子から顧客IdP を自動で判定して送ること。顧客IdP の一覧は見せない。1 顧客に複数ある場合のみ選ばせる | J33: HB-F-AUTH-02 HB-F-AUTH-04 HC-04a HJ-03 | K33: DDC-01 DDH-01 DDI-01 | L33: MKB-01 MKC-01 MKC-03 MKI-01 MKI-08 | M33: ST-01 ST-02 ST-03 | N33: 全工程あり | O33: —
A34: FR-FED-014 | B34: 機能要件 | C34: Should | D34: 対象外 | E34: — | F34: — | G34: Phase 1 では作らない | H34: Custom Domain での federation | I34: 顧客ごとの独自ドメインでフェデレーションできること | N34: Phase 1 では作らない | O34: —
A35: FR-FED-015 | B35: 機能要件 | C35: Must | D35: 対象 | E35: Keycloak-Broker | F35: インフラ（本基盤） | G35: 顧客IdP を持たない顧客のユーザは全員ここを通る。Keycloak-IdP 側の Client・Realm 設定は要求仕様（HE-23）でアプリチームへ渡す | H35: Keycloak-Broker ⇄ Keycloak-IdP 連携 | I35: 顧客IdP を持たない顧客のユーザを Keycloak-Broker から Keycloak-IdP へ委譲してログインさせられること。識別子の引き継ぎ・追加認証結果の取り込み・ログアウト連鎖・セッション上限の同値（12 時間）・閉域の単方向接続を含む | J35: HB-F-AUTH-09 HE-23 HI-11 | K35: DDB-18 DDE-11 DDI-10 | L35: MKA-20 MKB-30 MKI-19 | M35: IT-16 ST-28 | N35: 全工程あり | O35: アプリ（要求仕様どおりに broker-rp Client と Realm 設定を作る）
A36: FR-MFA-001 | B36: 機能要件 | C36: Must | D36: 対象 | E36: Keycloak-IdP | F36: アプリ（Keycloak-IdP） | G36: 追加認証は Keycloak-Broker では扱わない。ローカル収容ユーザは Keycloak-IdP 側 | H36: TOTP（Google Authenticator 等） | I36: スマートフォンアプリの数字コードで追加認証できること | N36: アプリ側で実施 | O36: アプリ（主体）
A37: FR-MFA-002 | B37: 機能要件 | C37: Should | D37: 対象 | E37: Keycloak-IdP | F37: アプリ（Keycloak-IdP） | G37: 同上 | H37: WebAuthn / FIDO2（Passkeys） | I37: 生体認証やセキュリティキーで追加認証できること | N37: アプリ側で実施 | O37: アプリ（主体）
A38: FR-MFA-003 | B38: 機能要件 | C38: Could | D38: 対象外 | E38: — | F38: — | G38: Phase 1 では作らない | H38: SMS OTP | I38: SMS の数字コードで追加認証できること | N38: Phase 1 では作らない | O38: —
A39: FR-MFA-004 | B39: 機能要件 | C39: Could | D39: 対象外 | E39: — | F39: — | G39: Phase 1 では作らない | H39: メール OTP | I39: メールの数字コードで追加認証できること | N39: Phase 1 では作らない | O39: —
A40: FR-MFA-005 | B40: 機能要件 | C40: Should | D40: 対象 | E40: Keycloak-IdP | F40: アプリ（Keycloak-IdP） | G40: 同上 | H40: バックアップコード | I40: 端末を失くしたときに使う予備のコードを発行できること | N40: アプリ側で実施 | O40: アプリ（主体）
...

Sheet 要件・機能対応表
A1: 要件ID | B1: 要件 | C1: 要件の概要 | D1: 機能ID | E1: 機能 | F1: 機能の概要 | G1: 担当 | H1: 状況
A2: FR-AUTH-001-a | B2: ID/PW 認証（ローカルユーザー）（本基盤運用者） | C2: ID とパスワードで直接ログインできること。顧客IdP を持たない顧客のユーザは Keycloak-IdP（アプリ責務）、本基盤の運用者は Keycloak-Broker（NFR-SEC-021）で満たす | D2: F-AUTH-01 | E2: Keycloak-IdP 収容ユーザのログイン | F2: 顧客側に認証システムが無い顧客のユーザが Keycloak-IdP に、本基盤の運用者が Keycloak-Broker に、ID とパスワードで直接ログインする。顧客のユーザ分は Keycloak-IdP 側（アプリ責務）、運用者分は本基盤 | G2: インフラ（本基盤） | H2: 全工程あり
D3: NF-OPS-11 | E3: 運用者アカウントと権限の保護 | F3: 本基盤運用者のローカル認証（WebAuthn 必須）、常時の全権付与の禁止と必要時だけの昇格、緊急時アクセスとの関係、定期棚卸し | G3: インフラ（本基盤） | H3: 全工程あり
A4: FR-AUTH-001-b | B4: ID/PW 認証（ローカルユーザー）（顧客IdP を持たない顧客のユーザ） | C4: ID とパスワードで直接ログインできること。顧客IdP を持たない顧客のユーザは Keycloak-IdP（アプリ責務）、本基盤の運用者は Keycloak-Broker（NFR-SEC-021）で満たす | D4: F-AUTH-01 | E4: Keycloak-IdP 収容ユーザのログイン | F4: 顧客側に認証システムが無い顧客のユーザが Keycloak-IdP に、本基盤の運用者が Keycloak-Broker に、ID とパスワードで直接ログインする。顧客のユーザ分は Keycloak-IdP 側（アプリ責務）、運用者分は本基盤 | G4: アプリ（Keycloak-IdP） | H4: アプリ側で実施（Keycloak-IdP 側。本基盤は ROSA の引き渡しまで＝NFR-OPS-012）
A5: FR-AUTH-002 | B5: Authorization Code + PKCE（SPA / モバイル） | C5: 画面を持つアプリが、標準の手順（認可コード＋PKCE）でログインを開始し JWT を受け取れること | D5: F-AUTH-05 | E5: 顧客IdPへのログイン委譲（OIDC） | F5: 顧客が持つ認証システムに OIDC で認証を委ね、その結果を受け取ってログインさせる | G5: インフラ（本基盤） | H5: 全工程あり
D6: F-INT-13 | E6: アプリの接続登録（クライアント登録） | F6: 新しいアプリを Keycloak-Broker に接続するときの登録内容・申請の流れ・接続情報の渡し方 | G6: インフラ（本基盤） | H6: 全工程あり
A7: FR-AUTH-003 | B7: Authorization Code + client_secret（SSR） | C7: サーバ側で処理するアプリが、接続用パスワードを使う標準の手順でログインできること | D7: F-AUTH-05 | E7: 顧客IdPへのログイン委譲（OIDC） | F7: 顧客が持つ認証システムに OIDC で認証を委ね、その結果を受け取ってログインさせる | G7: インフラ（本基盤） | H7: 全工程あり
D8: F-INT-13 | E8: アプリの接続登録（クライアント登録） | F8: 新しいアプリを Keycloak-Broker に接続するときの登録内容・申請の流れ・接続情報の渡し方 | G8: インフラ（本基盤） | H8: 全工程あり
A9: FR-AUTH-004 | B9: Client Credentials（M2M） | C9: 人ではなくシステムが API を呼ぶための資格を発行できること | D9: F-AZ-07 | E9: システム間 JWT の発行 | F9: アプリやバッチがシステムとして API を呼ぶための資格を発行する | G9: インフラ（本基盤） | H9: 全工程あり
A10: FR-AUTH-005 | B10: Token Exchange（RFC 8693） | C10: あるアプリ向けの JWT を、別のアプリ向けに交換できること | D10: F-AZ-08 | E10: 別アプリ向け JWT への交換（Token Exchange） | F10: あるアプリ向けに出した JWT を、別のアプリ向けの JWT に引き換える | G10: — | H10: Phase 1 では作らない
A11: FR-AUTH-006 | B11: Device Code Flow（画面のない機器・CLI 向けログイン） | C11: 画面のない機器や CLI からログインできること | D11: — | E11: —（本基盤に作る機能なし） | F11: 2026-08-16 の判断で Phase 1 対象外 | G11: — | H11: Phase 1 では作らない
A12: FR-AUTH-007 | B12: mTLS Client Authentication（RFC 8705、証明書によるアプリ認証） | C12: 証明書でアプリを認証できること | D12: — | E12: —（本基盤に作る機能なし） | F12: 2026-08-16 の判断で対象外。金融水準の顧客が現れたときに再評価 | G12: — | H12: Phase 1 では作らない
A13: FR-AUTH-008 | B13: ROPC（Password Grant） | C13: アプリがユーザのパスワードを直接受け取ってログインさせる方式 | D13: — | E13: —（本基盤に作る機能なし） | F13: 採用しない（安全でないため） | G13: — | H13: Phase 1 では作らない
A14: FR-AUTH-009 | B14: パスワードポリシー（最小長・複雑性） | C14: パスワードの最小の長さと文字種の組み合わせを決められること | D14: F-AUTH-01 | E14: Keycloak-IdP 収容ユーザのログイン | F14: 顧客側に認証システムが無い顧客のユーザが Keycloak-IdP に、本基盤の運用者が Keycloak-Broker に、ID とパスワードで直接ログインする。顧客のユーザ分は Keycloak-IdP 側（アプリ責務）、運用者分は本基盤 | G14: アプリ（Keycloak-IdP） | H14: アプリ側で実施（Keycloak-IdP 側。本基盤は ROSA の引き渡しまで＝NFR-OPS-012）
A15: FR-AUTH-010 | B15: パスワード履歴（N 個と一致禁止） | C15: 過去に使ったパスワードを一定個数まで再利用させないこと | D15: F-AUTH-01 | E15: Keycloak-IdP 収容ユーザのログイン | F15: 顧客側に認証システムが無い顧客のユーザが Keycloak-IdP に、本基盤の運用者が Keycloak-Broker に、ID とパスワードで直接ログインする。顧客のユーザ分は Keycloak-IdP 側（アプリ責務）、運用者分は本基盤 | G15: アプリ（Keycloak-IdP） | H15: アプリ側で実施（Keycloak-IdP 側。本基盤は ROSA の引き渡しまで＝NFR-OPS-012）
A16: FR-AUTH-011 | B16: アカウントロック（連続失敗） | C16: パスワードを連続で間違えたら一時的にログインを受け付けないこと | D16: F-AUTH-20 | E16: 連続失敗時の一時締め出し | F16: パスワードの連続失敗を検知して一時的に受け付けなくする | G16: アプリ（Keycloak-IdP） | H16: アプリ側で実施（Keycloak-IdP 側）
A17: FR-AUTH-012 | B17: パスワード有効期限 | C17: パスワードに有効期限を設けられること | D17: F-AUTH-01 | E17: Keycloak-IdP 収容ユーザのログイン | F17: 顧客側に認証システムが無い顧客のユーザが Keycloak-IdP に、本基盤の運用者が Keycloak-Broker に、ID とパスワードで直接ログインする。顧客のユーザ分は Keycloak-IdP 側（アプリ責務）、運用者分は本基盤 | G17: アプリ（Keycloak-IdP） | H17: アプリ側で実施（Keycloak-IdP 側。本基盤は ROSA の引き渡しまで＝NFR-OPS-012）
A18: FR-AUTH-013 | B18: セルフサービスパスワードリセット | C18: ユーザが自分でパスワードを再設定できること | D18: F-AUTH-18 | E18: パスワードの自己再設定 | F18: ユーザが自分でパスワードを再設定する | G18: アプリ（Keycloak-IdP） | H18: アプリ側で実施
A19: FR-AUTH-014 | B19: 初期パスワード強制変更 | C19: 初回ログイン時にパスワードの変更を強制できること | D19: F-AUTH-19 | E19: パスワード変更・初回強制変更 | F19: パスワードの変更と、初回ログイン時に変更を強制する動き | G19: アプリ（Keycloak-IdP） | H19: アプリ側で実施
A20: FR-AUTH-015 | B20: DPoP（RFC 9449、送信者に縛った JWT） | C20: JWT を受け取った本人以外が使い回せないよう、送信者を JWT に縛りつけること（DPoP） | D20: — | E20: —（本基盤に作る機能なし） | F20: 提案書で新規想定として挙げた項目。Phase 1 では作らない | G20: — | H20: Phase 1 では作らない
... A22: FR-FED-001 | B22: Auth0 OIDC IdP 連携 | C22: Auth0 を顧客IdP として接続できること | D22: F-AUTH-05 | E22: 顧客IdPへのログイン委譲（OIDC） | F22: 顧客が持つ認証システムに OIDC で認証を委ね、その結果を受け取ってログインさせる | G22: インフラ（本基盤） | H22: 全工程あり
D23: F-ADM-16 | E23: 顧客IdPの接続登録 | F23: 顧客IdPを基盤に接続する登録作業 | G23: インフラ（本基盤） | H23: 全工程あり
A24: FR-FED-002 | B24: Entra ID（Azure AD）OIDC 連携 | C24: Entra ID（Azure AD）を顧客IdP として接続できること | D24: F-AUTH-05 | E24: 顧客IdPへのログイン委譲（OIDC） | F24: 顧客が持つ認証システムに OIDC で認証を委ね、その結果を受け取ってログインさせる | G24: インフラ（本基盤） | H24: 全工程あり
D25: F-ADM-16 | E25: 顧客IdPの接続登録 | F25: 顧客IdPを基盤に接続する登録作業 | G25: インフラ（本基盤） | H25: 全工程あり
A26: FR-FED-003 | B26: Okta OIDC 連携 | C26: Okta を顧客IdP として接続できること | D26: F-AUTH-05 | E26: 顧客IdPへのログイン委譲（OIDC） | F26: 顧客が持つ認証システムに OIDC で認証を委ね、その結果を受け取ってログインさせる | G26: インフラ（本基盤） | H26: 全工程あり
D27: F-ADM-16 | E27: 顧客IdPの接続登録 | F27: 顧客IdPを基盤に接続する登録作業 | G27: インフラ（本基盤） | H27: 全工程あり
A28: FR-FED-004 | B28: Google Workspace OIDC 連携 | C28: Google Workspace を顧客IdP として接続できること | D28: F-AUTH-05 | E28: 顧客IdPへのログイン委譲（OIDC） | F28: 顧客が持つ認証システムに OIDC で認証を委ね、その結果を受け取ってログインさせる | G28: インフラ（本基盤） | H28: 全工程あり
D29: F-ADM-16 | E29: 顧客IdPの接続登録 | F29: 顧客IdPを基盤に接続する登録作業 | G29: インフラ（本基盤） | H29: 全工程あり
A30: FR-FED-005 | B30: SAML 2.0 IdP として受け入れ（SP モード） | C30: 旧方式（SAML）の顧客IdP からログインを受け入れられること | D30: F-AUTH-06 | E30: 顧客IdPへのログイン委譲（SAML） | F30: 顧客が持つ認証システムに SAML で認証を委ね、その結果を受け取ってログインさせる | G30: インフラ（本基盤） | H30: 全工程あり
D31: F-ADM-16 | E31: 顧客IdPの接続登録 | F31: 顧客IdPを基盤に接続する登録作業 | G31: インフラ（本基盤） | H31: 全工程あり
A32: FR-FED-006 | B32: SAML 2.0 IdP として発行（IdP モード） | C32: Keycloak-Broker が旧方式（SAML）の提供元として、業務システムへログインを提供できること | D32: F-INT-01 | E32: 業務システムへの認証提供 | F32: 業務システムに対して、Keycloak-Broker が認証の提供元として振る舞う | G32: インフラ（本基盤） | H32: 全工程あり
D33: F-INT-02 | E33: 業務システム側のユーザ自動作成 | F33: 業務システム側で、初回ログイン時にユーザを自動作成させる | G33: インフラ（本基盤） | H33: 全工程あり
A34: FR-FED-007 | B34: LDAP / AD 直接連携 | C34: 社内ディレクトリ（LDAP / AD）に直接つなげること | D34: — | E34: —（本基盤に作る機能なし） | F34: Phase 1 では作らない | G34: — | H34: Phase 1 では作らない
A35: FR-FED-008 | B35: JIT プロビジョニング | C35: 顧客IdP 経由で初めて来た人を、その場でユーザとして自動作成できること | D35: F-AUTH-05 | E35: 顧客IdPへのログイン委譲（OIDC） | F35: 顧客が持つ認証システムに OIDC で認証を委ね、その結果を受け取ってログインさせる | G35: インフラ（本基盤） | H35: 全工程あり
D36: F-PROV-01 | E36: 初回ログイン時のユーザ自動作成（JIT） | F36: 顧客IdP経由で初めてログインした人を、その場で Keycloak-Broker のユーザとして作成する | G36: インフラ（本基盤） | H36: 全工程あり
D37: F-PROV-03 | E37: 顧客IdP からのユーザ情報の同期 | F37: 顧客IdP から SCIM でユーザの登録・更新・削除通知・検索を受け取り、本基盤へ反映する。呼び出し口ごとの違いは提供 API 一覧で持つ。グループ連携は初期リリース対象外 | G37: インフラ（本基盤） | H37: 全工程あり
A38: FR-FED-009 | B38: 属性マッピング / クレーム変換 | C38: 顧客ごとにバラバラな属性名を、基盤の統一名に変換して取り込めること | D38: F-PROV-02 | E38: ログイン時の属性更新 | F38: 2 回目以降のログインで、顧客側の最新情報を使って属性を更新する | G38: インフラ（本基盤） | H38: 全工程あり
D39: F-PROV-03 | E39: 顧客IdP からのユーザ情報の同期 | F39: 顧客IdP から SCIM でユーザの登録・更新・削除通知・検索を受け取り、本基盤へ反映する。呼び出し口ごとの違いは提供 API 一覧で持つ。グループ連携は初期リリース対象外 | G39: インフラ（本基盤） | H39: 全工程あり
D40: F-PROV-08 | E40: 顧客IdP から受け取る属性の名前の統一 | F40: 顧客ごとにバラバラな項目名を基盤内の統一名に変換して取り込む。統一名の辞書と 顧客IdPごとの変換表を含む | G40: インフラ（本基盤） | H40: 全工程あり
A41: FR-FED-010 | B41: 複数 IdP 並行運用（マルチテナント） | C41: 複数の顧客IdP を同時に運用でき、顧客ごとに分離できること | D41: F-AZ-05 | E41: 顧客越境の防止（Keycloak-Broker 側） | F41: ユーザが自分の顧客以外の顧客IdPを使ってログインできないようにする。権限データ側の越境防止はアプリの責務 | G41: インフラ（本基盤） | H41: 全工程あり
...

Sheet WBS(基本設計)
A1: ID | B1: 分類 | C1: 作業種別 | D1: 機能グループ | E1: 機能名 | F1: 項目 | G1: 概要 | H1: 成果物と完了条件 | I1: 人日 | J1: 担当（案②: 一部移管） | K1: 担当（案③: アプリ構築） | L1: 判断根拠 | M1: 根拠の補足 | N1: スコープ | O1: 当初想定 | P1: 依存 | Q1: 状態 | R1: 出典 | S1: 機能ID
A2: HB-F-AUTH-02 | B2: HB-F 機能仕様書 | C2: 設計書の執筆 | D2: ログインの振り分け | E2: 顧客IdPの自動振り分け | F2: 機能仕様書: 顧客IdPの自動振り分け（HRD） | G2: 入力された ID から、その人がどの顧客IdPのユーザかを判定し、自動で送り先を決める | H2: 機能仕様書。判定に使う値・判定の順序・判定できたときの送り先が定まっている | I2: 1 | J2: 基盤チーム | K2: 基盤チーム | L2: 認証の中核 | M2: 顧客IdPが複数ある前提で、ユーザが自分の顧客IdPにたどり着く唯一の手段 | N2: 対象 | O2: 新規: 機能追加 | P2: — | Q2: 未着手 | S2: F-AUTH-02
A3: HJ-03 | B3: HJ Keycloak-Brokerの作り込み | C3: 設計書の執筆 | D3: ログインの振り分け | E3: 顧客IdPの自動振り分け | F3: HRD：自社拡張の仕様書（判定ロジック・切替） | G3: 判定を行う自社拡張の入出力・動作条件・Keycloak-Brokerへの組み込み位置を決める | H3: 拡張の仕様書。入出力と、どのフローのどこに置くかが定まっている | I3: 2 | J3: 基盤チーム | K3: 基盤チーム | L3: 認証の中核 | M3: Keycloak-Brokerの標準機能では実現できず、自社拡張で作る必要がある | N3: 対象 | O3: 新規: 機能追加 | P3: — | Q3: 未着手 | S3: F-AUTH-02
A4: HB-F-AUTH-03 | B4: HB-F 機能仕様書 | C4: 設計書の執筆 | D4: ログインの振り分け | E4: 振り分け失敗時のパスワード入力への切替 | F4: 機能仕様書: 振り分けできないときのパスワード入力への切替 | G4: 顧客IdPを判定できなかったときに、パスワード入力へ切り替えて処理を続ける動き | H4: 機能仕様書。切り替える条件と、切り替えた後の扱いが定まっている | I4: 0.5 | J4: 基盤チーム | K4: 基盤チーム | L4: 事故防止 | M4: どの顧客か分からない状態でもユーザを止めないための逃げ道 | N4: 対象 | O4: 新規: 機能追加 | P4: — | Q4: 未着手 | S4: F-AUTH-03
A5: HB-F-AUTH-04 | B5: HB-F 機能仕様書 | C5: 設計書の執筆 | D5: ログインの振り分け | E5: 顧客IdPの選択（1 顧客に複数） | F5: 機能仕様書: 顧客IdPの選択画面 | G5: 1 つの顧客に顧客IdPが複数ある場合に、ユーザにどれを使うか選ばせる | H5: 機能仕様書。選ばせる条件と、並び順の決め方が定まっている | I5: 0.5 | J5: 基盤チーム | K5: 基盤チーム | L5: 認証の中核 | M5: グループ会社や部門ごとに認証システムを持つ顧客がいるため | N5: 対象 | O5: 新規: 機能追加 | P5: — | Q5: 未着手 | S5: F-AUTH-04
A6: HB-F-AUTH-05 | B6: HB 機能設計 | C6: 設計書の執筆 | D6: 顧客IdP 連携ログイン | E6: 顧客IdPへのログイン委譲（OIDC） | F6: 機能仕様書: 顧客IdP 連携ログイン（OIDC） | G6: 顧客が持っている認証システムに認証を委ね、その結果を受け取ってログインさせる機能（標準的な連携方式） | H6: 機能仕様書 1 本。委譲時に渡す情報・受け取る情報と、拒否された場合の扱いが定義されレビュー承認済み | I6: 0.5 | J6: 基盤チーム | K6: 基盤チーム | L6: 認証の中核 | M6: 顧客IdPへ委ねる中核で、これが無いと基盤の存在理由が無い | N6: 対象 | O6: 当初あり | P6: — | Q6: 未着手 | R6: ADR-033、U2 §2.2 | S6: F-AUTH-05
A7: HE-14 | B7: HE つなぎ目設計 | C7: 設計書の執筆 | D7: 顧客IdP 連携ログイン | E7: 顧客IdPへのログイン委譲（OIDC） | F7: 認証プロトコルIF（OIDCエンドポイント・クレーム） | G7: 標準方式の認証連携で、やり取りする情報の仕様。内訳: 認可エンドポイント / トークンエンドポイント / クレーム / ログアウト | H7: 仕様書。顧客IdPの情報と、渡す項目が定まっている | I7: 4 | J7: 基盤チーム | K7: 基盤チーム | L7: 認証の中核 | M7: 顧客IdPへ委ねる中核で、これが無いと基盤の存在理由が無い | N7: 対象 | O7: 当初あり | P7: — | Q7: 未着手 | S7: F-AUTH-05
A8: HJ-02a | B8: HJ Keycloak の作り込み | C8: 設計書の執筆 | D8: 顧客IdP 連携ログイン | E8: 顧客IdPへのログイン委譲（OIDC） | F8: 認証フローの組み立て順序（3 系統） | G8: ログイン処理の組み立て順序を決める（外部連携を受ける側の 3 系統） | H8: 処理順序の設計書。3 系統それぞれの分岐が図で示されている | I8: 1 | J8: 基盤チーム | K8: 基盤チーム | L8: 認証の中核 | M8: 顧客IdPへ委ねる中核で、これが無いと基盤の存在理由が無い | N8: 対象 | O8: 当初あり | P8: — | Q8: 未着手 | S8: F-AUTH-05
A9: HJ-10a | B9: HJ Keycloak の作り込み | C9: 設計書の執筆 | D9: 顧客IdP 連携ログイン | E9: 顧客IdPへのログイン委譲（OIDC） | F9: Keycloak-Brokerの設定値一覧 | G9: Keycloak-Brokerの設定値を決める（外部連携を受ける側） | H9: 設定値一覧。有効期間・回数制限などが数値で定まっている | I9: 2 | J9: 基盤チーム | K9: 基盤チーム | L9: 認証の中核 | M9: 顧客IdPへ委ねる中核で、これが無いと基盤の存在理由が無い | N9: 対象 | O9: 当初あり | P9: — | Q9: 未着手 | S9: F-AUTH-05
A10: HE-17 | B10: HE つなぎ目設計 | C10: 設計書の執筆 | D10: 顧客IdP 連携ログイン | E10: 顧客IdPへのログイン委譲（OIDC） | F10: 外部IF 顧客IdP（SAML/OIDC差分） | G10: 顧客IdPごとの接続仕様の差分整理 | H10: 差分表。製品ごとの違いが一覧化されている | I10: 2 | J10: 基盤チーム | K10: 基盤チーム | L10: 認証の中核 | M10: 【省略・吸収】HE-14 / HE-15 の認証プロトコル IF に吸収。人日は復活時のために残す | N10: 対象外：省略・吸収 | O10: 当初あり | P10: — | Q10: 未着手 | S10: F-AUTH-05
A11: GD-09 | B11: GD アプリ向けガイド | C11: ガイド・手順書の執筆 | D11: 顧客IdP 連携ログイン | E11: 顧客IdPへのログイン委譲（OIDC） | F11: 第3部 Webアプリ（BFF / SSR） | G11: サーバー側で処理を受け持つ形式のアプリ向けの実装手順。Keycloak-Broker の推奨形式 | H11: ガイド 1 章。推奨する理由と、この形式でしか使えない機能が明示されている | I11: 1 | J11: 基盤チーム | K11: 基盤チーム | L11: 認証の中核 | M11: 顧客IdPへ委ねる中核で、これが無いと基盤の存在理由が無い | N11: 対象 | O11: 当初あり | P11: — | Q11: 未着手 | S11: F-AUTH-05
A12: GD-10 | B12: GD アプリ向けガイド | C12: ガイド・手順書の執筆 | D12: 顧客IdP 連携ログイン | E12: 顧客IdPへのログイン委譲（OIDC） | F12: 第3部 SPA（ブラウザ） | G12: ブラウザだけで動く形式のアプリ向けの実装手順と、認める条件 | H12: ガイド 1 章。JWT をブラウザに保存してはいけない範囲と、使えない機能の制約が明示されている | I12: 1 | J12: 基盤チーム | K12: 基盤チーム | L12: 認証の中核 | M12: 顧客IdPへ委ねる中核で、これが無いと基盤の存在理由が無い | N12: 対象 | O12: 当初あり | P12: — | Q12: 未着手 | S12: F-AUTH-05
A13: GD-14 | B13: GD アプリ向けガイド | C13: ガイド・手順書の執筆 | D13: 顧客IdP 連携ログイン | E13: 顧客IdPへのログイン委譲（OIDC） | F13: 第4部 認可リクエスト | G13: ログインを開始するときにアプリが必ず付ける情報と、やってはいけない古い方式 | H13: ガイド 1 章。必須パラメータと禁止事項が判定可能な形で列挙されている | I13: 2 | J13: 基盤チーム | K13: 基盤チーム | L13: 認証の中核 | M13: 顧客IdPへ委ねる中核で、これが無いと基盤の存在理由が無い | N13: 対象 | O13: 当初あり | P13: — | Q13: 未着手 | S13: F-AUTH-05
A14: GD-15 | B14: GD アプリ向けガイド | C14: ガイド・手順書の執筆 | D14: 顧客IdP 連携ログイン | E14: 顧客IdPへのログイン委譲（OIDC） | F14: 第4部 JWT の取得・保存 | G14: 受け取ったJWT をどこに保存してよいか・いけないかの方針 | H14: ガイド 1 章。保存場所ごとの可否と理由が示されている | I14: 2 | J14: 基盤チーム | K14: 基盤チーム | L14: 認証の中核 | M14: 顧客IdPへ委ねる中核で、これが無いと基盤の存在理由が無い | N14: 対象 | O14: 当初あり | P14: — | Q14: 未着手 | S14: F-AUTH-05
A15: HB-F-AUTH-06 | B15: HB 機能設計 | C15: 設計書の執筆 | D15: 顧客IdP 連携ログイン | E15: 顧客IdPへのログイン委譲（SAML） | F15: 機能仕様書: 顧客IdP 連携ログイン（SAML） | G15: 顧客が持っている認証システムのうち、旧来の方式で連携する場合のログイン機能 | H15: 機能仕様書 1 本。旧方式特有の識別子の扱いと、標準方式との差分が定義されレビュー承認済み | I15: 0.5 | J15: 基盤チーム | K15: 基盤チーム | L15: 認証の中核 | M15: 顧客IdPへ委ねる中核で、これが無いと基盤の存在理由が無い | N15: 対象 | O15: 当初あり | P15: — | Q15: 未着手 | R15: ADR-031、U2 §2.7 | S15: F-AUTH-06
A16: HE-15 | B16: HE つなぎ目設計 | C16: 設計書の執筆 | D16: 顧客IdP 連携ログイン | E16: 顧客IdPへのログイン委譲（SAML） | F16: 認証プロトコルIF（SAMLメタデータ・Assertion） | G16: 旧方式の認証連携で、やり取りする情報の仕様。内訳: メタデータ / Assertion / シングルログアウト | H16: 仕様書。接続情報の受け渡し方と項目が定まっている | I16: 4 | J16: 基盤チーム | K16: 基盤チーム | L16: 認証の中核 | M16: 顧客IdPへ委ねる中核で、これが無いと基盤の存在理由が無い | N16: 対象 | O16: 当初あり | P16: — | Q16: 未着手 | S16: F-AUTH-06
A17: D-11 | B17: D 判断 | C17: 調査・計画 | D17: 顧客IdP 連携ログイン | E17: 顧客IdPへのログイン委譲（SAML） | F17: 旧方式の顧客IdPを登録するひな形 | G17: 旧方式の顧客IdPを登録するときのひな形を作る | H17: ひな形定義。項目の対応づけが定まっている | I17: 2 | J17: 基盤チーム | K17: 基盤チーム | L17: 認証の中核 | M17: 【省略・吸収】HE-15 認証プロトコル IF（SAML メタデータ・Assertion）に吸収。人日は復活時のために残す | N17: 対象外：省略・吸収 | O17: 当初あり | P17: — | Q17: 未着手 | S17: F-AUTH-06
A18: HB-F-AUTH-07 | B18: HB-F 機能仕様書 | C18: 設計書の執筆 | D18: 顧客IdP 連携ログイン | E18: 初回ログイン時のユーザ自動作成（JIT） | F18: 機能仕様書: 初回ログイン時のユーザ自動作成（JIT） | G18: 顧客IdP経由で初めてログインした人を、その場で Keycloak-Broker のユーザとして作る | H18: 機能仕様書。作る条件・持たせる項目・重複したときの扱いが定まっている | I18: 1 | J18: 基盤チーム | K18: 基盤チーム | L18: 認証の中核 | M18: これが無いとフェデレーションのログインが完了しない。Keycloak-Brokerの初回連携フローに直結する | N18: 対象 | O18: 新規: 機能追加 | P18: — | Q18: 未着手 | S18: F-PROV-01
A19: HB-F-PROV-02 | B19: HB-F 機能仕様書 | C19: 設計書の執筆 | D19: 顧客IdP 連携ログイン | E19: ログイン時の属性更新 | F19: 機能仕様書: ログイン時の属性更新 | G19: 2 回目以降のログインで、顧客側の最新の情報を使って属性を更新する | H19: 機能仕様書。更新する項目と、更新しない項目の区別が定まっている | I19: 0.5 | J19: 基盤チーム | K19: 基盤チーム | L19: 認証の中核 | M19: 属性が古いままだとアプリ側の判断が誤る | N19: 対象 | O19: 新規: 機能追加 | P19: — | Q19: 未着手 | S19: F-PROV-02
A20: HB-F-AUTH-09 | B20: HB-F 機能仕様書 | C20: 設計書の執筆 | D20: 顧客IdP 連携ログイン | E20: Keycloak-Broker と Keycloak-IdP の連携 | F20: 機能仕様書: Keycloak-IdP へのログイン委譲 | G20: Keycloak-Broker が Keycloak-IdP を顧客IdP の 1 つ（共有エントリ）として扱い、識別子の引き継ぎ・初回作成・追加認証結果（amr）の取り込みを行う | H20: 機能仕様書。渡す情報・受け取る情報・拒否時の扱い・2 回目以降は Keycloak-IdP を呼ばないことが定まっている | I20: 1 | J20: 基盤チーム | K20: 基盤チーム | L20: 認証の中核 | M20: 2 台構成に戻したため復活。顧客IdP を持たない顧客のログインはすべてここを通る | N20: 対象 | O20: 新規: 機能追加 | P20: — | Q20: 未着手 | S20: F-AUTH-09
A21: HE-23 | B21: HE つなぎ目設計 | C21: 設計書の執筆 | D21: 顧客IdP 連携ログイン | E21: Keycloak-Broker と Keycloak-IdP の連携 | F21: Keycloak-Broker ⇄ Keycloak-IdP 接続仕様（要求仕様としてアプリチームへ渡す） | G21: Keycloak-IdP 側に求める Client（broker-rp）・返す項目（tenant_id / username / amr）・login_hint の書式・ログアウト連鎖・セッション上限の同値（12 時間）・接続経路（閉域・単方向）を 1 冊にまとめる | H21: 接続仕様書。両チームが合意し、Keycloak-IdP 側の設定値がこの 1 冊で作れる | I21: 2.5 | J21: 基盤チーム | K21: 基盤チーム | L21: 認証の中核 | M21: U2 §2.2.2〜2.2.5 / 02a / U6 D-U6-06 の決定を接続仕様の形にする。アプリチームとの境界そのもの | N21: 対象 | O21: 新規: 機能追加 | P21: — | Q21: 未着手 | S21: F-AUTH-09
A22: HI-11 | B22: HI レビュー・合意 | C22: レビュー・合意 | D22: 顧客IdP 連携ログイン | E22: Keycloak-Broker と Keycloak-IdP の連携 | F22: 接続仕様のアプリチームとの合意 | G22: 接続仕様（HE-23）をアプリチームとレビューし、Keycloak-IdP 側の設定値と検証環境の提供時期を合意する | H22: 合意記録。設定値・検証環境の提供時期・連絡先が定まっている | I22: 1 | J22: 基盤チーム | K22: 基盤チーム | L22: 構成の前提 | M22: 合意が無いと結合試験（IT-16）が始められない | N22: 対象 | O22: 新規: 機能追加 | P22: — | Q22: 未着手 | S22: F-AUTH-09
A23: HB-F-AUTH-01 | B23: HB 機能設計 | C23: 設計書の執筆 | D23: パスワードによるログイン | E23: Keycloak-IdP 収容ユーザのログイン | F23: 機能仕様書: ローカルログイン（ID/PW） | G23: 本基盤の運用者が Keycloak-Broker に ID とパスワード＋WebAuthn で直接ログインする機能。顧客のユーザ分（Keycloak-IdP 収容）はアプリ側の仕様とし、本仕様書は運用者分のみ | H23: 機能仕様書 1 本。運用者の認証手段・失敗時にユーザへ返す内容が定義されレビュー承認済み（パスワード桁数等の顧客ユーザ向け規則は対象外） | I23: 0.5 | J23: 基盤チーム | K23: 基盤チーム | L23: 認証の中核 | M23: Keycloak-Broker にローカルで残るのは運用者だけ。顧客ユーザのパスワード規則は Keycloak-IdP（アプリ責務） | N23: 対象 | O23: 当初あり | P23: — | Q23: 未着手 | R23: U2 §2.3、P-07 | S23: F-AUTH-01
A24: HJ-10b | B24: HJ Keycloak の作り込み | C24: 設計書の執筆 | D24: パスワードによるログイン | E24: Keycloak-IdP 収容ユーザのログイン | F24: Keycloak-Brokerの設定値一覧（ユーザを直接収容する側） | G24: Keycloak-Brokerの設定値を決める（ユーザを直接収容する側） | H24: 設定値一覧。パスワード条件を含め数値で定まっている | I24: 2 | J24: 基盤チーム | K24: 基盤チーム | L24: 構成の前提 | M24: Keycloak-IdP 側の設定値はアプリチームが決める。本基盤が求める値は接続仕様（HE-23）に限る | N24: 対象外：Keycloak-IdP 側の責務 | O24: 当初あり | P24: — | Q24: 未着手 | S24: F-AUTH-01
A25: HJ-20 | B25: HJ Keycloak-Brokerの作り込み | C25: レビュー・合意 | D25: パスワードによるログイン | E25: Keycloak-IdP 側の引き渡しと責任分界 | F25: Keycloak-IdP 側の引き渡し範囲と責任分界の取り決め | G25: 基盤（ROSA）をどの状態まで作って渡すか、渡した後は誰が何を持つかを決める | H25: 合意記録。引き渡す状態・手順・渡した後の責任範囲が定まっている | I25: 1.5 | J25: 基盤チーム | K25: 基盤チーム | L25: 構成の前提 | M25: 基盤は基盤（ROSA）だけを作ってアプリチームへ引き渡す前提。境界が曖昧だと運用で揉める | N25: 対象 | O25: 新規: 機能追加 | P25: — | Q25: 未着手 | S25: F-AUTH-29
A26: D-21 | B26: D 判断 | C26: レビュー・合意 | D26: パスワードによるログイン | E26: Keycloak-IdP 側の引き渡しと責任分界 | F26: Keycloak-IdP 側の非機能責任表（可用性・復旧・監視・更新・鍵・ログ） | G26: 非機能要件ごとに Keycloak-IdP 側では誰が満たすかを表にする。本基盤は ROSA の引き渡しまで、以降はアプリ責務とする方針を明文化する | H26: 責任表。非機能要件の全行に Keycloak-IdP 側の担当が入っている | I26: 1.5 | J26: 基盤チーム | K26: 基盤チーム | L26: 構成の前提 | M26: 要件マッピングの「Keycloak-IdP 側」列の根拠。曖昧だと SLA と運用で揉める | N26: 対象 | O26: 新規: 非機能・運用 | P26: — | Q26: 未着手 | S26: F-AUTH-29
A27: HB-F-AUTH-10 | B27: HB 機能設計 | C27: 設計書の執筆 | D27: 多要素認証 | E27: 追加認証の利用 | F27: 機能仕様書: MFA認証（TOTP） | G27: スマートフォンアプリで生成する 6 桁の数字による追加認証 | H27: → 収載先: 多要素認証設計書。機能仕様書 1 本。桁ずれの許容範囲と、連続失敗時の扱いが定義されレビュー承認済み | I27: 0.5 | J27: 基盤チーム | K27: 基盤チーム | L27: 製品機能 | M27: 【Keycloak-IdP 側の責務】追加認証はKeycloak-Broker では行わない。フェデレーションのユーザは顧客IdP側、直接収容するユーザは Keycloak-IdP 側で行う。人日は復活時のために残す | N27: 対象外：Keycloak-IdP 側の責務 | O27: 当初あり | P27: — | Q27: 未着手 | R27: U7 D-U7-14 | S27: F-AUTH-10
A28: HB-F-AUTH-12 | B28: HB 機能設計 | C28: 設計書の執筆 | D28: 多要素認証 | E28: 追加認証の登録 | F28: 機能仕様書: MFAエンロール（TOTP） | G28: スマートフォンアプリの追加認証を初めて登録する画面の流れ | H28: → 収載先: 多要素認証設計書。機能仕様書 1 本。QR と手入力の両方を用意し、登録完了を確認してから有効化する手順が定義されレビュー承認済み | I28: 0.5 | J28: 基盤チーム | K28: 基盤チーム | L28: 製品機能 | M28: 【Keycloak-IdP 側の責務】追加認証はKeycloak-Broker では行わない。フェデレーションのユーザは顧客IdP側、直接収容するユーザは Keycloak-IdP 側で行う。人日は復活時のために残す | N28: 対象外：Keycloak-IdP 側の責務 | O28: 当初あり | P28: — | Q28: 未着手 | R28: U4 §4.4.2 | S28: F-AUTH-12
A29: HB-F-AUTH-21 | B29: HB-F 機能仕様書 | C29: 設計書の執筆 | D29: ログイン口の保護 | E29: ユーザの存在推測の防止 | F29: 機能仕様書: 振り分けの応答の同一化と試行回数の制限 | G29: 入力された識別子が実在するかどうかが応答の違いから分からないようにし、短時間の繰り返し試行を制限する | H29: 機能仕様書。同一化する応答の範囲・制限する回数と時間・制限にかかったときの表示が定まっている | I29: 1 | J29: 基盤チーム | K29: 基盤チーム | L29: 事故防止 | M29: Keycloak-Brokerはパスワードを持たないため連続失敗の締め出しは不要だが、振り分けは識別子を受け取るため実在の推測と総当たりが成立する。WAF は同じ送信元しか見ないので、分散して来ると効かない | N29: 対象 | O29: 新規: 機能追加 | P29: — | Q29: 未着手 | S29: F-AUTH-21
A30: HA-10 | B30: HA 全体・方式設計 | C30: 設計書の執筆 | D30: セッションとログアウト | E30: ログイン状態の保持とタイムアウト | F30: 認証：セッション管理方式設計（ログイン状態の保持・タイムアウト・ログアウト） | G30: ログイン状態をどう保持するかの全体方針 | H30: 方式設計。保持する場所と有効期間の考え方が定まっている | I30: 2 | J30: 共同 | K30: 共同 | L30: 横断（対象縮小） | M30: ログイン状態はKeycloak-Brokerが持つため全アプリ共通。アプリ内の保持方法はアプリが決めるが、全体の有効期間は 1 つの設定で全アプリに効くため共同で決める | N30: 対象 | O30: 当初あり | P30: — | Q30: 未着手 | S30: F-AUTH-23
A31: GD-21 | B31: GD アプリ向けガイド | C31: ガイド・手順書の執筆 | D31: セッションとログアウト | E31: ログイン状態の保持とタイムアウト | F31: 第4部 セッション管理 | G31: ログイン状態がどれくらい続くのか、いつ切れるのかの説明 | H31: ガイド 1 章。有効期間の一覧と、切れたときのアプリ側の動きが示されている | I31: 2 | J31: 基盤チーム | K31: 基盤チーム | L31: 認証の中核 | M31: 顧客IdPへ委ねる中核で、これが無いと基盤の存在理由が無い | N31: 対象 | O31: 当初あり | P31: — | Q31: 未着手 | S31: F-AUTH-23
A32: GD-24 | B32: GD アプリ向けガイド | C32: ガイド・手順書の執筆 | D32: セッションとログアウト | E32: ログイン状態の保持とタイムアウト | F32: 第4部 リフレッシュトークン | G32: JWT を延長するための仕組みと、不正利用が疑われた場合の挙動 | H32: ガイド 1 章。延長時の入れ替え要件と、失効したときのアプリ側の動きが示されている | I32: 1 | J32: 基盤チーム | K32: 基盤チーム | L32: 認証の中核 | M32: 顧客IdPへ委ねる中核で、これが無いと基盤の存在理由が無い | N32: 対象 | O32: 当初あり | P32: — | Q32: 未着手 | S32: F-AUTH-23
A33: GD-22 | B33: GD アプリ向けガイド | C33: ガイド・手順書の執筆 | D33: セッションとログアウト | E33: アプリへのログアウト連携 | F33: 第4部 ログアウト3方式の使い分け | G33: ログアウトの 3 つの方式の違いと、どれをいつ使うかの整理。1 つ実装すれば全アプリで切れる、という誤解を正す | H33: ガイド 1 章。3 方式の関係と責任分界が図で示されている | I33: 2 | J33: 基盤チーム | K33: 基盤チーム | L33: 認証の中核 | M33: 顧客IdPへ委ねる中核で、これが無いと基盤の存在理由が無い | N33: 対象 | O33: 当初あり | P33: — | Q33: 未着手 | S33: F-AUTH-24
A34: GD-23 | B34: GD アプリ向けガイド | C34: ガイド・手順書の執筆 | D34: セッションとログアウト | E34: アプリへのログアウト連携 | F34: 第4部 Back-Channel Logout受信実装 | G34: 他のアプリでのログアウトを受け取って自分のセッションも切る実装。受け取った通知の検証項目を含む | H34: ガイド 1 章。8 つの検証項目が列挙され、検証を省くと強制ログアウトの悪用が可能になる旨が警告されている | I34: 2 | J34: 基盤チーム | K34: 基盤チーム | L34: 認証の中核 | M34: 顧客IdPへ委ねる中核で、これが無いと基盤の存在理由が無い | N34: 対象 | O34: 当初あり | P34: — | Q34: 未着手 | S34: F-AUTH-24
A35: HC-04a | B35: HC 画面設計 | C35: 設計書の執筆 | D35: ログイン画面 | E35: ログイン画面の表示（ブランド・並び順） | F35: 画面仕様書: 識別子の入力画面（振り分け） | G35: 振り分けの起点となる、識別子を入力させる画面の項目・文言・遷移を決める | H35: 画面仕様書。入力項目・検証・次に進む条件・戻り方が定まっている | I35: 1 | J35: 基盤チーム | K35: 基盤チーム | L35: 認証の中核 | M35: 振り分け（HRD）は識別子の入力から始まるため、この画面が無いと成立しない | N35: 対象 | O35: 新規: 機能追加 | P35: — | Q35: 未着手 | S35: F-AUTH-25
A36: HC-04j | B36: HC 画面設計 | C36: 設計書の執筆 | D36: ログイン画面 | E36: エラー・案内画面（Keycloak-Broker） | F36: 画面仕様書: エラー・案内の表示画面（Keycloak-Broker） | G36: ログインや振り分けに失敗したときに何を表示し、どこへ誘導するかを決める | H36: 画面仕様書。表示する文言・出し分けの条件・誘導先が定まっている | I36: 1 | J36: 基盤チーム | K36: 基盤チーム | L36: 事故防止 | M36: 失敗したときの案内が無いとユーザが詰まる。文言はユーザの実在を推測させない書き方にする必要がある | N36: 対象 | O36: 新規: 機能追加 | P36: — | Q36: 未着手 | S36: F-AUTH-26
A37: D-22 | B37: D 判断 | C37: 調査・計画 | D37: ログイン画面 | E37: 利用規約への同意取得と記録 | F37: 同意取得の要否と方式の判断 | G37: 利用規約などへの同意をログイン画面で取るか、アプリ側で取るか、取らないかを顧客に確認して決める | H37: 決定記録。要否と、取る場合の場所と記録先が定まっている | I37: 0.5 | J37: 基盤チーム | K37: 基盤チーム | L37: 業務ルール依存 | M37: 要件未確定。顧客回答待ち | N37: 対象 | O37: 新規: 機能追加 | P37: — | Q37: 要件確認 | S37: F-AUTH-28
A38: HE-09 | B38: HE つなぎ目設計 | C38: 設計書の執筆 | D38: ユーザ管理 | E38: 顧客IdP からのユーザ情報の同期 | F38: SCIM 受信仕様（窓口・項目の対応づけ・絞り込み・削除の読み替え） | G38: 顧客の人事システムや認証システムからユーザ情報を受け取る窓口の仕様を決める。窓口はKeycloak-Broker（Keycloak）の上に立て、別の実行基盤は作らない | H38: 接続仕様。入口・認証方法・項目の対応・応答が定まっている | I38: 3 | J38: 基盤チーム | K38: アプリチーム | L38: 認証の中核 | M38: ログインを待たずにユーザを反映する唯一の経路。Keycloak-Brokerの標準機能は使わず自作または部品を使い、Keycloak-Brokerの上に載せる | N38: 対象 | O38: 新規: 機能追加 | P38: — | Q38: 未着手 | S38: F-PROV-03
